Workbook
Name A___Bonificação__lucros: #REF!
Name B_1___Administração_Central: #REF!
Name B_2___Seguro___Garantia: #REF!
Name B_3___Risco: #REF!
Name B_4___Despesas_Financeiras: #REF!
Name C_1___PIS___uso_do_REIDI: #REF!
Name C_2___ISS: #REF!
Name C_3___COFINS____Uso_do_Reidi: #REF!
Name C_4___CPRB: #REF!

Sheet Resumo
B3: FUNDO DE DESENVOLVIMENTO DA INFRAESTRUTURA REGIONAL SUSTENTÁVEL - FDIRS (“FDIRS”)
B5: ESTRUTURAÇÃO DE PROJETO DE CONCESSÃO DO PERÍMETRO IRRIGADO DO JAÍBA (ETAPAS 3 E 4)
J6: =SUMIF($A$11:$A$147,A94,$I$11:$I$147) -> 40996864 | K6: =J6/2 -> 20498432
B7: PLANILHA RESUMO DO ORÇAMENTO | J7: =SUMIF($A$11:$A$147,Cronograma!F2,$I$11:$I$147) -> 30120630
H8: DATA BASE: | I8: 45839 | J8: =SUMIF($A$11:$A$147,A105,$I$11:$I$147) -> 58404735
H9: BDI: | I9: =+BDI!C16 -> 0.2527
B10: ITEM | C10: FONTE | D10: CÓDIGO | E10: DESCRIÇÃO DA ATIVIDADE/SERVIÇO | F10: UNIDADE | G10: QUANTIDADE | H10: CUSTO UNITÁRIO (R$) | I10: CUSTO TOTAL (R$)
B11: 0 | C11: 0 | D11: 0 | E11: VALOR TOTAL DO PROJETO | F11: 0 | G11: 0 | H11: 0 | I11: =+I13+I161+I163+I165+I167+I169+I171 -> 4.7205359e+08
B13: A | C13: - | D13: - | E13: CANTEIRO DE OBRAS | F13: - | G13: 0 | H13: 0 | I13: =+Planilha!I13 -> 34844063
B15: B | C15: - | D15: - | E15: ETAPA 3 | F15: - | G15: 0 | H15: 0 | I15: =+Planilha!I19 -> 1.8505383e+08
B16: B1 | C16: - | D16: - | E16: SERVIÇOS TÉCNICOS DE ENGENHARIA | F16: - | G16: 0 | H16: 0 | I16: =+Planilha!I20 -> 12187104
B17: B2 | C17: - | D17: - | E17: OBRAS CIVIS | F17: - | G17: 0 | H17: 0 | I17: =+I18+I38+I50+I68+I71+I73+I75 -> 1.6180211e+08
B18: 1 | C18: - | D18: - | E18: CANAIS | F18: - | G18: 0 | H18: 0 | I18: =+I19+I25+I27+I29+I35 -> 1.3433664e+08
B19: 0 | C19: - | D19: - | E19: Canal: CS19 | F19: - | G19: 0 | H19: 0 | I19: =SUM(I20:I24) -> 61302489
B20: 1.1 | C20: - | D20: - | E20: Canal: CS19 - Trecho 1 | F20: - | G20: 0 | H20: 0 | I20: =+Planilha!I27 -> 2871252.9
B21: 1.2 | C21: - | D21: - | E21: Canal: CS19 - Trecho 2 | F21: - | G21: 0 | H21: 0 | I21: =+Planilha!I64 -> 15394371
B22: 1.3 | C22: - | D22: - | E22: Canal: CS19 - Trecho 3 | F22: - | G22: 0 | H22: 0 | I22: =+Planilha!I101 -> 14208007
B23: 1.4 | C23: - | D23: - | E23: Canal: CS19 - Trecho 4 | F23: - | G23: 0 | H23: 0 | I23: =+Planilha!I138 -> 12551586
B24: 1.5 | C24: - | D24: - | E24: Canal: CS19 - Trecho 5 | F24: - | G24: 0 | H24: 0 | I24: =+Planilha!I175 -> 16277272
B25: 0 | C25: - | D25: - | E25: Canal: CT1-CS19 | F25: - | G25: 0 | H25: 0 | I25: =SUM(I26:I26) -> 11436090
B26: 1.6 | C26: - | D26: - | E26: Canal: CT1-CS19 - Trecho 1 | F26: - | G26: 0 | H26: 0 | I26: =+Planilha!I213 -> 11436090
B27: 0 | C27: - | D27: - | E27: Canal: CS21 | F27: - | G27: 0 | H27: 0 | I27: =+I28 -> 5299527.5
B28: 1.7 | C28: - | D28: - | E28: Canal: CS21 | F28: - | G28: 0 | H28: 0 | I28: =+Planilha!I251 -> 5299527.5
B29: 0 | C29: - | D29: - | E29: Canal: CS21a | F29: - | G29: 0 | H29: 0 | I29: =SUM(I30:I34) -> 50460642
B30: 1.8 | C30: - | D30: - | E30: Canal: CS21a - Trecho 1 | F30: - | G30: 0 | H30: 0 | I30: =+Planilha!I289 -> 12223393
B31: 1.9 | C31: - | D31: - | E31: Canal: CS21a - Trecho 2 | F31: - | G31: 0 | H31: 0 | I31: =+Planilha!I326 -> 12110017
B32: 1.10 | C32: - | D32: - | E32: Canal: CS21a - Trecho 3 | F32: - | G32: 0 | H32: 0 | I32: =+Planilha!I363 -> 9927442.3
B33: 1.11 | C33: - | D33: - | E33: Canal: CS21a - Trecho 4 | F33: - | G33: 0 | H33: 0 | I33: =+Planilha!I400 -> 5463595.6
B34: 1.12 | C34: - | D34: - | E34: Canal: CS21a - Trecho 5 | F34: - | G34: 0 | H34: 0 | I34: =+Planilha!I437 -> 10736194
B35: 0 | C35: - | D35: - | E35: Canal: CT2-S21 | F35: - | G35: 0 | H35: 0 | I35: =+I36 -> 5837894.6
B36: 1.13 | C36: - | D36: - | E36: Canal: CT2-S21 | F36: - | G36: 0 | H36: 0 | I36: =+Planilha!I475 -> 5837894.6
B38: 2 | C38: - | D38: - | E38: ESTRUTURAS DE CONTROLE | F38: - | G38: 0 | H38: 0 | I38: =+I39+I44 -> 1505387.6
B39: 0 | C39: - | D39: - | E39: Canal: CS19 | F39: - | G39: 0 | H39: 0 | I39: =SUM(I40:I43) -> 716959.09
B40: 2.1 | C40: - | D40: - | E40: EC2 - CS19 | F40: - | G40: 0 | H40: 0 | I40: =+Planilha!I515 -> 195266.4
B41: 2.1 | C41: - | D41: - | E41: EC3 - CS19 | F41: - | G41: 0 | H41: 0 | I41: =+Planilha!I530 -> 181932.65
B42: 2.2 | C42: - | D42: - | E42: EC4 - CS19 | F42: - | G42: 0 | H42: 0 | I42: =+Planilha!I545 -> 181932.65
B43: 2.3 | C43: - | D43: - | E43: EC5 - CS19 | F43: - | G43: 0 | H43: 0 | I43: =+Planilha!I560 -> 157827.39
B44: 0 | C44: - | D44: - | E44: Canal: CS21a | F44: - | G44: 0 | H44: 0 | I44: =SUM(I45:I48) -> 788428.54
B45: 2.4 | C45: - | D45: - | E45: EC2 - CS21a | F45: - | G45: 0 | H45: 0 | I45: =+Planilha!I576 -> 217980.61
B46: 2.5 | C46: - | D46: - | E46: EC3 - CS21a | F46: - | G46: 0 | H46: 0 | I46: =+Planilha!I591 -> 201193.49
...

Sheet Planilha
B3: FUNDO DE DESENVOLVIMENTO DA INFRAESTRUTURA REGIONAL SUSTENTÁVEL - FDIRS (“FDIRS”)
B5: ESTRUTURAÇÃO DE PROJETO DE CONCESSÃO DO PERÍMETRO IRRIGADO DO JAÍBA (ETAPAS 3 E 4)
B7: PLANILHA DE ORÇAMENTO
H8: DATA BASE: | I8: 45839
H9: BDI: | I9: =+BDI!C16 -> 0.2527
A10: 1 | B10: ITEM | C10: FONTE | D10: CÓDIGO | E10: DESCRIÇÃO DA ATIVIDADE/SERVIÇO | F10: UNIDADE | G10: QUANTIDADE | H10: CUSTO UNITÁRIO (R$) | I10: CUSTO TOTAL (R$) | J10: Aux_Cronograma
B11: 0 | C11: 0 | D11: 0 | E11: VALOR TOTAL DO PROJETO | F11: 0 | G11: 0 | H11: 0 | I11: =I13+I1455+I1457+I1460+I1466+I1470+I1473 -> 4.7205359e+08
B13: A | C13: - | D13: - | E13: CANTEIRO DE OBRAS | F13: - | G13: 0 | H13: 0 | I13: =SUM(I14:I17) -> 34844063 | J13: CANTEIRO
B14: 1 | C14: COMPOSIÇÃO | D14: 1 | E14: Instalação do Canteiro | F14: % | G14: 2 | H14: =+$I$1455-$I$20-$I$815 -> 3.1676421e+08 | I14: =+G14*H14/100 -> 6335284.1
B15: 2 | C15: COMPOSIÇÃO | D15: 1 | E15: Operação e Manutenção do Canteiro | F15: % | G15: 2.5 | H15: =+$I$1455-$I$20-$I$815 -> 3.1676421e+08 | I15: =+G15*H15/100 -> 7919105.2
B16: 3 | C16: COMPOSIÇÃO | D16: 1 | E16: Administração Local | F16: % | G16: 6 | H16: =+$I$1455-$I$20-$I$815 -> 3.1676421e+08 | I16: =+G16*H16/100 -> 19005852
B17: 4 | C17: COMPOSIÇÃO | D17: 1 | E17: Mobilização e Desmobilização de Equipamentos | F17: % | G17: 0.5 | H17: =+$I$1455-$I$20-$I$815 -> 3.1676421e+08 | I17: =+G17*H17/100 -> 1583821
B19: B | C19: - | D19: - | E19: ETAPA 3 | F19: - | G19: 0 | H19: 0 | I19: =+I812 -> 1.8505383e+08
B20: B1 | C20: - | D20: - | E20: SERVIÇOS TÉCNICOS DE ENGENHARIA | F20: - | G20: 0 | H20: 0 | I20: =SUM(I21:I23) -> 12187104
B21: 1 | C21: COMPOSIÇÃO | D21: 1 | E21: Projetos Básico/Executivo | F21: % | G21: 4 | H21: =+$I$809+$I$810 -> 1.7286673e+08 | I21: =+G21*H21/100 -> 6914669.2 | J21: PROJETO3
B22: 2 | C22: COMPOSIÇÃO | D22: 1 | E22: Gerenciamento/Supervisão de Obras | F22: % | G22: 3 | H22: =+$I$809+$I$810 -> 1.7286673e+08 | I22: =+G22*H22/100 -> 5186001.9 | J22: SUP3
B23: 3 | C23: COMPOSIÇÃO | D23: 1 | E23: Controles Tecnológicos | F23: % | G23: 0.05 | H23: =+$I$809+$I$810 -> 1.7286673e+08 | I23: =+G23*H23/100 -> 86433.365 | J23: SUP3
B24: B2 | C24: - | D24: - | E24: OBRAS CIVIS | F24: - | G24: 0 | H24: 0 | I24: =+I25+I513+I637+I699+I775+I709+I765 -> 1.6180211e+08
B25: 1 | C25: - | D25: - | E25: CANAIS | F25: - | G25: 0 | H25: 0 | I25: =+I26+I212+I250+I288+I474 -> 1.3433664e+08
B26: 0 | C26: - | D26: - | E26: Canal: CS19 | F26: - | G26: 0 | H26: 0 | I26: =+I27+I64+I101+I138+I175 -> 61302489
A27: E3-L1 | B27: 1.1 | C27: - | D27: - | E27: Canal: CS19 - Trecho 1 | F27: - | G27: 0 | H27: 0 | I27: =SUM(I28:I63) -> 2871252.9 | J27: E3-L1
B28: 1.1.1 | C28: - | D28: - | E28: TERRAPLENAGEM E TRATAMENTOS
B29: 1.1.1.1 | C29: SICRO | D29: 5501700 | E29: =VLOOKUP($D29,'Preços Unitários'!$B:$G,2,FALSE) -> Desmatamento, destocamento e limpeza de área com árvores de diâmetro até 0,15 m | F29: =VLOOKUP($D29,'Preços Unitários'!$B:$G,3,FALSE) -> m² | G29: =+'MC Canais'!J5 -> 34000 | H29: =VLOOKUP($D29,'Preços Unitários'!$B:$G,6,FALSE) -> 0.87689 | I29: =+G29*H29 -> 29814.26
B30: 1.1.1.2 | C30: SICRO | D30: 5502114 | E30: =VLOOKUP($D30,'Preços Unitários'!$B:$G,2,FALSE) -> Escavação, carga e transporte de material de 1ª categoria - DMT de 1.000 a 1.200 m - caminho de serviço em leito natural - com escavadeira e caminhão basculante de 14 m³ | F30: =VLOOKUP($D30,'Preços Unitários'!$B:$G,3,FALSE) -> m³ | G30: =+'MC Canais'!J6 -> 1218.69 | H30: =VLOOKUP($D30,'Preços Unitários'!$B:$G,6,FALSE) -> 10.673004 | I30: =+G30*H30 -> 13007.083
B31: 1.1.1.3 | C31: SICRO | D31: 5502978 | E31: =VLOOKUP($D31,'Preços Unitários'!$B:$G,2,FALSE) -> Compactação de aterros a 100% do Proctor normal | F31: =VLOOKUP($D31,'Preços Unitários'!$B:$G,3,FALSE) -> m³ | G31: =+'MC Canais'!J7 -> 40104.47 | H31: =VLOOKUP($D31,'Preços Unitários'!$B:$G,6,FALSE) -> 7.102809 | I31: =+G31*H31 -> 284854.39
B32: 1.1.1.4 | C32: SICRO | D32: 5915319 | E32: =VLOOKUP($D32,'Preços Unitários'!$B:$G,2,FALSE) -> Transporte com caminhão basculante de 14 m³ - rodovia em leito natural | F32: =VLOOKUP($D32,'Preços Unitários'!$B:$G,3,FALSE) -> tkm | G32: =+'MC Canais'!J8 -> 272200.46 | H32: =VLOOKUP($D32,'Preços Unitários'!$B:$G,6,FALSE) -> 1.165011 | I32: =+G32*H32 -> 317116.53
B33: 1.1.1.5 | C33: SICRO | D33: 4413986 | E33: =VLOOKUP($D33,'Preços Unitários'!$B:$G,2,FALSE) -> Regularização de superfície com motoniveladora | F33: =VLOOKUP($D33,'Preços Unitários'!$B:$G,3,FALSE) -> m² | G33: =+'MC Canais'!J9 -> 1530 | H33: =VLOOKUP($D33,'Preços Unitários'!$B:$G,6,FALSE) -> 0.100216 | I33: =+G33*H33 -> 153.33048
B34: 1.1.1.6 | C34: COMPOSIÇÃO | D34: CPU-CAN002 | E34: Fornecimento e instalação de geocomposto drenante para os taludes | F34: m² | G34: =+'MC Canais'!J10 -> 1901 | H34: =+'Composições de Preços'!$F$87 -> 59.387949 | I34: =+G34*H34 -> 112896.49
B35: 1.1.1.7 | C35: COMPOSIÇÃO | D35: CPU-CAN004 | E35: Regularização dos taludes do canal com solo-cimento (5% de cimento) | F35: m³ | G35: =+'MC Canais'!J11 -> 1520.6 | H35: =+'Composições de Preços'!$F$446 -> 99.894988 | I35: =+G35*H35 -> 151900.32
B36: 1.1.1.8 | C36: COMPOSIÇÃO | D36: CPU-CAN001 | E36: Fornecimento e aplicação de geomembrana sintética para impermeabilização do canal, 1,00 mm de espessura (PEAD) | F36: m² | G36: =+'MC Canais'!J12 -> 7603 | H36: =+'Composições de Preços'!$F$44 -> 73.117919 | I36: =+G36*H36 -> 555915.54
B37: 1.1.1.9 | C37: COMPOSIÇÃO | D37: CPU-CAN005 | E37: Ancoragem da geomembrana com escavação de material de 1ª e 2ª categorias | F37: m³ | G37: =+'MC Canais'!J13 -> 1700 | H37: =+'Composições de Preços'!$F$492 -> 107.93859 | I37: =+G37*H37 -> 183495.61
B38: 1.1.1.10 | C38: SICRO | D38: 1106280 | E38: =VLOOKUP($D38,'Preços Unitários'!$B:$G,2,FALSE) -> Concreto para bombeamento fck = 30 MPa - confecção em central dosadora de 30 m³/h - areia e brita comerciais | F38: =VLOOKUP($D38,'Preços Unitários'!$B:$G,3,FALSE) -> m³ | G38: =+'MC Canais'!J14 -> 532.21 | H38: =VLOOKUP($D38,'Preços Unitários'!$B:$G,6,FALSE) -> 575.92882 | I38: =+G38*H38 -> 306515.08
B39: 1.1.1.11 | C39: SICRO | D39: 1106088 | E39: =VLOOKUP($D39,'Preços Unitários'!$B:$G,2,FALSE) -> Lançamento mecânico de concreto com bomba rebocável com capacidade de 30 m³/h - confecção em central dosadora de 30 m³/h | F39: =VLOOKUP($D39,'Preços Unitários'!$B:$G,3,FALSE) -> m³ | G39: =+'MC Canais'!J15 -> 532.21 | H39: =VLOOKUP($D39,'Preços Unitários'!$B:$G,6,FALSE) -> 86.285976 | I39: =+G39*H39 -> 45922.259
B40: 1.1.1.12 | C40: SICRO | D40: 0307084 | E40: =VLOOKUP($D40,'Preços Unitários'!$B:$G,2,FALSE) -> Lábios poliméricos em junta de pavimento de concreto - L = 20 mm e H = 30 mm - confecção e assentamento | F40: =VLOOKUP($D40,'Preços Unitários'!$B:$G,3,FALSE) -> m | G40: =+'MC Canais'!J16 -> 4333.3 | H40: =VLOOKUP($D40,'Preços Unitários'!$B:$G,6,FALSE) -> 39.635428 | I40: =+G40*H40 -> 171752.2
B41: 1.1.1.13 | C41: COMPOSIÇÃO | D41: CPU-CAN003 | E41: Guias de proteção em concreto pré-moldado | F41: m | G41: =+'MC Canais'!J17 -> 1700 | H41: =+'Composições de Preços'!$F$130 -> 37.70077 | I41: =+G41*H41 -> 64091.308
B42: 1.1.1.14 | C42: SICRO | D42: 4415673 | E42: =VLOOKUP($D42,'Preços Unitários'!$B:$G,2,FALSE) -> Revestimento vegetal com grama em mudas em superfícies inclinadas | F42: =VLOOKUP($D42,'Preços Unitários'!$B:$G,3,FALSE) -> m² | G42: =+'MC Canais'!J18 -> 10200 | H42: =VLOOKUP($D42,'Preços Unitários'!$B:$G,6,FALSE) -> 9.984019 | I42: =+G42*H42 -> 101836.99
B43: 1.1.2 | C43: - | D43: - | E43: DRENAGEM INTERNA DOS CANAIS | G43: =+'MC Canais'!J19 -> 0
B44: 1.1.2.1 | C44: SICRO | D44: 4805757 | E44: =VLOOKUP($D44,'Preços Unitários'!$B:$G,2,FALSE) -> Escavação mecânica de vala em material de 1ª categoria | F44: =VLOOKUP($D44,'Preços Unitários'!$B:$G,3,FALSE) -> m³ | G44: =+'MC Canais'!J20 -> 714 | H44: =VLOOKUP($D44,'Preços Unitários'!$B:$G,6,FALSE) -> 8.731319 | I44: =+G44*H44 -> 6234.1618
B45: 1.1.2.2 | C45: SICRO | D45: 4815671 | E45: =VLOOKUP($D45,'Preços Unitários'!$B:$G,2,FALSE) -> Reaterro e compactação com soquete vibratório | F45: =VLOOKUP($D45,'Preços Unitários'!$B:$G,3,FALSE) -> m³ | G45: =+'MC Canais'!J21 -> 408 | H45: =VLOOKUP($D45,'Preços Unitários'!$B:$G,6,FALSE) -> 22.611235 | I45: =+G45*H45 -> 9225.3839
B46: 1.1.2.3 | C46: SICRO | D46: 5915319 | E46: =VLOOKUP($D46,'Preços Unitários'!$B:$G,2,FALSE) -> Transporte com caminhão basculante de 14 m³ - rodovia em leito natural | F46: =VLOOKUP($D46,'Preços Unitários'!$B:$G,3,FALSE) -> tkm | G46: =+'MC Canais'!J22 -> 2142 | H46: =VLOOKUP($D46,'Preços Unitários'!$B:$G,6,FALSE) -> 1.165011 | I46: =+G46*H46 -> 2495.4536
...

Sheet Cronograma
B1: Cronograma - Alternativa 1 (implantação independente entre Etapas)
B2: Ano de concessão | C2: Proj executivo | D2: Ampliação EB1, 2 e 3 e conexão com CEMIG | E2: E4-L1 | F2: E4-L2 | G2: E4-L3 | H2: E3-L1 | I2: E3-L2 | J2: E3-L3 | K2: E3-L4 | L2: Total | N2: Proj executivo | O2: Ampliação EB1, 2 e 3 e conexão com CEMIG | P2: E4-L1 | Q2: E4-L2 | R2: E4-L3 | S2: E3-L1 | T2: E3-L2 | U2: E3-L3 | V2: E3-L4
B3: 1 | L3: =SUM(C3:K3) -> 0
B4: 2 | C4: =Planilha!I816 -> 5755899.1 | L4: =SUM(C4:K4) -> 5755899.1 | N4: =C4/$K$26 -> #DIV/0!
B5: 3 | D5: =Resumo!I167+Resumo!I169+Resumo!I171+Resumo!I163+Resumo!I165 -> 98113444 | E5: =((SUMIF(Planilha!$A$11:$A$1447,Cronograma!E$2,Planilha!$I$11:$I$1447)/2)+(SUMIF(Planilha!$J$11:$J$1447,"E4-L1i",Planilha!$I$11:$I$1447)/2)*$C$15)+(Planilha!$I$817+Planilha!$I$818)*$D$23+(Planilha!$I$13*$D$21) -> 23675181 | L5: =SUM(C5:K5) -> 1.2178862e+08 | O5: =$D$5/$K$26/2 -> #DIV/0! | P5: =#REF!/$K$26 -> #REF!
B6: 4 | E6: =((SUMIF(Planilha!$A$11:$A$1447,Cronograma!E$2,Planilha!$I$11:$I$1447)/2)+(SUMIF(Planilha!$J$11:$J$1447,"E4-L1i",Planilha!$I$11:$I$1447)/2)*$C$15)+(Planilha!$I$817+Planilha!$I$818)*$E$23+(Planilha!$I$13*$E$21) -> 23675181 | L6: =SUM(C6:K6) -> 23675181 | O6: =$D$5/$K$26/2 -> #DIV/0! | P6: =E6/$K$26 -> #DIV/0!
B7: 5 | F7: =(SUMIF(Planilha!$A$11:$A$1447,Cronograma!F$2,Planilha!$I$11:$I$1447)/2)+((SUMIF(Planilha!$J$11:$J$1447,"E4-L2i",Planilha!$I$11:$I$1447)/2)*$C$15)+(Planilha!$I$817+Planilha!$I$818)*$F$23+(Planilha!$I$13*$F$21) -> 40136311 | L7: =SUM(C7:K7) -> 40136311 | Q7: =F7/$K$26 -> #DIV/0!
B8: 6 | C8: =Planilha!I21 -> 6914669.2 | F8: =(SUMIF(Planilha!$A$11:$A$1447,Cronograma!F$2,Planilha!$I$11:$I$1447)/2)+((SUMIF(Planilha!$J$11:$J$1447,"E4-L2i",Planilha!$I$11:$I$1447)/2)*$C$15) -> 36915970 | G8: =(SUMIF(Planilha!$A$11:$A$1447,Cronograma!G$2,Planilha!$I$11:$I$1447)/2)+((SUMIF(Planilha!$J$11:$J$1447,"E4-L3i",Planilha!$I$11:$I$1447)/2)*$C$15)+(Planilha!$I$817+Planilha!$I$818)*$G$23+(Planilha!$I$13*$G$21) -> 21018609 | L8: =SUM(C8:K8) -> 64849249 | Q8: =F8/$K$26 -> #DIV/0! | R8: =G8/$K$26 -> #DIV/0!
B9: 7 | G9: =(SUMIF(Planilha!$A$11:$A$1447,Cronograma!G$2,Planilha!$I$11:$I$1447)/2)+((SUMIF(Planilha!$J$11:$J$1447,"E4-L3i",Planilha!$I$11:$I$1447)/2)*$C$15)+(Planilha!$I$817+Planilha!$I$818)*$H$23+(Planilha!$I$13*$H$21) -> 17798269 | H9: =(SUMIF(Planilha!$J$11:$J$1447,Cronograma!H$2,Planilha!$I$11:$I$1447)/2)+(SUMIF(Planilha!$J$11:$J$1447,"E3-L1I",Planilha!$I$11:$I$1447)/2)++((SUMIF(Planilha!$J$11:$J$1447,"E3-L1i",Planilha!$I$11:$I$1447)/2)*$C$15)+(Planilha!$I$22+Planilha!$I$23)*$H$24+(Planilha!$I$13*$H$22) -> 26603583 | L9: =SUM(C9:K9) -> 44401852 | N9: =C8/$K$26 -> #DIV/0! | R9: =G9/$K$26 -> #DIV/0!
B10: 8 | H10: =(SUMIF(Planilha!$J$11:$J$1447,Cronograma!H$2,Planilha!$I$11:$I$1447)/2)+(SUMIF(Planilha!$J$11:$J$1447,"E3-L1I",Planilha!$I$11:$I$1447)/2)+((SUMIF(Planilha!$J$11:$J$1447,"E3-L1i",Planilha!$I$11:$I$1447)/2)*$C$15) -> 23455667 | I10: =(SUMIF(Planilha!$J$11:$J$1447,Cronograma!I$2,Planilha!$I$11:$I$1447)/2)+(SUMIF(Planilha!$J$11:$J$1447,"E3-L2I",Planilha!$I$11:$I$1447)/2)+((SUMIF(Planilha!$J$11:$J$1447,"E3-L2i",Planilha!$I$11:$I$1447)/2)*$C$15)+(Planilha!$I$22+Planilha!$I$23)*$I$24+(Planilha!$I$13*$I$22) -> 32123417 | L10: =SUM(C10:K10) -> 55579084 | S10: =H9/$K$26 -> #DIV/0!
B11: 9 | I11: =(SUMIF(Planilha!$J$11:$J$1447,Cronograma!I$2,Planilha!$I$11:$I$1447)/2)+(SUMIF(Planilha!$J$11:$J$1447,"E3-L2I",Planilha!$I$11:$I$1447)/2)+((SUMIF(Planilha!$J$11:$J$1447,"E3-L2i",Planilha!$I$11:$I$1447)/2)*$C$15) -> 25827584 | J11: =(SUMIF(Planilha!$J$11:$J$1447,Cronograma!J$2,Planilha!$I$11:$I$1447)/2)+(SUMIF(Planilha!$J$11:$J$1447,"E3-L3I",Planilha!$I$11:$I$1447)/2)+((SUMIF(Planilha!$J$11:$J$1447,"E3-L3i",Planilha!$I$11:$I$1447)/2)*$C$15)+(Planilha!$I$22+Planilha!$I$23)*$J$24+(Planilha!$I$13*$J$22) -> 27994744 | L11: =SUM(C11:K11) -> 53822329 | S11: =H10/$K$26 -> #DIV/0! | T11: =I10/$K$26 -> #DIV/0!
B12: 10 | J12: =(SUMIF(Planilha!$J$11:$J$1447,Cronograma!J$2,Planilha!$I$11:$I$1447)/2)+(SUMIF(Planilha!$J$11:$J$1447,"E3-L3I",Planilha!$I$11:$I$1447)/2)+((SUMIF(Planilha!$J$11:$J$1447,"E3-L3i",Planilha!$I$11:$I$1447)/2)*$C$15) -> 21698912 | K12: =(SUMIF(Planilha!$J$11:$J$1447,Cronograma!K$2,Planilha!$I$11:$I$1447)/2)+(SUMIF(Planilha!$J$11:$J$1447,"E3-L4I",Planilha!$I$11:$I$1447)/2)++((SUMIF(Planilha!$J$11:$J$1447,"E3-L4i",Planilha!$I$11:$I$1447)/2)*$C$15)+(Planilha!$I$22+Planilha!$I$23)*$K$24+(Planilha!$I$13*$K$22) -> 21747033 | L12: =SUM(C12:K12) -> 43445945 | T12: =I11/$K$26 -> #DIV/0! | U12: =J11/$K$26 -> #DIV/0!
B13: 11 | K13: =(SUMIF(Planilha!$J$11:$J$1447,Cronograma!K$2,Planilha!$I$11:$I$1447)/2)++(SUMIF(Planilha!$J$11:$J$1447,"E3-L4I",Planilha!$I$11:$I$1447)/2)++((SUMIF(Planilha!$J$11:$J$1447,"E3-L4i",Planilha!$I$11:$I$1447)/2)*$C$15)++(Planilha!$I$22+Planilha!$I$23)*$L$24+(Planilha!$I$13*$L$22) -> 18599117 | L13: =SUM(C13:K13) -> 18599117 | U13: =J12/$K$26 -> #DIV/0! | V13: =K12/$K$26 -> #DIV/0!
B15: Equipamentos, peças e acessórios | C15: 0.05 | L15: =SUM(L3:L13) -> 4.7205359e+08
B16: Total Lotes | C16: =SUM(C17:C18) -> 14 | L16: =L15=Planilha!I11 -> TRUE
B17: Lotes E3 | C17: =COUNT($H$3:$K$13) -> 8
B18: Lotes E4 | C18: =COUNT($E$3:$G$13) -> 6
B20: Cronograma | C20: 2 | D20: 3 | E20: 4 | F20: 5 | G20: 6 | H20: 7 | I20: 8 | J20: 9 | K20: 10 | L20: 11
B21: Canteiro de obras - E4 | D21: =1/$C$16 -> 0.071428571 | E21: =1/$C$16 -> 0.071428571 | F21: =1/$C$16 -> 0.071428571 | G21: =1/$C$16*2 -> 0.14285714 | H21: =1/$C$16 -> 0.071428571
B22: Canteiro de obras - E3 | H22: =1/$C$16 -> 0.071428571 | I22: =1/$C$16*2 -> 0.14285714 | J22: =1/$C$16*2 -> 0.14285714 | K22: =1/$C$16*2 -> 0.14285714 | L22: =1/$C$16 -> 0.071428571
B23: Supervisão de obras - E4 | D23: =1/$C$18 -> 0.16666667 | E23: =1/$C$18 -> 0.16666667 | F23: =1/$C$18 -> 0.16666667 | G23: =1/$C$18*2 -> 0.33333333 | H23: =1/$C$18 -> 0.16666667
B24: Supervisão de obras - E3 | H24: =1/$C$17 -> 0.125 | I24: =1/$C$17*2 -> 0.25 | J24: =1/$C$17*2 -> 0.25 | K24: =1/$C$17*2 -> 0.25 | L24: =1/$C$17 -> 0.125
B27: Faseamento Implantação Projeto Jaíba
B28: Etapa | C28: Lote | D28: Canais | E28: Ext. (km) | F28: Blocos | G28: Área (ha) | H28: Obs.
B29: 3 | C29: 1 | D29: CS19 (até EC3) | E29: 10.1 | F29: 7 | G29: 2386.6735
D30: CT1-S19 | E30: 5.35 | F30: 3 | G30: 822.54714
D31: Total | E31: =SUM(E29:E30) -> 15.45 | F31: =SUM(F29:F30) -> 10 | G31: =SUM(G29:G30) -> 3209.2207
C32: 3 | D32: CS19 (até final) | E32: =22.18-E29 -> 12.08 | F32: 7 | G32: 1949.3665
D33: Total | E33: =E32 -> 12.08 | F33: =F32 -> 7 | G33: =G32 -> 1949.3665
C34: 2 | D34: CS21 (até EC3) | E34: 8 | F34: 7 | G34: 2217.8547
D35: CT2-S21 | E35: 2.6 | F35: 4 | G35: 1367.0125
D36: Total | E36: =SUM(E34:E35) -> 10.6 | F36: =F34+F35 -> 11 | G36: =G34+G35 -> 3584.8672
C37: 4 | D37: CS21 (até final) | E37: =19.2-E34 -> 11.2 | F37: 8 | G37: 1973.6512
D38: Total | E38: =E37 -> 11.2 | F38: =F37 -> 8 | G38: =G37 -> 1973.6512 | I38: =G31+G33+G36+G38 -> 10717.106
B39: 4 | C39: 1 | D39: CP3 | E39: 10 | F39: 10 | G39: 2764
D40: CS23 | E40: 2.6 | F40: 1 | G40: 269
D41: Total | E41: =E39+E40 -> 12.6 | F41: =F39+F40 -> 11 | G41: =G39+G40 -> 3033
C42: 2 | D42: CP3a | E42: 9.9 | F42: 9 | G42: 2501
D43: CP3b | E43: 4 | F43: 6 | G43: 1016
D44: TS29 | E44: 1.6 | F44: 1 | G44: 127
...

Sheet Preços Unitários
F4: =+BDI!C16 -> 0.2527
A5: Fonte | B5: Código | C5: Descrição do Serviço | D5: Unidade | E5: Custo Unitário (R$) | F5: BDI | G5: Preço Unitário com BDI (R$)
A6: SICRO | B6: 0307731 | C6: Aparelho de apoio de neoprene fretado para estruturas moldadas no local - fornecimento e instalação | D6: dm³ | E6: 150.12 | F6: =+E6*$F$4 -> 37.935324 | G6: =+E6+F6 -> 188.05532
A7: SICRO | B7: 0307732 | C7: Aparelho de apoio de neoprene fretado para estruturas pré-moldadas - fornecimento e instalação | D7: dm³ | E7: 124.93 | F7: =+E7*$F$4 -> 31.569811 | G7: =+E7+F7 -> 156.49981
A8: SICRO | B8: 0308308 | C8: Aparelho de apoio metálico elastomérico fixo com capacidade de 1.500 kN - fornecimento e instalação | D8: un | E8: 5208.94 | F8: =+E8*$F$4 -> 1316.2991 | G8: =+E8+F8 -> 6525.2391
A9: SICRO | B9: 0308313 | C9: Aparelho de apoio metálico elastomérico fixo com capacidade de 10.000 kN - fornecimento e instalação | D9: un | E9: 32060.18 | F9: =+E9*$F$4 -> 8101.6075 | G9: =+E9+F9 -> 40161.787
A10: SICRO | B10: 0308309 | C10: Aparelho de apoio metálico elastomérico fixo com capacidade de 2.500 kN - fornecimento e instalação | D10: un | E10: 8634.05 | F10: =+E10*$F$4 -> 2181.8244 | G10: =+E10+F10 -> 10815.874
A11: SICRO | B11: 0308310 | C11: Aparelho de apoio metálico elastomérico fixo com capacidade de 4.000 kN - fornecimento e instalação | D11: un | E11: 11540.09 | F11: =+E11*$F$4 -> 2916.1807 | G11: =+E11+F11 -> 14456.271
A12: SICRO | B12: 0308311 | C12: Aparelho de apoio metálico elastomérico fixo com capacidade de 5.500 kN - fornecimento e instalação | D12: un | E12: 16369.55 | F12: =+E12*$F$4 -> 4136.5853 | G12: =+E12+F12 -> 20506.135
A13: SICRO | B13: 0308312 | C13: Aparelho de apoio metálico elastomérico fixo com capacidade de 7.500 kN - fornecimento e instalação | D13: un | E13: 22859.75 | F13: =+E13*$F$4 -> 5776.6588 | G13: =+E13+F13 -> 28636.409
A14: SICRO | B14: 0308307 | C14: Aparelho de apoio metálico elastomérico fixo com capacidade de 700 kN - fornecimento e instalação | D14: un | E14: 3103.37 | F14: =+E14*$F$4 -> 784.2216 | G14: =+E14+F14 -> 3887.5916
A15: SICRO | B15: 0308322 | C15: Aparelho de apoio metálico elastomérico multidirecional com capacidade de 1.500 kN - fornecimento e instalação | D15: un | E15: 4910.86 | F15: =+E15*$F$4 -> 1240.9743 | G15: =+E15+F15 -> 6151.8343
A16: SICRO | B16: 0308327 | C16: Aparelho de apoio metálico elastomérico multidirecional com capacidade de 10.000 kN - fornecimento e instalação | D16: un | E16: 29569.3 | F16: =+E16*$F$4 -> 7472.1621 | G16: =+E16+F16 -> 37041.462
A17: SICRO | B17: 0308323 | C17: Aparelho de apoio metálico elastomérico multidirecional com capacidade de 2.500 kN - fornecimento e instalação | D17: un | E17: 7724.89 | F17: =+E17*$F$4 -> 1952.0797 | G17: =+E17+F17 -> 9676.9697
... A6499: SICRO | B6499: 7107378 | C6499: Tratamento superficial e pintura do fundo do flutuante | D6499: m² | E6499: 190.02 | F6499: =+E6499*$F$4 -> 48.018054 | G6499: =+E6499+F6499 -> 238.03805

Sheet BDI
B2: A - Bonificação (lucros) | C2: 0.08
B4: B - Despesas Indiretas | C4: =SUM(C5:C8) -> 0.0894
B5: B 1 - Administração Central | C5: 0.07
B6: B 2 - Seguro + Garantia | C6: 0.0031
B7: B 3 - Risco | C7: 0.0063
B8: B 4 - Despesas Financeiras | C8: 0.01
B10: C - Tributos | C10: =SUM(C11:C14) -> 0.0833
B11: C 1 - PIS | C11: 0.0081
B12: C 2 - ISS | C12: 0.0376
B13: C 3 - COFINS | C13: 0.0376
B14: C 4 - CPRB | C14: 0
B16: BDI | C16: =+C2+C4+C10 -> 0.2527

Sheet Composições de Preços
A1: DEMONSTRATIVO DAS COMPOSICOES DE PRECOS UNITARIOS DE SERVICOS | F1: DATA BASE: 07/2025
A3: Discriminação: | B3: Fornecimento e aplicação de geomembrana sintética para impermeabilização do canal, 1,00 mm de espessura (PEAD) | E3: CÓDIGO: | F3: CPU-CAN001
E4: UNIDADE: | F4: m²
A6: CÓDIGO DO INSUMO | B6: DESCRIÇÃO | C6: UNIDADE | D6: VALOR UNITÁRIO | E6: COEFICIENTE | F6: VALOR PARCELA
A8: MATERIAL
A9: COTAÇÃO | B9: Manta termoplástica, PEAD, geomembrana texturizada em ambas as faces, e = 1,00 mm (NBR 15352) | C9: m² | D9: 46.22 | E9: 1.05 | F9: =+D9*E9 -> 48.531
F10: =+D10*E10 -> 0
F11: =+D11*E11 -> 0
F12: =+D12*E12 -> 0
F13: =+D13*E13 -> 0
A15: MÃO DE OBRA
A16: P9821 | B16: Pedreiro | C16: hora | D16: 27.5523 | E16: 0.2 | F16: =+D16*E16 -> 5.51046
A17: P9824 | B17: Servente | C17: hora | D17: 21.634 | E17: 0.2 | F17: =+D17*E17 -> 4.3268
F18: =+D18*E18 -> 0
F19: =+D19*E19 -> 0
A21: EQUIPAMENTO
F23: =+D23*E23 -> 0
F24: =+D24*E24 -> 0
F25: =+D25*E25 -> 0
F26: =+D26*E26 -> 0
A28: OUTROS SERVIÇOS
F30: =+D30*E30 -> 0
F31: =+D31*E31 -> 0
F32: =+D32*E32 -> 0
F33: =+D33*E33 -> 0
D35: COMPONENTES DE CUSTO
D36: MATERIAL | E36: =+F36/F$41 -> 0.83146217 | F36: =SUM(F9:F14) -> 48.531
D37: MÃO DE OBRA | E37: =+F37/F$41 -> 0.16853783 | F37: =SUM(F16:F20) -> 9.83726
D38: EQUIPAMENTO | E38: =+F38/F$41 -> 0 | F38: =SUM(F23:F27) -> 0
D39: OUTROS SERVIÇOS | E39: =+F39/F$41 -> 0 | F39: =SUM(F30:F33) -> 0
D41: CUSTO TOTAL | E41: =SUM(E36:E40) -> 1 | F41: =SUM(F36:F40) -> 58.36826
D42: BDI | E42: 0.2527 | F42: =+F41*E42 -> 14.749659
D44: PREÇO TOTAL | F44: =SUM(F41:F43) -> 73.117919
A46: Discriminação: | B46: Fornecimento e instalação de geocomposto drenante para os taludes | E46: CÓDIGO: | F46: CPU-CAN002
E47: UNIDADE: | F47: m²
A49: CÓDIGO DO INSUMO | B49: DESCRIÇÃO | C49: UNIDADE | D49: VALOR UNITÁRIO | E49: COEFICIENTE | F49: VALOR PARCELA
A51: MATERIAL
A52: M0107 | B52: Geocomposto para drenagem | C52: m² | D52: 43.0225 | E52: 1.1 | F52: =+D52*E52 -> 47.32475
F53: =+D53*E53 -> 0
F54: =+D54*E54 -> 0
...

Sheet Critérios
A1: CRITÉRIOS DE QUANTIFICAÇÃO DOS SERVIÇOS
A3: CANAIS
L6: L talude
J7: altura (1,0)
L10: base (1,5)
J11: L talude = √(1,5² + 1,0²) = 1,8028
A16: DESMATAMENTO:
A17: Extensão X 40 metros (faixa de domínio)
A19: TERRAPLENAGEM:
A20: Calculado nos desenhos de projeto
A22: REVESTIMENTO (Geocomposto + Geomembrana):
A23: Taludes 1:1,5
A24: Perímetro = base + 2X L talude + 0,40 (ancoragem)
A26: CONCRETO:
A27: Área REVESTIMENTO X 0,07 m
A29: JUNTAS:
A30: Perímetro X Comprimento do canal ÷ 2 (junta a cada 2,00 metros)
A32: GUIAS:
... A92: L X 2 X 2,20 (h)

Sheet Ficha Canais
A1: FICHA TÉCNICA DOS CANAIS
A3: ETAPA 3 | J3: REVISÃO
A4: SEGMENTO | B4: EXTENSÃO | C4: BASE | D4: ALTURA | E4: REVESTIMENTO MANTA | F4: CONCRETO REVESTIMENTO | G4: ESCAVAÇÃO | H4: ATERRO | I4: GEOCOMPOSTO | J4: EXTENSÃO | K4: REVESTIMENTO MANTA | L4: CONCRETO REVESTIMENTO | M4: ESCAVAÇÃO | N4: ATERRO | O4: GEOCOMPOSTO
A5: Canal: CS19 - Trecho 1 | B5: 850 | C5: 1.8 | D5: 2.11 | E5: 7898 | F5: 552.83 | G5: 1218.69 | H5: 40104.47 | I5: 1974.3913 | J5: 850 | K5: 7603 | L5: 532.21 | M5: 1218.69 | N5: 40104.47 | O5: 1901
A6: Canal: CS19 - Trecho 2 | B6: 4950 | C6: 1.5 | D6: 1.72 | E6: 37535 | F6: 2627.43 | G6: 187330.72 | H6: 23759.27 | I6: 9383.6913 | J6: 4950 | K6: 36840 | L6: 2578.8 | M6: 187330.72 | N6: 23759.27 | O6: 9210
A7: Canal: CS19 - Trecho 3 | B7: 4292 | C7: 1.2 | D7: 1.58 | E7: 26863 | F7: 1880.43 | G7: 257084.94 | H7: 31272.74 | I7: 6715.8087 | J7: 4292 | K7: 26863 | L7: 1880.43 | M7: 257084.94 | N7: 31272.74 | O7: 6715.8087
A8: Canal: CS19 - Trecho 4 | B8: 4192 | C8: 1 | D8: 1.37 | E8: 24524 | F8: 1716.7 | G8: 196281.71 | H8: 825.37 | I8: 6131.0759 | J8: 4192 | K8: 24524 | L8: 1716.7 | M8: 196281.71 | N8: 825.37 | O8: 6131.0759
A9: Canal: CS19 - Trecho 5 | B9: 6192 | C9: 1 | D9: 1.37 | E9: 36225 | F9: 2535.74 | G9: 172403.48 | H9: 59799.23 | I9: 9056.208 | J9: 6192 | K9: 36225 | L9: 2535.74 | M9: 172403.48 | N9: 59799.23 | O9: 9056.208
A10: Canal: CS19 - Trecho 6 | B10: 0 | C10: 0 | D10: 0 | E10: 0 | F10: 0 | G10: 0 | H10: 0 | I10: 0 | J10: 0 | K10: 0 | L10: 0 | M10: 0 | N10: 0 | O10: 0
A11: Canal: CT1-CS19 - Trecho 1 | B11: 5600 | C11: 0.8 | D11: 1.16 | E11: 27643 | F11: 1935 | G11: 60141.74 | H11: 36362.25 | I11: 6910.7211 | J11: 5349 | K11: 26404 | L11: 1848.28 | M11: 54668.67 | N11: 36393.86 | O11: 6601
A12: Canal: CT1-CS19 - Trecho 2 | B12: 5670 | C12: 0.4 | D12: 0.81 | E12: 18536 | F12: 1297.55 | G12: 82739.12 | H12: 43846.24 | I12: 4634.1121 | J12: 0 | K12: 0 | L12: 0 | M12: 0 | N12: 0 | O12: 0
A13: Canal: CS21 | B13: 1670 | C13: 1.8 | D13: 2.29 | E13: 16557 | F13: 1158.96 | G13: 32288.39 | H13: 11965.57 | I13: 4139.1505 | J13: 1670 | K13: 16557 | L13: 1158.96 | M13: 32288.39 | N13: 11965.57 | O13: 4139.1505
A14: Canal: CS21a - Trecho 1 | B14: 4000 | C14: 1.5 | D14: 2.08 | E14: 35486 | F14: 2484 | G14: 10303.58 | H14: 104100.52 | I14: 8871.4224 | J14: 4000 | K14: 35486 | L14: 2484 | M14: 10339.03 | N14: 104054.4 | O14: 8871.4224
A15: Canal: CS21a - Trecho 2 | B15: 3992 | C15: 1.5 | D15: 1.98 | E15: 31129 | F15: 2179.04 | G15: 31229.53 | H15: 137619.45 | I15: 7782.3017 | J15: 3992 | K15: 31129 | L15: 2179.04 | M15: 31221.93 | N15: 137607 | O15: 7782.3017
A16: Canal: CS21a - Trecho 3 | B16: 742 | C16: 1.2 | D16: 1.7 | E16: 5371 | F16: 375.94 | G16: 17518.4 | H16: 758.23 | I16: 1342.6421 | J16: 3292 | K16: 22747 | L16: 1592.29 | M16: 12014.31 | N16: 151425.7 | O16: 5687
... A20: Canal: CT2-S21 | B20: 2600 | C20: 0.8 | D20: 1.21 | E20: 13253 | F20: 927.69 | G20: 33821.54 | H20: 13007.64 | I20: 3313.174 | J20: 2600 | K20: 13253 | L20: 927.69 | M20: 33821.54 | N20: 13007.64 | O20: 3313.174
A21: TOTAL | B21: =SUM(B5:B20) -> 56994 | E21: =SUM(E5:E20) -> 358692 | F21: =SUM(F5:F20) -> 25108.39 | G21: =SUM(G5:G20) -> 1254654 | H21: =SUM(H5:H20) -> 540842.36 | I21: =SUM(I5:I20) -> 89672.826 | J21: =SUM(J5:J20) -> 48376 | K21: =SUM(K5:K20) -> 318105 | L21: =SUM(L5:L20) -> 22267.32 | ... O21: =SUM(O5:O20) -> 79526.141
A23: ETAPA 4
A24: SEGMENTO | B24: EXTENSÃO | C24: BASE | D24: ALTURA | E24: REVESTIMENTO MANTA | F24: CONCRETO REVESTIMENTO | G24: ESCAVAÇÃO | H24: ATERRO | I24: GEOCOMPOSTO | J24: EXTENSÃO | K24: REVESTIMENTO MANTA | L24: CONCRETO REVESTIMENTO | M24: ESCAVAÇÃO | N24: ATERRO | O24: GEOCOMPOSTO
A25: Canal: CP3 - Trecho 1 | B25: 1950 | C25: 1.8 | D25: 2.65 | E25: 21796 | F25: 1525.75 | G25: 1049.11 | H25: 86734.59 | I25: 5449.1036 | J25: 1950 | K25: 21796 | L25: 1525.75 | M25: 1049.11 | N25: 86734.59 | O25: 5449.1036
A26: Canal: CP3 - Trecho 2 | B26: 4900 | C26: 1.8 | D26: 2.56 | E26: 53323 | F26: 3732.6 | G26: 87315.64 | H26: 35943.57 | I26: 13330.718 | J26: 4900 | K26: 53323 | L26: 3732.6 | M26: 87315.64 | N26: 35943.57 | O26: 13330.718
A27: Canal: CP3 - Trecho 3 | B27: 2982 | C27: 1.5 | D27: 2.02 | E27: 25880 | F27: 1811.58 | G27: 72198.38 | H27: 10868.67 | I27: 6469.9214 | J27: 2982 | K27: 25880 | L27: 1811.58 | M27: 72198.38 | N27: 10868.67 | O27: 6469.9214
A28: Canal: CP3a - Trecho 1 | B28: 5000 | C28: 1.2 | D28: 1.72 | E28: 36484 | F28: 2553.85 | G28: 86098.91 | H28: 94515.39 | I28: 9120.905 | J28: 5000 | K28: 36484 | L28: 2553.85 | M28: 86098.91 | N28: 94515.39 | O28: 9120.905
A29: Canal: CP3a - Trecho 2 | B29: 2670 | C29: 1 | D29: 1.4 | E29: 16511 | F29: 1155.79 | G29: 83046.67 | H29: 28206.89 | I29: 4127.8037 | J29: 2670 | K29: 16511 | L29: 1155.79 | M29: 83046.67 | N29: 28206.89 | O29: 4127.8037
A30: Canal: CP3b - Trecho 1 | B30: 2100 | C30: 0.8 | D30: 1.29 | E30: 11290 | F30: 790.3 | G30: 7609.24 | H30: 27541.36 | I30: 2822.5134 | J30: 2100 | K30: 11290 | L30: 790.3 | M30: 7609.24 | N30: 27541.36 | O30: 2822.5134
A31: Canal: CP3b - Trecho 2 | B31: 0 | C31: 0 | D31: 0 | E31: 0 | F31: 0 | G31: 0 | H31: 0 | I31: 0 | J31: 0 | K31: 0 | L31: 0 | M31: 0 | N31: 0 | O31: 0
A32: Canal: CS23 | B32: 2591 | C32: 0.4 | D32: 0.73 | E32: 7755 | F32: 542.86 | G32: 11948.53 | H32: 5884.78 | I32: 1938.7744 | J32: 2591 | K32: 7755 | L32: 542.86 | M32: 11948.53 | N32: 5884.78 | O32: 1938.7744
A33: Canal: CS25 - Trecho 1 | B33: 4000 | C33: 1.2 | D33: 1.56 | E33: 11393 | F33: 797.49 | G33: 9648.14 | H33: 147510.42 | I33: 2848.1733 | J33: 4000 | K33: 11393 | L33: 797.49 | M33: 9648.14 | N33: 147510.42 | O33: 2848.1733
A34: Canal: CS25 - Trecho 2 | B34: 1392 | C34: 0.8 | D34: 1.16 | E34: 26971 | F34: 1888 | G34: 1879.1 | H34: 128031.35 | I34: 6742.8538 | J34: 1392 | K34: 26971 | L34: 1888 | M34: 1879.1 | N34: 128031.35 | O34: 6742.8538
A35: Canal: CS27 | B35: 3186 | C35: 0.6 | D35: 0.85 | E35: 6851 | F35: 479.54 | G35: 42907 | H35: 37839.32 | I35: 1712.6521 | J35: 3186 | K35: 6851 | L35: 479.54 | M35: 42907 | N35: 37839.32 | O35: 1712.6521
A36: Canal: CS29 | B36: 0 | C36: 0 | D36: 0 | E36: 0 | F36: 0 | G36: 0 | H36: 0 | I36: 0 | J36: 0 | K36: 0 | L36: 0 | M36: 0 | N36: 0 | O36: 0
A37: TOTAL | B37: =SUM(B25:B36) -> 30771 | E37: =SUM(E25:E36) -> 218254 | F37: =SUM(F25:F36) -> 15277.76 | G37: =SUM(G25:G36) -> 403700.72 | H37: =SUM(H25:H36) -> 603076.34 | I37: =SUM(I25:I36) -> 54563.419 | J37: =SUM(J25:J36) -> 30771 | K37: =SUM(K25:K36) -> 218254 | L37: =SUM(L25:L36) -> 15277.76 | ... O37: =SUM(O25:O36) -> 54563.419
B39: =+B21+B37 -> 87765 | E39: =+E21+E37 -> 576946 | F39: =+F21+F37 -> 40386.15 | I39: =+I21+I37 -> 144236.24 | J39: =+J21+J37 -> 79147 | K39: =+K21+K37 -> 536359 | L39: =+L21+L37 -> 37545.08 | O39: =+O21+O37 -> 134089.56

Sheet Ficha EC
A1: FICHA TÉCNICA DAS ESTRUTURAS DE CONTROLE
K2: =+BDI!C16 -> 0.2527
A3: ETAPA 3 | G3: COMPORTAS
A4: SEGMENTO | B4: EXTENSÃO | C4: BASE | D4: COTA BERMA | E4: COTA FUNDO | F4: ALTURA | G4: Código | H4: Preço Material | I4: Mão-de-Obra | J4: SUBTOTAL | K4: BDI | L4: TOTAL
A5: EC2 - CS19 | B5: 8 | C5: 3.2 | D5: 474.39 | E5: 472.83 | F5: =+D5-E5 -> 1.56 | G5: CPU-CPT001 | H5: 80000 | I5: =+H5*0.3 -> 24000 | J5: =+H5+I5 -> 104000 | K5: =+J5*$K$2 -> 26280.8 | L5: =+J5+K5 -> 130280.8
A6: EC3 - CS19 | B6: 8 | C6: 2.6 | D6: 473.58 | E6: 472.19 | F6: =+D6-E6 -> 1.39 | G6: CPU-CPT002 | H6: 64000 | I6: =+H6*0.3 -> 19200 | J6: =+H6+I6 -> 83200 | K6: =+J6*$K$2 -> 21024.64 | L6: =+J6+K6 -> 104224.64
A7: EC4 - CS19 | B7: 8 | C7: 2.6 | D7: 472.74 | E7: 471.35 | F7: =+D7-E7 -> 1.39 | G7: CPU-CPT003 | H7: 64000 | I7: =+H7*0.3 -> 19200 | J7: =+H7+I7 -> 83200 | K7: =+J7*$K$2 -> 21024.64 | L7: =+J7+K7 -> 104224.64
A8: EC5 - CS19 | B8: 8 | C8: 1.3 | D8: 471.3 | E8: 470.11 | F8: =+D8-E8 -> 1.19 | G8: CPU-CPT004 | H8: 40800 | I8: =+H8*0.3 -> 12240 | J8: =+H8+I8 -> 53040 | K8: =+J8*$K$2 -> 13403.208 | L8: =+J8+K8 -> 66443.208
A9: EC6 - CT1-S19 | B9: EXCLUÍDO DO ORÇAMENTO REVISADO
A10: EC2 - CS21a | B10: 8 | C10: 4 | D10: 479.76 | E10: 477.8 | F10: =+D10-E10 -> 1.96 | G10: CPU-CPT006 | H10: 124000 | I10: =+H10*0.3 -> 37200 | J10: =+H10+I10 -> 161200 | K10: =+J10*$K$2 -> 40735.24 | L10: =+J10+K10 -> 201935.24
A11: EC3 - CS21a | B11: 8 | C11: 3.3 | D11: 479.12 | E11: 477.4 | F11: =+D11-E11 -> 1.72 | G11: CPU-CPT007 | H11: 93600 | I11: =+H11*0.3 -> 28080 | J11: =+H11+I11 -> 121680 | K11: =+J11*$K$2 -> 30748.536 | L11: =+J11+K11 -> 152428.54
A12: EC4 - CS21a | B12: 8 | C12: 3.1 | D12: 463.48 | E12: 461.92 | F12: =+D12-E12 -> 1.56 | G12: CPU-CPT008 | H12: 81600 | I12: =+H12*0.3 -> 24480 | J12: =+H12+I12 -> 106080 | K12: =+J12*$K$2 -> 26806.416 | L12: =+J12+K12 -> 132886.42
A13: EC5 - CS21a | B13: 8 | C13: 2.3 | D13: 462.63 | E13: 461.32 | F13: =+D13-E13 -> 1.31 | G13: CPU-CPT009 | H13: 86800 | I13: =+H13*0.3 -> 26040 | J13: =+H13+I13 -> 112840 | K13: =+J13*$K$2 -> 28514.668 | L13: =+J13+K13 -> 141354.67
A15: ETAPA 4
A16: SEGMENTO | B16: EXTENSÃO | C16: BASE | D16: COTA BERMA | E16: COTA FUNDO | F16: ALTURA | H16: Preço Material | I16: Mão-de-Obra | J16: SUBTOTAL | K16: BDI | L16: TOTAL
A17: EC2 - CP3 | B17: 8 | C17: 4 | D17: 478.14 | E17: 476.1 | F17: =+D17-E17 -> 2.04 | G17: CPU-CPT010 | H17: 128000 | I17: =+H17*0.3 -> 38400 | J17: =+H17+I17 -> 166400 | K17: =+J17*$K$2 -> 42049.28 | L17: =+J17+K17 -> 208449.28
A18: EC3 - CP3a | B18: 8 | C18: 2.7 | D18: 480.13 | E18: 478.73 | F18: =+D18-E18 -> 1.4 | G18: CPU-CPT011 | H18: 66400 | I18: =+H18*0.3 -> 19920 | J18: =+H18+I18 -> 86320 | K18: =+J18*$K$2 -> 21813.064 | L18: =+J18+K18 -> 108133.06
A19: EC4 - CS25 | B19: 8 | C19: 2.1 | D19: 479.69 | E19: 478.51 | F19: =+D19-E19 -> 1.18 | G19: CPU-CPT012 | H19: 48400 | I19: =+H19*0.3 -> 14520 | J19: =+H19+I19 -> 62920 | K19: =+J19*$K$2 -> 15899.884 | L19: =+J19+K19 -> 78819.884

Sheet Ficha EXTRAV
E2: Dissipador de Energia | M2: Mureta (Dissipador) | S2: Mureta (Enrocamento) | X2: Enrocamento
B3: Obra | C3: Trecho | D3: L (m) | E3: Ainício (m²) | F3: Adegrau (m²) | G3: Afinal (m²) | H3: N degraus (un) | I3: Plat (m) | J3: Pfundo (m) | K3: Forma (m²) | L3: Concreto (m³) | M3: Largura (m) | N3: Alat (m²) | O3: Pfechamento (m) | P3: Pfundo (m) | Q3: Forma (m²) | R3: Concreto (m³) | S3: Comprimento (m) | T3: Altura (m) | U3: Largura (m) | V3: Forma (m²) | W3: Concreto (m³) | X3: L1 (m) | Y3: L2 (m) | Z3: C1 (m) | AA3: C2 (m) | AB3: Altura (m) | AC3: Volume (m³)
B4: EX-1 | C4: CS19-Trecho 2 | D4: 20.5 | E4: 3.22 | F4: 2.18 | G4: 5.37 | H4: 7 | I4: =(1.19+2.41)+(0.96+0.5+1)+(1*H4) -> 13.06 | J4: =(1+1.18)+(1.5+3.09+2.09)+(1.92*H4) -> 22.3 | K4: =I4*D4 -> 267.73 | L4: =($E$4+$F$4*H4+$G$4)*D4 -> 488.925 | M4: 0.4 | N4: 66.38 | O4: 5.15 | P4: 24.47 | Q4: =2*((2*$N$4)+($M$4*$O$4)) -> 269.64 | R4: =$N$4*$M$4 -> 26.552 | S4: =SQRT(((1.5*D4)-2.2)^2+(0.5*D4*0.5)^2) -> 29.006346 | T4: =1.5+AB4 -> 2.5 | U4: =M4 -> 0.4 | V4: =2*((2*S4*$T$4)+($T$4*$U$4)) -> 292.06346 | W4: =S4*$T$4*$U$4*2 -> 58.012693 | X4: =D4 -> 20.5 | Y4: =X4*1.5 -> 30.75 | Z4: 2.2 | AA4: =Y4-$Z$4 -> 28.55 | AB4: 1 | AC4: =AB4*((X4*$Z$4)+((X4+Y4)*0.5*AA4)) -> 776.69375
B5: EX-2 | C5: CS19-Trecho 3 | D5: 14.8 | H5: 7 | I5: =(1.19+2.41)+(0.96+0.5+1)+(1*H5) -> 13.06 | J5: =(1+1.18)+(1.5+3.09+2.09)+(1.92*H5) -> 22.3 | K5: =I5*D5 -> 193.288 | L5: =($E$4+$F$4*H5+$G$4)*D5 -> 352.98 | Q5: =2*((2*$N$4)+($M$4*$O$4)) -> 269.64 | R5: =$N$4*$M$4 -> 26.552 | S5: =SQRT(((1.5*D5)-2.2)^2+(0.5*D5*0.5)^2) -> 20.339371 | V5: =2*((2*S5*$T$4)+($T$4*$U$4)) -> 205.39371 | W5: =S5*$T$4*$U$4*2 -> 40.678741 | X5: =D5 -> 14.8 | Y5: =X5*1.5 -> 22.2 | AA5: =Y5-$Z$4 -> 20 | AB5: 1 | AC5: =AB5*((X5*$Z$4)+((X5+Y5)*0.5*AA5)) -> 402.56
B6: EX-3 | C6: CS19-Trecho 4 | D6: 10.8 | H6: 7 | I6: =(1.19+2.41)+(0.96+0.5+1)+(1*H6) -> 13.06 | J6: =(1+1.18)+(1.5+3.09+2.09)+(1.92*H6) -> 22.3 | K6: =I6*D6 -> 141.048 | L6: =($E$4+$F$4*H6+$G$4)*D6 -> 257.58 | Q6: =2*((2*$N$4)+($M$4*$O$4)) -> 269.64 | R6: =$N$4*$M$4 -> 26.552 | S6: =SQRT(((1.5*D6)-2.2)^2+(0.5*D6*0.5)^2) -> 14.25798 | V6: =2*((2*S6*$T$4)+($T$4*$U$4)) -> 144.5798 | W6: =S6*$T$4*$U$4*2 -> 28.51596 | X6: =D6 -> 10.8 | Y6: =X6*1.5 -> 16.2 | AA6: =Y6-$Z$4 -> 14 | AB6: 1 | AC6: =AB6*((X6*$Z$4)+((X6+Y6)*0.5*AA6)) -> 212.76
B7: EX-4 | C7: CS19-Trecho 5 | D7: 10.8 | H7: 7 | I7: =(1.19+2.41)+(0.96+0.5+1)+(1*H7) -> 13.06 | J7: =(1+1.18)+(1.5+3.09+2.09)+(1.92*H7) -> 22.3 | K7: =I7*D7 -> 141.048 | L7: =($E$4+$F$4*H7+$G$4)*D7 -> 257.58 | Q7: =2*((2*$N$4)+($M$4*$O$4)) -> 269.64 | R7: =$N$4*$M$4 -> 26.552 | S7: =SQRT(((1.5*D7)-2.2)^2+(0.5*D7*0.5)^2) -> 14.25798 | V7: =2*((2*S7*$T$4)+($T$4*$U$4)) -> 144.5798 | W7: =S7*$T$4*$U$4*2 -> 28.51596 | X7: =D7 -> 10.8 | Y7: =X7*1.5 -> 16.2 | AA7: =Y7-$Z$4 -> 14 | AB7: 1 | AC7: =AB7*((X7*$Z$4)+((X7+Y7)*0.5*AA7)) -> 212.76
B8: EX-5 | C8: CT1-CS19-Trecho 1 | D8: 6.2 | H8: 7 | I8: =(1.19+2.41)+(0.96+0.5+1)+(1*H8) -> 13.06 | J8: =(1+1.18)+(1.5+3.09+2.09)+(1.92*H8) -> 22.3 | K8: =I8*D8 -> 80.972 | L8: =($E$4+$F$4*H8+$G$4)*D8 -> 147.87 | Q8: =2*((2*$N$4)+($M$4*$O$4)) -> 269.64 | R8: =$N$4*$M$4 -> 26.552 | S8: =SQRT(((1.5*D8)-2.2)^2+(0.5*D8*0.5)^2) -> 7.2672209 | V8: =2*((2*S8*$T$4)+($T$4*$U$4)) -> 74.672209 | W8: =S8*$T$4*$U$4*2 -> 14.534442 | X8: =D8 -> 6.2 | Y8: =X8*1.5 -> 9.3 | AA8: =Y8-$Z$4 -> 7.1 | AB8: 1 | AC8: =AB8*((X8*$Z$4)+((X8+Y8)*0.5*AA8)) -> 68.665
B9: EX-6 | C9: CT1-CS19-Trecho 2 | H9: 7 | I9: =(1.19+2.41)+(0.96+0.5+1)+(1*H9) -> 13.06 | J9: =(1+1.18)+(1.5+3.09+2.09)+(1.92*H9) -> 22.3 | S9: ELIMINADO | X9: =D9 -> 0 | Y9: =X9*1.5 -> 0 | AA9: =Y9-$Z$4 -> -2.2
B10: EX-1 | C10: CS21 | D10: 24.9 | H10: 7 | I10: =(1.19+2.41)+(0.96+0.5+1)+(1*H10) -> 13.06 | J10: =(1+1.18)+(1.5+3.09+2.09)+(1.92*H10) -> 22.3 | K10: =I10*D10 -> 325.194 | L10: =($E$4+$F$4*H10+$G$4)*D10 -> 593.865 | Q10: =2*((2*$N$4)+($M$4*$O$4)) -> 269.64 | R10: =$N$4*$M$4 -> 26.552 | S10: =SQRT(((1.5*D10)-2.2)^2+(0.5*D10*0.5)^2) -> 35.696962 | V10: =2*((2*S10*$T$4)+($T$4*$U$4)) -> 358.96962 | W10: =S10*$T$4*$U$4*2 -> 71.393925 | X10: =D10 -> 24.9 | Y10: =X10*1.5 -> 37.35 | AA10: =Y10-$Z$4 -> 35.15 | AB10: 1 | AC10: =AB10*((X10*$Z$4)+((X10+Y10)*0.5*AA10)) -> 1148.8237
B11: EX-2 | C11: CS21a-Trecho 1 | D11: 17.8 | H11: 7 | I11: =(1.19+2.41)+(0.96+0.5+1)+(1*H11) -> 13.06 | J11: =(1+1.18)+(1.5+3.09+2.09)+(1.92*H11) -> 22.3 | K11: =I11*D11 -> 232.468 | L11: =($E$4+$F$4*H11+$G$4)*D11 -> 424.53 | Q11: =2*((2*$N$4)+($M$4*$O$4)) -> 269.64 | R11: =$N$4*$M$4 -> 26.552 | S11: =SQRT(((1.5*D11)-2.2)^2+(0.5*D11*0.5)^2) -> 24.900853 | V11: =2*((2*S11*$T$4)+($T$4*$U$4)) -> 251.00853 | W11: =S11*$T$4*$U$4*2 -> 49.801707 | X11: =D11 -> 17.8 | Y11: =X11*1.5 -> 26.7 | AA11: =Y11-$Z$4 -> 24.5 | AB11: 1 | AC11: =AB11*((X11*$Z$4)+((X11+Y11)*0.5*AA11)) -> 584.285
B12: EX-3 | C12: CS21a-Trecho 2 | D12: 21.2 | H12: 7 | I12: =(1.19+2.41)+(0.96+0.5+1)+(1*H12) -> 13.06 | J12: =(1+1.18)+(1.5+3.09+2.09)+(1.92*H12) -> 22.3 | K12: =I12*D12 -> 276.872 | L12: =($E$4+$F$4*H12+$G$4)*D12 -> 505.62 | Q12: =2*((2*$N$4)+($M$4*$O$4)) -> 269.64 | R12: =$N$4*$M$4 -> 26.552 | S12: =SQRT(((1.5*D12)-2.2)^2+(0.5*D12*0.5)^2) -> 30.07075 | V12: =2*((2*S12*$T$4)+($T$4*$U$4)) -> 302.7075 | W12: =S12*$T$4*$U$4*2 -> 60.1415 | X12: =D12 -> 21.2 | Y12: =X12*1.5 -> 31.8 | AA12: =Y12-$Z$4 -> 29.6 | AB12: 1 | AC12: =AB12*((X12*$Z$4)+((X12+Y12)*0.5*AA12)) -> 831.04
B13: EX-4 | C13: CS21a-Trecho 3.1 | D13: 15.1 | H13: 7 | I13: =(1.19+2.41)+(0.96+0.5+1)+(1*H13) -> 13.06 | J13: =(1+1.18)+(1.5+3.09+2.09)+(1.92*H13) -> 22.3 | K13: =I13*D13 -> 197.206 | L13: =($E$4+$F$4*H13+$G$4)*D13 -> 360.135 | Q13: =2*((2*$N$4)+($M$4*$O$4)) -> 269.64 | R13: =$N$4*$M$4 -> 26.552 | S13: =SQRT(((1.5*D13)-2.2)^2+(0.5*D13*0.5)^2) -> 20.795507 | V13: =2*((2*S13*$T$4)+($T$4*$U$4)) -> 209.95507 | W13: =S13*$T$4*$U$4*2 -> 41.591015 | X13: =D13 -> 15.1 | Y13: =X13*1.5 -> 22.65 | AA13: =Y13-$Z$4 -> 20.45 | AB13: 1 | AC13: =AB13*((X13*$Z$4)+((X13+Y13)*0.5*AA13)) -> 419.21375
B14: EX-5 | C14: CS21a-Trecho 4 | D14: 8.7 | H14: 7 | I14: =(1.19+2.41)+(0.96+0.5+1)+(1*H14) -> 13.06 | J14: =(1+1.18)+(1.5+3.09+2.09)+(1.92*H14) -> 22.3 | K14: =I14*D14 -> 113.622 | L14: =($E$4+$F$4*H14+$G$4)*D14 -> 207.495 | Q14: =2*((2*$N$4)+($M$4*$O$4)) -> 269.64 | R14: =$N$4*$M$4 -> 26.552 | S14: =SQRT(((1.5*D14)-2.2)^2+(0.5*D14*0.5)^2) -> 11.065854 | V14: =2*((2*S14*$T$4)+($T$4*$U$4)) -> 112.65854 | W14: =S14*$T$4*$U$4*2 -> 22.131708 | X14: =D14 -> 8.7 | Y14: =X14*1.5 -> 13.05 | AA14: =Y14-$Z$4 -> 10.85 | AB14: 1 | AC14: =AB14*((X14*$Z$4)+((X14+Y14)*0.5*AA14)) -> 137.13375
B15: EX-6 | C15: CS21a-Trecho 5 | H15: 7 | I15: =(1.19+2.41)+(0.96+0.5+1)+(1*H15) -> 13.06 | J15: =(1+1.18)+(1.5+3.09+2.09)+(1.92*H15) -> 22.3 | S15: ELIMINADO | X15: =D15 -> 0 | Y15: =X15*1.5 -> 0 | AA15: =Y15-$Z$4 -> -2.2
B16: CT2-S21 | D16: 4.8 | H16: 7 | I16: =(1.19+2.41)+(0.96+0.5+1)+(1*H16) -> 13.06 | J16: =(1+1.18)+(1.5+3.09+2.09)+(1.92*H16) -> 22.3 | K16: =I16*D16 -> 62.688 | L16: =($E$4+$F$4*H16+$G$4)*D16 -> 114.48 | Q16: =2*((2*$N$4)+($M$4*$O$4)) -> 269.64 | R16: =$N$4*$M$4 -> 26.552 | S16: =SQRT(((1.5*D16)-2.2)^2+(0.5*D16*0.5)^2) -> 5.1419841 | V16: =2*((2*S16*$T$4)+($T$4*$U$4)) -> 53.419841 | W16: =S16*$T$4*$U$4*2 -> 10.283968 | X16: =D16 -> 4.8 | Y16: =X16*1.5 -> 7.2 | AA16: =Y16-$Z$4 -> 5 | AB16: 1 | AC16: =AB16*((X16*$Z$4)+((X16+Y16)*0.5*AA16)) -> 40.56
B17: EX-1 | C17: CP3 - Trecho 2 | D17: 33 | H17: 7 | I17: =(1.19+2.41)+(0.96+0.5+1)+(1*H17) -> 13.06 | J17: =(1+1.18)+(1.5+3.09+2.09)+(1.92*H17) -> 22.3 | K17: =I17*D17 -> 430.98 | L17: =($E$4+$F$4*H17+$G$4)*D17 -> 787.05 | Q17: =2*((2*$N$4)+($M$4*$O$4)) -> 269.64 | R17: =$N$4*$M$4 -> 26.552 | S17: =SQRT(((1.5*D17)-2.2)^2+(0.5*D17*0.5)^2) -> 48.014086 | V17: =2*((2*S17*$T$4)+($T$4*$U$4)) -> 482.14086 | W17: =S17*$T$4*$U$4*2 -> 96.028173 | X17: =D17 -> 33 | Y17: =X17*1.5 -> 49.5 | AA17: =Y17-$Z$4 -> 47.3 | AB17: 1 | AC17: =AB17*((X17*$Z$4)+((X17+Y17)*0.5*AA17)) -> 2023.725
B18: EX-2 | C18: CP3 - Trecho 3 | D18: 16.7 | H18: 7 | I18: =(1.19+2.41)+(0.96+0.5+1)+(1*H18) -> 13.06 | J18: =(1+1.18)+(1.5+3.09+2.09)+(1.92*H18) -> 22.3 | K18: =I18*D18 -> 218.102 | L18: =($E$4+$F$4*H18+$G$4)*D18 -> 398.295 | Q18: =2*((2*$N$4)+($M$4*$O$4)) -> 269.64 | R18: =$N$4*$M$4 -> 26.552 | S18: =SQRT(((1.5*D18)-2.2)^2+(0.5*D18*0.5)^2) -> 23.228283 | V18: =2*((2*S18*$T$4)+($T$4*$U$4)) -> 234.28283 | W18: =S18*$T$4*$U$4*2 -> 46.456566 | X18: =D18 -> 16.7 | Y18: =X18*1.5 -> 25.05 | AA18: =Y18-$Z$4 -> 22.85 | AB18: 1 | AC18: =AB18*((X18*$Z$4)+((X18+Y18)*0.5*AA18)) -> 513.73375
B19: EX-3 | C19: CP3a - Trecho 1 | D19: 18.5 | H19: 7 | I19: =(1.19+2.41)+(0.96+0.5+1)+(1*H19) -> 13.06 | J19: =(1+1.18)+(1.5+3.09+2.09)+(1.92*H19) -> 22.3 | K19: =I19*D19 -> 241.61 | L19: =($E$4+$F$4*H19+$G$4)*D19 -> 441.225 | Q19: =2*((2*$N$4)+($M$4*$O$4)) -> 269.64 | R19: =$N$4*$M$4 -> 26.552 | S19: =SQRT(((1.5*D19)-2.2)^2+(0.5*D19*0.5)^2) -> 25.965229 | V19: =2*((2*S19*$T$4)+($T$4*$U$4)) -> 261.65229 | W19: =S19*$T$4*$U$4*2 -> 51.930458 | X19: =D19 -> 18.5 | Y19: =X19*1.5 -> 27.75 | AA19: =Y19-$Z$4 -> 25.55 | AB19: 1 | AC19: =AB19*((X19*$Z$4)+((X19+Y19)*0.5*AA19)) -> 631.54375
B20: EX-4 | C20: CP3a - Trecho 2 | D20: 11.5 | H20: 7 | I20: =(1.19+2.41)+(0.96+0.5+1)+(1*H20) -> 13.06 | J20: =(1+1.18)+(1.5+3.09+2.09)+(1.92*H20) -> 22.3 | K20: =I20*D20 -> 150.19 | L20: =($E$4+$F$4*H20+$G$4)*D20 -> 274.275 | Q20: =2*((2*$N$4)+($M$4*$O$4)) -> 269.64 | R20: =$N$4*$M$4 -> 26.552 | S20: =SQRT(((1.5*D20)-2.2)^2+(0.5*D20*0.5)^2) -> 15.322145 | V20: =2*((2*S20*$T$4)+($T$4*$U$4)) -> 155.22145 | W20: =S20*$T$4*$U$4*2 -> 30.64429 | X20: =D20 -> 11.5 | Y20: =X20*1.5 -> 17.25 | AA20: =Y20-$Z$4 -> 15.05 | AB20: 1 | AC20: =AB20*((X20*$Z$4)+((X20+Y20)*0.5*AA20)) -> 241.64375
B21: EX-5 | C21: CP3b - Trecho 1 | D21: 8.3 | H21: 7 | I21: =(1.19+2.41)+(0.96+0.5+1)+(1*H21) -> 13.06 | J21: =(1+1.18)+(1.5+3.09+2.09)+(1.92*H21) -> 22.3 | K21: =I21*D21 -> 108.398 | L21: =($E$4+$F$4*H21+$G$4)*D21 -> 197.955 | Q21: =2*((2*$N$4)+($M$4*$O$4)) -> 269.64 | R21: =$N$4*$M$4 -> 26.552 | S21: =SQRT(((1.5*D21)-2.2)^2+(0.5*D21*0.5)^2) -> 10.457922 | V21: =2*((2*S21*$T$4)+($T$4*$U$4)) -> 106.57922 | W21: =S21*$T$4*$U$4*2 -> 20.915843 | X21: =D21 -> 8.3 | Y21: =X21*1.5 -> 12.45 | AA21: =Y21-$Z$4 -> 10.25 | AB21: 1 | AC21: =AB21*((X21*$Z$4)+((X21+Y21)*0.5*AA21)) -> 124.60375
B22: EX-6 | C22: CS23 | D22: 3.1 | H22: 7 | I22: =(1.19+2.41)+(0.96+0.5+1)+(1*H22) -> 13.06 | J22: =(1+1.18)+(1.5+3.09+2.09)+(1.92*H22) -> 22.3 | K22: =I22*D22 -> 40.486 | L22: =($E$4+$F$4*H22+$G$4)*D22 -> 73.935 | Q22: =2*((2*$N$4)+($M$4*$O$4)) -> 269.64 | R22: =$N$4*$M$4 -> 26.552 | S22: =SQRT(((1.5*D22)-2.2)^2+(0.5*D22*0.5)^2) -> 2.5696546 | V22: =2*((2*S22*$T$4)+($T$4*$U$4)) -> 27.696546 | W22: =S22*$T$4*$U$4*2 -> 5.1393093 | X22: =D22 -> 3.1 | Y22: =X22*1.5 -> 4.65 | AA22: =Y22-$Z$4 -> 2.45 | AB22: 1 | AC22: =AB22*((X22*$Z$4)+((X22+Y22)*0.5*AA22)) -> 16.31375
B23: EX-7 | C23: CS25 - Trecho 1 | D23: 14.4 | H23: 7 | I23: =(1.19+2.41)+(0.96+0.5+1)+(1*H23) -> 13.06 | J23: =(1+1.18)+(1.5+3.09+2.09)+(1.92*H23) -> 22.3 | K23: =I23*D23 -> 188.064 | L23: =($E$4+$F$4*H23+$G$4)*D23 -> 343.44 | Q23: =2*((2*$N$4)+($M$4*$O$4)) -> 269.64 | R23: =$N$4*$M$4 -> 26.552 | S23: =SQRT(((1.5*D23)-2.2)^2+(0.5*D23*0.5)^2) -> 19.731194 | V23: =2*((2*S23*$T$4)+($T$4*$U$4)) -> 199.31194 | W23: =S23*$T$4*$U$4*2 -> 39.462387 | X23: =D23 -> 14.4 | Y23: =X23*1.5 -> 21.6 | AA23: =Y23-$Z$4 -> 19.4 | AB23: 1 | AC23: =AB23*((X23*$Z$4)+((X23+Y23)*0.5*AA23)) -> 380.88
B24: EX-8 | C24: CS25 - Trecho 2 | D24: 6.2 | H24: 7 | I24: =(1.19+2.41)+(0.96+0.5+1)+(1*H24) -> 13.06 | J24: =(1+1.18)+(1.5+3.09+2.09)+(1.92*H24) -> 22.3 | K24: =I24*D24 -> 80.972 | L24: =($E$4+$F$4*H24+$G$4)*D24 -> 147.87 | Q24: =2*((2*$N$4)+($M$4*$O$4)) -> 269.64 | R24: =$N$4*$M$4 -> 26.552 | S24: =SQRT(((1.5*D24)-2.2)^2+(0.5*D24*0.5)^2) -> 7.2672209 | V24: =2*((2*S24*$T$4)+($T$4*$U$4)) -> 74.672209 | W24: =S24*$T$4*$U$4*2 -> 14.534442 | X24: =D24 -> 6.2 | Y24: =X24*1.5 -> 9.3 | AA24: =Y24-$Z$4 -> 7.1 | AB24: 1 | AC24: =AB24*((X24*$Z$4)+((X24+Y24)*0.5*AA24)) -> 68.665
B25: EX-9 | C25: CS27 | D25: 2.9 | H25: 7 | I25: =(1.19+2.41)+(0.96+0.5+1)+(1*H25) -> 13.06 | J25: =(1+1.18)+(1.5+3.09+2.09)+(1.92*H25) -> 22.3 | K25: =I25*D25 -> 37.874 | L25: =($E$4+$F$4*H25+$G$4)*D25 -> 69.165 | Q25: =2*((2*$N$4)+($M$4*$O$4)) -> 269.64 | R25: =$N$4*$M$4 -> 26.552 | S25: =SQRT(((1.5*D25)-2.2)^2+(0.5*D25*0.5)^2) -> 2.268948 | V25: =2*((2*S25*$T$4)+($T$4*$U$4)) -> 24.68948 | W25: =S25*$T$4*$U$4*2 -> 4.537896 | X25: =D25 -> 2.9 | Y25: =X25*1.5 -> 4.35 | AA25: =Y25-$Z$4 -> 2.15 | AB25: 1 | AC25: =AB25*((X25*$Z$4)+((X25+Y25)*0.5*AA25)) -> 14.17375
B26: Total = | K26: =SUM(K4:K25) -> 3528.812 | L26: =SUM(L4:L25) -> 6444.27 | Q26: =SUM(Q4:Q25) -> 5392.8 | R26: =SUM(R4:R25) -> 531.04 | V26: =SUM(V4:V25) -> 3716.2549 | W26: =SUM(W4:W25) -> 735.25098 | AC26: =SUM(AC4:AC25) -> 8849.7775
B29: Resumo
B30: Forma | C30: =K26+Q26+V26 -> 12637.867 | D30: m²
B31: Concreto | C31: =L26+R26+W26 -> 7710.561 | D31: m³

Sheet Ficha Bueiros
K8: EXCLUÍDO NO ORÇAMENTO REVISADO

Sheet MC Canais
A1: MEMÓRIA DE CÁLCULO - QUANTITATIVOS DOS CANAIS
A3: ETAPA 3 | B3: =+'Ficha Canais'!A5 -> Canal: CS19 - Trecho 1 | E3: Extensão: | F3: =+'Ficha Canais'!B5 -> 850 | G3: metros | H3: DMT (KM) = | I3: 5
B4: Extensão | C4: Larg faixa | D4: Base | E4: Altura | F4: Perímetro | G4: Área | H4: Volume | I4: Comprimento | J4: Quantitativo | L4: =+Planilha!E28 -> TERRAPLENAGEM E TRATAMENTOS
A5: Desmatamento | B5: =+F3 -> 850 | C5: 40 | D5: 0 | E5: 0 | F5: 0 | G5: =+B5*C5 -> 34000 | H5: 0 | I5: 0 | J5: =SUM(G5:I5) -> 34000 | L5: =+Planilha!E29 -> Desmatamento, destocamento e limpeza de área com árvores de diâmetro até 0,15 m
A6: Escavavação | B6: 0 | C6: 0 | D6: 0 | E6: 0 | F6: 0 | G6: 0 | H6: 1218.69 | I6: 0 | J6: =SUM(G6:I6) -> 1218.69 | L6: =+Planilha!E30 -> Escavação, carga e transporte de material de 1ª categoria - DMT de 1.000 a 1.200 m - caminho de serviço em leito natural - com escavadeira e caminhão basculante de 14 m³
A7: Aterro | B7: 0 | C7: 0 | D7: 0 | E7: 0 | F7: 0 | G7: 0 | H7: 40104.47 | I7: 0 | J7: =SUM(G7:I7) -> 40104.47 | L7: =+Planilha!E31 -> Compactação de aterros a 100% do Proctor normal
A8: Transporte | B8: 0 | C8: 0 | D8: 0 | E8: 0 | F8: 0 | G8: 0 | H8: =+(H7-H6)*1.4*I3 -> 272200.46 | I8: 0 | J8: =SUM(G8:I8) -> 272200.46 | L8: =+Planilha!E32 -> Transporte com caminhão basculante de 14 m³ - rodovia em leito natural
A9: Regularização | B9: =+F3 -> 850 | C9: 0 | D9: =+'Ficha Canais'!$C$5 -> 1.8 | E9: 0 | F9: 0 | G9: =+B9*D9 -> 1530 | H9: 0 | J9: =SUM(G9:I9) -> 1530 | L9: Regularização de superfície com motoniveladora
A10: Geocomposto | B10: =+F3 -> 850 | C10: 0 | D10: 1.8 | E10: 2.11 | F10: =(E10*1.8*2)+D10+0.8 -> 10.196 | G10: 1901 | H10: 0 | I10: 0 | J10: =SUM(G10:I10) -> 1901 | L10: =+Planilha!E34 -> Fornecimento e instalação de geocomposto drenante para os taludes
A11: Solo cimento | B11: 850 | C11: 0 | D11: 0 | E11: 0 | F11: 0 | G11: 0 | H11: =+G12*0.2 -> 1520.6 | I11: 0 | J11: =SUM(G11:I11) -> 1520.6 | L11: Regularização dos taludes do canal com solo-cimento (5% de cimento)
A12: Geomembrana | B12: 0 | C12: 0 | D12: 0 | E12: 0 | F12: 0 | G12: 7603 | H12: 0 | I12: 0 | J12: =SUM(G12:I12) -> 7603 | L12: =+Planilha!E36 -> Fornecimento e aplicação de geomembrana sintética para impermeabilização do canal, 1,00 mm de espessura (PEAD)
A13: Ancoragem | B13: 850 | C13: 0 | D13: 0 | E13: 0 | F13: 0 | G13: 0 | H13: 0 | I13: =+B13*2 -> 1700 | J13: =+I13 -> 1700 | L13: Ancoragem da geomembrana com escavação de material de 1ª e 2ª categorias
A14: Concreto | B14: 0 | C14: 0 | D14: 0 | E14: 0 | F14: 0 | G14: 0 | H14: =+G12*0.07 -> 532.21 | I14: 0 | J14: =SUM(G14:I14) -> 532.21 | L14: =+Planilha!E38 -> Concreto para bombeamento fck = 30 MPa - confecção em central dosadora de 30 m³/h - areia e brita comerciais
A15: Lançamento | B15: 0 | C15: 0 | D15: 0 | E15: 0 | F15: 0 | G15: 0 | H15: =+H14 -> 532.21 | I15: 0 | J15: =SUM(G15:I15) -> 532.21 | L15: =+Planilha!E39 -> Lançamento mecânico de concreto com bomba rebocável com capacidade de 30 m³/h - confecção em central dosadora de 30 m³/h
A16: Junta | B16: =+F3 -> 850 | C16: 0 | D16: 0 | E16: 0 | F16: =+F10 -> 10.196 | G16: 0 | H16: 0 | I16: =+B16/2*F16 -> 4333.3 | J16: =SUM(G16:I16) -> 4333.3 | L16: =+Planilha!E40 -> Lábios poliméricos em junta de pavimento de concreto - L = 20 mm e H = 30 mm - confecção e assentamento
A17: Guia | B17: =+F3 -> 850 | C17: 0 | D17: 0 | E17: 0 | F17: 0 | G17: 0 | H17: 0 | I17: =+B17*2 -> 1700 | J17: =SUM(G17:I17) -> 1700 | L17: =+Planilha!E41 -> Guias de proteção em concreto pré-moldado
A18: Grama | B18: =+F3 -> 850 | C18: 12 | D18: 0 | E18: 0 | F18: 0 | G18: =+B18*C18 -> 10200 | H18: 0 | I18: 0 | J18: =SUM(G18:I18) -> 10200 | L18: =+Planilha!E42 -> Revestimento vegetal com grama em mudas em superfícies inclinadas
B19: Extensão | C19: Larg faixa | D19: Base | E19: Altura | F19: Perímetro | G19: Área | H19: Volume | I19: Comprimento | J19: 0 | L19: =+Planilha!E43 -> DRENAGEM INTERNA DOS CANAIS
A20: Escavação | B20: =+F3 -> 850 | C20: 0 | D20: 1.2 | E20: 0.7 | F20: 0 | G20: 0 | H20: =+B20*D20*E20 -> 714 | I20: 0 | J20: =SUM(G20:I20) -> 714 | L20: =+Planilha!E44 -> Escavação mecânica de vala em material de 1ª categoria
A21: Reaterro | B21: =+F3 -> 850 | D21: 0.6 | E21: 0.6 | H21: =+H20-(B21*D21*E21) -> 408 | J21: =SUM(G21:I21) -> 408 | L21: =+Planilha!E45 -> Reaterro e compactação com soquete vibratório
A22: Transporte | B22: 0 | C22: 0 | D22: 0 | E22: 0 | F22: 0 | G22: 0 | H22: =(H20-H21)*1.4*5 -> 2142 | J22: =SUM(G22:I22) -> 2142 | L22: =+Planilha!E46 -> Transporte com caminhão basculante de 14 m³ - rodovia em leito natural
A23: Manta | B23: =+F3 -> 850 | C23: 0 | D23: 0.6 | E23: 0.6 | F23: 0 | G23: =B23*D23*4 -> 2040 | H23: 0 | I23: 0 | J23: =SUM(G23:I23) -> 2040 | L23: =+Planilha!E47 -> Fornecimento e aplicação de manta geotêxtil (Execução de dreno com manta geotêxtil 400 g/m2)
A24: Tubo | B24: =+F3 -> 850 | C24: 0 | D24: 0 | E24: 0 | F24: 0 | G24: 0 | H24: 0 | I24: =+B24 -> 850 | J24: =SUM(G24:I24) -> 850 | L24: =+Planilha!E48 -> Tubo de concreto perfurado produzido na obra para drenagem - D = 0,40 m - fornecimento e instalação
A25: Brita | B25: =+F3 -> 850 | C25: 0 | D25: 0.6 | E25: 0.6 | F25: 0 | G25: 0 | H25: =B25*D25*E25-(B25*3.14*0.4*0.4/4) -> 199.24 | I25: 0 | J25: =SUM(G25:I25) -> 199.24 | L25: =+Planilha!E49 -> Lastro de brita comercial compactado com soquete vibratório - espalhamento manual
A26: Areia | B26: =+F3 -> 850 | C26: 1.2 | D26: 0 | E26: 0.1 | F26: 0 | G26: 0 | H26: =+B26*C26*E26 -> 102 | J26: =SUM(G26:I26) -> 102 | L26: =+Planilha!E50 -> Lastro de areia comercial - espalhamento manual
B27: Extensão | C27: Larg faixa | D27: Base | E27: Altura | F27: Perímetro | G27: Área | H27: Volume | I27: Comprimento | J27: 0 | L27: =+Planilha!E51 -> OBRAS DE DRENAGEM SUPERFICIAL - VALETAS, SARJETAS, BUEIROS, GALERIAS E PASSAGENS MOLHADAS
A28: Valeta | B28: =+F3 -> 850 | C28: 0 | D28: 0 | E28: 0 | F28: 0 | G28: 0 | H28: 0 | I28: =+B28*2 -> 1700 | J28: =SUM(G28:I28) -> 1700 | L28: =+Planilha!E52 -> Valeta de proteção de cortes com revestimento vegetal - VPCG 120-30 - escavação mecânica
A29: Sarjeta | B29: =+F3 -> 850 | C29: 0 | D29: 0 | E29: 0 | F29: 0 | G29: 0 | H29: 0 | I29: =+B29*2 -> 1700 | J29: =SUM(G29:I29) -> 1700 | L29: =+Planilha!E53 -> Sarjeta triangular de grama - STG 125-25 - escavação mecânica
A30: Bueiro | B30: 0 | C30: 0 | D30: 0 | E30: 0 | F30: 0 | G30: 0 | H30: 0 | I30: 0 | J30: =SUM(G30:I30) -> 0 | L30: =+Planilha!E54 -> Corpo de BSTC D = 0,80 m PA1 - areia, brita e pedra de mão comerciais
A31: Boca | B31: 0 | C31: 0 | D31: 0 | E31: 0 | F31: 0 | G31: 0 | H31: 0 | I31: 0 | J31: =SUM(G31:I31) -> 0 | L31: =+Planilha!E55 -> Boca de BSTC D = 0,80 m - esconsidade 0° - areia e brita comerciais - alas retas
B32: Extensão | C32: Larg faixa | D32: Base | E32: Altura | F32: Perímetro | G32: Área | H32: Volume | I32: Comprimento | J32: 0 | L32: =+Planilha!E56 -> ESTRADAS LATERAIS
A33: Escavação | B33: =+F3 -> 850 | C33: 0 | D33: 3.5 | E33: 0.15 | F33: 0 | G33: 0 | H33: =+B33*D33*E33*2 -> 892.5 | I33: 0 | J33: =SUM(G33:I33) -> 892.5 | L33: =+Planilha!E57 -> Escavação mecânica com retroescavadeira em material de 1ª categoria
A34: Aterro | B34: =+F3 -> 850 | C34: 0 | D34: 3.5 | E34: 0.1 | F34: 0 | G34: 0 | H34: =+B34*D34*E34*2 -> 595 | I34: 0 | J34: =SUM(G34:I34) -> 595 | L34: =+Planilha!E58 -> Compactação de aterros a 100% do Proctor normal
A35: Transporte | B35: 0 | C35: 0 | D35: 0 | E35: 0 | F35: 0 | G35: 0 | H35: =+H33-H34 -> 297.5 | I35: 0 | J35: =SUM(G35:I35) -> 297.5 | L35: =+Planilha!E59 -> Transporte com caminhão basculante de 14 m³ - rodovia em leito natural
A36: Regularização | B36: =+F3 -> 850 | C36: 0 | D36: 3.5 | E36: 0 | F36: 0 | G36: =+B36*D36*2 -> 5950 | H36: 0 | I36: 0 | J36: =SUM(G36:I36) -> 5950 | L36: =+Planilha!E60 -> Regularização de superfície com motoniveladora
A37: Revestimento | B37: =+F3 -> 850 | C37: 0 | D37: 3.5 | E37: 0.15 | F37: 0 | H37: =+B37*D37*E37 -> 446.25 | I37: 0 | J37: =SUM(G37:I37) -> 446.25 | L37: =+Planilha!E61 -> Revestimento primário para as pistas laterais
B38: Extensão | C38: Larg faixa | D38: Base | E38: Altura | F38: Perímetro | G38: Área | H38: Volume | I38: Comprimento | J38: 0 | L38: =+Planilha!E62 -> SERVIÇOS COMPLEMENTARES
A39: Cercas | B39: =+F3 -> 850 | C39: 0 | D39: 0 | E39: 0 | F39: 0 | G39: 0 | H39: 0 | I39: =+B39*2 -> 1700 | J39: =SUM(G39:I39) -> 1700 | L39: =+Planilha!E63 -> Cerca com 4 fios de arame liso galvanizado e mourão de madeira a cada 2,5 m e esticador a cada 50 m
A41: ETAPA 3 | B41: =+'Ficha Canais'!A6 -> Canal: CS19 - Trecho 2 | E41: Extensão: | F41: =+'Ficha Canais'!B6 -> 4950 | G41: metros | H41: DMT (KM) = | I41: =+I3 -> 5
B42: Extensão | C42: Larg faixa | D42: Base | E42: Altura | F42: Perímetro | G42: Área | H42: Volume | I42: Comprimento | J42: Quantitativo
...

Sheet MC EC
A1: MEMÓRIA DE CÁLCULO - QUANTITATIVOS DAS ESTRUTURAS DE CONTROLE
A3: ETAPA 3 | B3: =+'Ficha EC'!A5 -> EC2 - CS19 | D3: Extensão: | E3: =+'Ficha EC'!B5 -> 8 | F3: metros
B4: Extensão | C4: Base | D4: Altura | E4: Área | F4: Volume | G4: Peso | H4: Comprimento | I4: Quantitativo
A5: Desmatamento | B5: =+E3 -> 8 | C5: =+'Ficha EC'!C5 -> 3.2 | D5: =+'Ficha EC'!F5 -> 1.56 | E5: =+B5*(C5+20) -> 185.6 | F5: 0 | G5: 0 | H5: 0 | I5: =SUM(E5:H5) -> 185.6 | K5: =+Planilha!E516 -> Desmatamento, destocamento e limpeza de área com árvores de diâmetro até 0,15 m
A6: Escavavação | B6: =+E3 -> 8 | C6: =+C5 -> 3.2 | D6: =+D5 -> 1.56 | E6: 0 | F6: =+B6*(C6+5)*D6 -> 102.336 | G6: 0 | H6: 0 | I6: =SUM(E6:H6) -> 102.336 | K6: =+Planilha!E517 -> Escavação, carga e transporte de material de 1ª categoria - DMT de 1.000 a 1.200 m - caminho de serviço em leito natural - com escavadeira e caminhão basculante de 14 m³
A7: Aterro | B7: =+E3 -> 8 | C7: =+C6 -> 3.2 | D7: =+D6 -> 1.56 | E7: 0 | F7: =+B7*C7*D7 -> 39.936 | G7: 0 | H7: 0 | I7: =SUM(E7:H7) -> 39.936 | K7: =+Planilha!E518 -> Compactação de aterros a 100% do Proctor normal
A8: Transporte | B8: 0 | C8: 0 | D8: 0 | E8: 0 | F8: =(F6-F7)*1.4*5 -> 436.8 | G8: 0 | H8: 0 | I8: =SUM(E8:H8) -> 436.8 | K8: =+Planilha!E519 -> Transporte com caminhão basculante de 14 m³ - rodovia em leito natural
A9: Magro | B9: =+E3 -> 8 | C9: =+C6 -> 3.2 | D9: 0.1 | E9: 0 | F9: =B9*(3*D9+C9)*0.3 -> 8.4 | G9: 0 | H9: 0 | I9: =SUM(E9:H9) -> 8.4 | K9: Concreto magro - confecção em betoneira e lançamento manual - areia e brita comerciais
