Workbook

Sheet CustosUnit
A1: Ref.: Concessão administrativa para apoio à prestação dos serviços públicos de adução de água bruta do Projeto de Integração do Rio São Francisco com Bacias Hidrográficas do Nordeste Setentrional (PISF). 2025. Disponível em: <https://www.gov.br/mdr/consulta-publica-do-contrato-de-concessao-do-pisf.>
A3: Custo de mão de obra (Data base: Out/25)
A4: Código | B4: Salário | C4: Encargos Sociais | D4: Custo Administrativo | E4: Remuneração da empresa | F4: Despesas fiscais | G4: Custo com encargos
A5: P0 | B5: 19016.06 | C5: =B5*0.2 -> 3803.212 | D5: =B5*0.3 -> 5704.818 | E5: =SUM(B5:D5)*0.12 -> 3422.8908 | F5: =SUM(B5:E5)*0.1662 -> 5309.5882 | G5: =SUM(B5:F5) -> 37256.569
A6: P1 | B6: =B7*1.2 -> 16636.2 | C6: =B6*0.2 -> 3327.24 | D6: =B6*0.3 -> 4990.86 | E6: =SUM(B6:D6)*0.12 -> 2994.516 | F6: =SUM(B6:E6)*0.1662 -> 4645.0932 | G6: =SUM(B6:F6) -> 32593.909
A7: P2 | B7: =B11*8.5 -> 13863.5 | C7: =B7*0.2 -> 2772.7 | D7: =B7*0.3 -> 4159.05 | E7: =SUM(B7:D7)*0.12 -> 2495.43 | F7: =SUM(B7:E7)*0.1662 -> 3870.911 | G7: =SUM(B7:F7) -> 27161.591
A8: P3 | B8: =6*B11 -> 9786 | C8: =B8*0.2 -> 1957.2 | D8: =B8*0.3 -> 2935.8 | E8: =SUM(B8:D8)*0.12 -> 1761.48 | F8: =SUM(B8:E8)*0.1662 -> 2732.4078 | G8: =SUM(B8:F8) -> 19172.888
A9: T1 | B9: =B11*1.2 -> 1957.2 | C9: =B9*0.2 -> 391.44 | D9: =B9*0.3 -> 587.16 | E9: =SUM(B9:D9)*0.12 -> 352.296 | F9: =SUM(B9:E9)*0.1662 -> 546.48156 | G9: =SUM(B9:F9) -> 3834.5776
A10: T2 | B10: =B11*1.1 -> 1794.1 | C10: =B10*0.2 -> 358.82 | D10: =B10*0.3 -> 538.23 | E10: =SUM(B10:D10)*0.12 -> 322.938 | F10: =SUM(B10:E10)*0.1662 -> 500.94143 | G10: =SUM(B10:F10) -> 3515.0294
A11: T3 | B11: 1631 | C11: =B11*0.2 -> 326.2 | D11: =B11*0.3 -> 489.3 | E11: =SUM(B11:D11)*0.12 -> 293.58 | F11: =SUM(B11:E11)*0.1662 -> 455.4013 | G11: =SUM(B11:F11) -> 3195.4813
A13: Custos referentes a serviços e recursos materiais (Data base: Out/2024)
A14: Item | B14: Descrição | C14: Unidade | D14: Custo | E14: Remuneração da Empresa | F14: Despesas Fiscais | G14: Custo com Encargos
A15: Veículos (aluguel e combustível) | B15: Sedan - 71 a 115cv | C15: mês | D15: 3080.7286 | E15: =D15*0.12 -> 369.68743 | F15: =D15*0.1662 -> 512.0171 | G15: =SUM(D15:F15) -> 3962.4331
B16: Caminhonete - 140 a 165cv | C16: mês | D16: 3731.3158 | E16: =D16*0.12 -> 447.75789 | F16: =D16*0.1662 -> 620.14468 | G16: =SUM(D16:F16) -> 4799.2184
B17: Van - 120 a 140 cv | C17: mês | D17: 8598.9247 | E17: =D17*0.12 -> 1031.871 | F17: =D17*0.1662 -> 1429.1413 | G17: =SUM(D17:F17) -> 11059.937
A18: Equipamentos e laboratório GERAL | B18: GPS | C18: mês | D18: 18.93211 | E18: =D18*0.12 -> 2.2718532 | F18: =D18*0.1662 -> 3.1465167 | G18: =SUM(D18:F18) -> 24.35048
B19: Análise de parâmetros de qualidade da Água e Limnologia | C19: unidade | D19: 1504.9998 | E19: =D19*0.12 -> 180.59997 | F19: =D19*0.1662 -> 250.13096 | G19: =SUM(D19:F19) -> 1935.7307
B20: Computador portátil | C20: mês | D20: 76.122405 | E20: =D20*0.12 -> 9.1346886 | F20: =D20*0.1662 -> 12.651544 | G20: =SUM(D20:F20) -> 97.908637
B21: Impressora | C21: mês | D21: 863.03672 | E21: =D21*0.12 -> 103.56441 | F21: =D21*0.1662 -> 143.4367 | G21: =SUM(D21:F21) -> 1110.0378
B22: Câmera fotográfica | C22: mês | D22: 10.728246 | E22: =D22*0.12 -> 1.2873895 | F22: =D22*0.1662 -> 1.7830345 | G22: =SUM(D22:F22) -> 13.79867
B23: Data show | C23: mês | D23: 87.469938 | E23: =D23*0.12 -> 10.496393 | F23: =D23*0.1662 -> 14.537504 | G23: =SUM(D23:F23) -> 112.50383
B24: TV | C24: mês | D24: 97.18882 | E24: =D24*0.12 -> 11.662658 | F24: =D24*0.1662 -> 16.152782 | G24: =SUM(D24:F24) -> 125.00426
B25: Aquisição de equipamentos e materiais especializados - Meio Biótico | C25: verba | D25: 5598.076 | E25: =D25*0.12 -> 671.76912 | F25: =D25*0.1662 -> 930.40024 | G25: =SUM(D25:F25) -> 7200.2454
A26: Equipamentos e laboratório HERPETOFAUNA | B26: Balde plástico 20L | C26: unidade | D26: 27.850428 | E26: =D26*0.12 -> 3.3420514 | F26: =D26*0.1662 -> 4.6287412 | G26: =SUM(D26:F26) -> 35.821221
B27: Lona plástica 50cm de altura | C27: unidade | D27: 293.75904 | E27: =D27*0.12 -> 35.251085 | F27: =D27*0.1662 -> 48.822752 | G27: =SUM(D27:F27) -> 377.83288
B28: Pote plástico 500ml | C28: unidade | D28: 6.1578836 | E28: =D28*0.12 -> 0.73894604 | F28: =D28*0.1662 -> 1.0234403 | G28: =SUM(D28:F28) -> 7.9202699
B29: Algodão para limpeza | C29: unidade | D29: 39.186532 | E29: =D29*0.12 -> 4.7023839 | F29: =D29*0.1662 -> 6.5128017 | G29: =SUM(D29:F29) -> 50.401718
B30: Saco de contenção | C30: unidade | D30: 15.079817 | E30: =D30*0.12 -> 1.8095781 | F30: =D30*0.1662 -> 2.5062656 | G30: =SUM(D30:F30) -> 19.395661
B31: Dardos anestésicos | C31: unidade | D31: 856.16096 | E31: =D31*0.12 -> 102.73932 | F31: =D31*0.1662 -> 142.29395 | G31: =SUM(D31:F31) -> 1101.1942
B32: Medicamento anestésico Cetamina | C32: unidade | D32: 65.581461 | E32: =D32*0.12 -> 7.8697753 | F32: =D32*0.1662 -> 10.899639 | G32: =SUM(D32:F32) -> 84.350875
B33: Lanterna tática | C33: unidade | D33: 160.87471 | E33: =D33*0.12 -> 19.304965 | F33: =D33*0.1662 -> 26.737377 | G33: =SUM(D33:F33) -> 206.91705
B34: Caixa plástica de utensílios | C34: unidade | D34: 62.20862 | E34: =D34*0.12 -> 7.4650344 | F34: =D34*0.1662 -> 10.339073 | G34: =SUM(D34:F34) -> 80.012727
B35: Caixa térmica 32litros | C35: unidade | D35: 81.871862 | E35: =D35*0.12 -> 9.8246234 | F35: =D35*0.1662 -> 13.607103 | G35: =SUM(D35:F35) -> 105.30359
B36: Laço cambão | C36: unidade | D36: 54.581241 | E36: =D36*0.12 -> 6.549749 | F36: =D36*0.1662 -> 9.0714023 | G36: =SUM(D36:F36) -> 70.202393
B37: Par de luvas de raspa | C37: par | D37: 13.981195 | E37: =D37*0.12 -> 1.6777434 | F37: =D37*0.1662 -> 2.3236746 | G37: =SUM(D37:F37) -> 17.982613
A38: Equipamentos e laboratório AVIFAUNA | B38: Redes de neblina | C38: unidade | D38: 179.27838 | E38: =D38*0.12 -> 21.513406 | F38: =D38*0.1662 -> 29.796068 | G38: =SUM(D38:F38) -> 230.58786
B39: Gravador de áudio ambiente | C39: mês | D39: 9.0735482 | E39: =D39*0.12 -> 1.0888258 | F39: =D39*0.1662 -> 1.5080237 | G39: =SUM(D39:F39) -> 11.670398
A40: Equipamentos e laboratório MASTOFAUNA | B40: Régua metálica graduada | C40: unidade | D40: 5.4581241 | E40: =D40*0.12 -> 0.6549749 | F40: =D40*0.1662 -> 0.90714023 | G40: =SUM(D40:F40) -> 7.0202393
B41: Paquímetro digital | C41: unidade | D41: 108.46272 | E41: =D41*0.12 -> 13.015527 | F41: =D41*0.1662 -> 18.026505 | G41: =SUM(D41:F41) -> 139.50475
B42: Fita métrica flexível | C42: unidade | D42: 1.7493988 | E42: =D42*0.12 -> 0.20992785 | F42: =D42*0.1662 -> 0.29075007 | G42: =SUM(D42:F42) -> 2.2500767
...

Sheet CustosReflorest.
A1: Ref.: CODEVASF. Programa de Revitalização da Bacia Hidrográfica do Rio São Francisco. Plano Quinquenal de Conformidade Ambiental - Perímetro Irrigado Jaíba (2005/2009). Outubro/2005.
A3: Estimativa de custo de revegetaçao area descoberta-investimento (R$/ha) | M3: Estimativa de custo de const. de cerca (R$/km)
A4: Especificação | B4: unidade | C4: quantidade | D4: preço unitario | E4: Total | G4: Especificação | H4: unidade | I4: quantidade | J4: preço unitario | K4: Total | M4: Especificação | N4: unidade | O4: quantidade | P4: preço unitario | Q4: Total
A5: 1-insumos | G5: 1-projeto de jardinagem | H5: vb | I5: 1 | J5: 1500 | K5: =I5*J5 -> 1500 | M5: esticador | N5: n.o | O5: =O6/20 -> 10 | P5: 13 | Q5: =O5*P5 -> 130
A6: mudas | B6: n.o | C6: 1120 | D6: 7 | E6: =C6*D6 -> 7840 | G6: 2-revegetaçao | H6: vb | I6: 1 | J6: =E26 -> 11647.75 | K6: =I6*J6 -> 11647.75 | M6: estacas/poste | N6: n.o | O6: 200 | P6: 10 | Q6: =O6*P6 -> 2000
A7: cloreto de potassio | B7: kg | C7: =0.3*C6 -> 336 | D7: 0.8 | E7: =C7*D7 -> 268.8 | G7: TOTAL | K7: =SUM(K5:K6) -> 13147.75 | M7: balancins | N7: n.o | O7: =O6 -> 200 | P7: 2 | Q7: =O7*P7 -> 400
A8: calcario | B8: kg | C8: =0.3*C6 -> 336 | D8: 0.15 | E8: =C8*D8 -> 50.4 | M8: locaçao | N8: dh | O8: 0.8 | P8: 35 | Q8: =O8*P8 -> 28
A9: esterco bovino curtido | B9: m3 | C9: =0.02*C6 -> 22.4 | D9: 35 | E9: =C9*D9 -> 784 | M9: perfuraçao | N9: dh | O9: 8 | P9: 25 | Q9: =O9*P9 -> 200
A10: super simples | B10: kg | C10: =0.35*C6 -> 392 | D10: 0.65 | E10: =C10*D10 -> 254.8 | M10: cercante | N10: dh | O10: 10 | P10: 35 | Q10: =O10*P10 -> 350
A11: formicida granulado | B11: kg | C11: =0.005*C6 -> 5.6 | D11: 25 | E11: =C11*D11 -> 140 | M11: ajudante | N11: dh | O11: 15 | P11: 25 | Q11: =O11*P11 -> 375
A12: agua | B12: m3 | C12: 0 | D12: 40 | E12: =C12*D12 -> 0 | M12: TOTAL | Q12: =SUM(Q5:Q11) -> 3483
A13: tranporte pessoal/insumos | B13: vb | C13: 1 | D13: 600 | E13: =C13*D13 -> 600
A14: sub-total insumos | E14: =SUM(E6:E13) -> 9938
A15: 2-mao de obra | M15: JAÍBA
A16: marcaçao de covas | B16: dh | C16: 4.5 | D16: 25 | E16: =C16*D16 -> 112.5 | M16: TOTAL | Q16: =Q12*J19 -> 10100.7
A17: abertura de covas | B17: dh | C17: 9.5 | D17: 25 | E17: =C17*D17 -> 237.5
A18: adubaçao de covas | B18: dh | C18: 9.5 | D18: 25 | E18: =C18*D18 -> 237.5
A19: plantio | B19: dh | C19: 4.5 | D19: 25 | E19: =C19*D19 -> 112.5 | J19: 2.9
A20: coroamento | B20: dh | C20: 7.5 | D20: 25 | E20: =C20*D20 -> 187.5
A21: combate a formigas | B21: dh | C21: 4 | D21: 25 | E21: =C21*D21 -> 100 | G21: JAÍBA
A22: irrigaçao | B22: dh | C22: 0 | D22: 25 | E22: =C22*D22 -> 0 | G22: Especificação | H22: unidade | I22: quantidade | J22: preço unitario | K22: Total
A23: supervisao tecnica | B23: hh | C23: 15 | D23: 48.15 | E23: =C23*D23 -> 722.25 | G23: 1-projeto de jardinagem | H23: vb | I23: 0 | J23: 0 | K23: =I23*J23 -> 0
E24: =C24*D24 -> 0 | G24: 2-revegetaçao | H24: vb | I24: 1 | J24: =J6*$J$19 -> 33778.475 | K24: =I24*J24 -> 33778.475
A25: sub-total mao de obra | E25: =SUM(E16:E24) -> 1709.75 | G25: TOTAL | K25: =SUM(K23:K24) -> 33778.475
A26: TOTAL GERAL | E26: =E14+E25 -> 11647.75
A28: Observações
A29: 1- preço de mudas de tamanho entre 60 e 80 cm,colocadas no local.
A30: 2-custo da agua levado em pipa e aplicada manualmente a base de 15 litros por cova ano
A31: 3-custo instalaçao de cerca inclui locação,perfuraçao,cercante e ajudante
A32: 4- custo mao de obra inclui salario minimo,encargos sociais e trabalhista de 72%
A33: 5- supervisao tecnica inclui custo de profissional nivel superior de R$3200,00,
A34: encargos sociais e trabalhista de 72% e jornada de 160 horas mensais e veiculo para deslocamento.

Sheet CustosEstudos
A1: Ref.: Concessão do Projeto Hidroagrícola Jequitaí. 2022. Disponível em: <https://www.gov.br/mdr/pt-br/noticias/consulta-publica-sobre-concessao-do-projeto-hidroagricola-jequitai-esta-aberta-ate-15-de-junho>.
A3: 2 | B3: BARRAGEM II - CANAIS - PERÌMETRO
A4: 2.1 | B4: ETAPA LI + LP (obtenção) e LO (obtenção)
A5: 2.1.1 | B5: ESTUDOS AMBIENTAIS | F5: =SUM(F6:F16) -> 4000000 | H5: JAÍBA
A6: 2.1.1.1 | B6: Elaboração de Relatório /Estudo Diagnóstico, Prognóstico e Impactos | C6: gl | D6: 1 | E6: 2500000 | F6: =D6*E6 -> 2500000 | G6: Edital de Concorrência Pública 006/2012 - Ruralminas e Ajustes anuais da Coluna 39 - FGV | H6: =F6*$B$18 -> 2850000
A7: 2.1.1.1.1 | B7: Inventário Florestal - Projeto de Intervenção Ambiental | C7: gl | D7: 1 | E7: 1500000 | F7: =D7*E7 -> 1500000 | G7: Edital de Concorrência Pública 006/2012 - Ruralminas e Ajustes anuais da Coluna 39 - FGV | H7: =F7*$B$18 -> 1710000
B18: 1.14

Sheet CustosFEAM
A1: Ref.: https://feam.br/documents/d/feam/site-custos_tabelados_de_ra_g_2026-pdf
A3: CUSTOS TABELADOS PARA OS PROCESSOS DE REGULARIZAÇÃO AMBIENTAL (R$)
A4: ATIVIDADES AGROSSILVIPASTORIS (Listagem G)
A5: VALOR DA UFEMG = | D5: 5.531 | E5: ANO | F5: 2025
A6: 3 - LICENCIAMENTO AMBIENTAL CONCOMITANTE - LAC (R$)
A7: MODALIDADE | B7: FASE | C7: CLASSE
C8: 2 | D8: 3 | E8: 4 | F8: 5 | G8: 6
A9: LAC 2 | B9: LP | C9: - | D9: 5755.16 | E9: 8516.94 | F9: 13785.75 | G9: 26355.62
A10: LAC 2 | B10: LP+LI | C10: - | D10: 6814.71 | E10: 10132.33 | F10: 16408.58 | G10: 31224.93
A11: LAC 2 | B11: LI+LO | C11: - | D11: 6189.4 | E11: 8939.61 | F11: 14474.75 | G11: 28665.79
A12: LAC 2 | B12: LO | C12: - | D12: 4863.52 | E12: 6814.71 | F12: 11029.76 | G12: 22707.99
A13: ANÁLISE EIA/RIMA (R$)
A14: CLASSE | D14: 3 | E14: 4 | F14: 5 | G14: 6
A15: SISEMA | D15: 14191.04 | E15: 20276.23 | F15: 30408.55 | G15: 48658.32

Sheet CustosIntervAmb
A1: Ref.:https://feam.br/documents/d/feam/site-custos_de_analise_dos_processos_de_ia-2026-pdf | B1: UFEMG 2026 | C1: 5.7899
A3: CUSTOS TABELADOS PARA PROCESSOS DE AUTORIZAÇÃO DE INTERVENÇÃO AMBIENTAL | B3: Custo (Ufemgs) | C3: Area (ha) | D3: Custo (R$)
A4: Supressão de cobertura vegetal nativa, com ou sem destoca, para uso alternativo do solo. | B4: 124 Ufemg + 1 Ufemg por hectare | C4: =1740+782 -> 2522 | D4: =124*$C$1+$C$1*Tabela2[[#This Row],[Area (ha)]] -> 15320.075
A5: Intervenção com supressão de cobertura vegetal nativa em áreas de preservação permanente - APP. | B5: 124 Ufemg + 1 Ufemg por hectare | C5: 0 | D5: 0
A6: Destoca em área remanescente de supressão de vegetação nativa. | B6: 124 Ufemg + 1 Ufemg por hectare | C6: 0 | D6: 0
A7: Corte ou aproveitamento de árvores isoladas nativas vivas. | B7: 124 Ufemg + 1 Ufemg por hectare | C7: =7608-C4 -> 5086 | D7: =124*$C$1+$C$1*Tabela2[[#This Row],[Area (ha)]] -> 30165.379
A8: Análise e vistoria de Plano de Manejo sustentável da vegetação nativa. | B8: 124 Ufemg + 1 Ufemg por hectare ou fração | C8: 0 | D8: 0
A9: Intervenção em Área de Preservação Permanente - APP sem supressão de cobertura vegetal nativa. | B9: 124 Ufemg + 30 Ufemg por hectare ou fração | C9: 0 | D9: 0
A10: Supressão de maciço florestal de origem plantada com presença de sub-bosque nativo com rendimento lenhoso. | B10: 124 Ufemg + 1 Ufemg por hectare | C10: 0 | D10: 0
A11: Supressão de maciço florestal de origem plantada localizado em APP. | B11: 124 Ufemg + 1 Ufemg por hectare | C11: 0 | D11: 0
A12: Aproveitamento de material lenhoso. | B12: 124 Ufemg + 1 Ufemg por metro cúbico | C12: 28000 | D12: =124*$C$1+$C$1*Tabela2[[#This Row],[Area (ha)]] -> 162835.15
A13: Análise de Cadastro Ambiental Rural com vistoria e, imóveis com área acima de 4 módulos fiscais. | B13: 124 Ufemg + 1 Ufemg por hectare ou fração | C13: 0 | D13: 0
A14: Análise de processo de regularização de reserva legal através da compensação em unidades de conservação estaduais de domínio público. | B14: 124 Ufemg + 1 Ufemg por hectare ou fração | C14: 0 | D14: 0
A15: Análise de processo de reserva legal para fins de averbação opcional ou alteração de localização. | B15: 124 Ufemg + 1 Ufemg por hectare ou fração | C15: 5336 | D15: =124*$C$1+$C$1*Tabela2[[#This Row],[Area (ha)]] -> 31612.854
A16: Prorrogação de prazo de validade do DAIA. | B16: 124 Ufemg + 1 Ufemg por hectare ou fração | C16: 0 | D16: 0
A17: Análise de projetos técnicos de reconstituição da flora para imóveis com área acima de 4 módulos fiscais. | B17: 124 Ufemg + 1 Ufemg por hectare ou fração | C17: =C7+C4 -> 7608 | D17: 0
A18: Análise de projetos de recuperação de área alterada ou degradada para imóveis com área acima de 4 módulos fiscais. | B18: 124 Ufemg + 1 Ufemg por hectare ou fração | C18: 0 | D18: 0
A19: Total | B19: - | C19: - | D19: =SUBTOTAL(109,Tabela2[Custo (R$)]) -> 239933.46

Sheet CalcTaxas
A1: Licenciamento | B1: OBS | C1: Taxas ao órgão Estadual
C2: Custo unitário (R$) | D2: Quant. | E2: Unidade | F2: Custo Total (R$)
A3: LAC 2, Classe 4 (I) | B3: LP+LI | C3: =CustosFEAM!E10 -> 10132.33 | D3: 1 | E3: un. | F3: =C3*D3 -> 10132.33
A4: LAC 2, Classe 4 (I) | B4: LO | C4: =CustosFEAM!E12 -> 6814.71 | D4: 1 | E4: un. | F4: =C4*D4 -> 6814.71
A5: LAC 2, Classe 4 (I) | B5: Total | C5: =C3+C4 -> 16947.04 | D5: 1 | E5: un. | F5: =C5*D5 -> 16947.04
A6: Análise EIA/RIMA | B6: Classe 4 | C6: =CustosFEAM!E15 -> 20276.23 | D6: 1 | E6: un. | F6: =C6*D6 -> 20276.23
A7: TOTAL | F7: =SUM(F5:F6) -> 37223.27

Sheet CalcProgramas
A1: Resumo quantitativo de mão de obra para os programas
A2: Programa | B2: Categoria Profissional
D3: Qnt. | E3: Mês | F3: Valores Unitários | G3: Custo Final
A4: Programa de Gestão Ambiental do Empreendimento | B4: P2 | C4: Eng. Ambiental | D4: 1 | E4: 48 | F4: =VLOOKUP(B4,CustosUnit!A$5:G$11,7,FALSE) -> 27161.591 | G4: =F4*E4*D4 -> 1303756.4
B5: P2 | C5: Biólogo Generalista | D5: 1 | E5: 48 | F5: =VLOOKUP(B5,CustosUnit!A$5:G$11,7,FALSE) -> 27161.591 | G5: =F5*E5*D5 -> 1303756.4
B6: T2 | C6: Técnico Ambiental | D6: 1 | E6: =35*12 -> 420 | F6: =VLOOKUP(B6,CustosUnit!A$5:G$11,7,FALSE) -> 3515.0294 | G6: =F6*E6*D6 -> 1476312.4
B7: T3 | C7: Comunicador Local (Campo) | D7: 1 | E7: =48+4*12 -> 96 | F7: =VLOOKUP(B7,CustosUnit!A$5:G$11,7,FALSE) -> 3195.4813 | G7: =F7*E7*D7 -> 306766.2
B8: Subtotal: | G8: =SUM(G4:G7) -> 4390591.3
A9: Programa de Monitoramento e Controle de Processos Erosivos | B9: P2 | C9: Geólogo | D9: 1 | E9: =2*4 -> 8 | F9: =VLOOKUP(B9,CustosUnit!A$5:G$11,7,FALSE) -> 27161.591 | G9: =F9*E9*D9 -> 217292.73
B10: Subtotal: | G10: =SUM(G9) -> 217292.73
A11: Programa de Supressão Vegetal | B11: P2 | C11: Biólogo especialista em flora (coleta de germoplasma) | D11: 2 | E11: =2*4*2 -> 16 | F11: =VLOOKUP(B11,CustosUnit!A$5:G$11,7,FALSE) -> 27161.591 | G11: =F11*E11*D11 -> 869170.91
B12: P2 | C12: Biólogo especialista em fauna (resgate e afugentamento da fauna) | D12: 2 | E12: =2*4*2 -> 16 | F12: =VLOOKUP(B12,CustosUnit!A$5:G$11,7,FALSE) -> 27161.591 | G12: =F12*E12*D12 -> 869170.91
B13: P2 | C13: Eng. Florestal | D13: 2 | E13: =2*4*2 -> 16 | F13: =VLOOKUP(B13,CustosUnit!A$5:G$11,7,FALSE) -> 27161.591 | G13: =F13*E13*D13 -> 869170.91
B14: T1 | C14: Técnico de nível médio | D14: 2 | E14: =2*4*2 -> 16 | F14: =VLOOKUP(B14,CustosUnit!A$5:G$11,7,FALSE) -> 3834.5776 | G14: =F14*E14*D14 -> 122706.48
B15: T2 | C15: Auxiliar de campo | D15: 2 | E15: =2*4*2 -> 16 | F15: =VLOOKUP(B15,CustosUnit!A$5:G$11,7,FALSE) -> 3515.0294 | G15: =F15*E15*D15 -> 112480.94
B16: Subtotal: | G16: =SUM(G11:G15) -> 2842700.2
A17: Programa de Monitoramento da Fauna | B17: P2 | C17: Biólogo (Herpetofauna) | D17: 1 | E17: =3*4+2*5 -> 22 | F17: =VLOOKUP(B17,CustosUnit!A$5:G$11,7,FALSE) -> 27161.591 | G17: =F17*E17*D17 -> 597555
B18: T3 | C18: Auxiliar de campo (Herpetofauna) | D18: 1 | E18: =3*4+2*5 -> 22 | F18: =VLOOKUP(B18,CustosUnit!A$5:G$11,7,FALSE) -> 3195.4813 | G18: =F18*E18*D18 -> 70300.589
B19: P2 | C19: Biólogo (Avifauna) | D19: 1 | E19: =3*4+2*5 -> 22 | F19: =VLOOKUP(B19,CustosUnit!A$5:G$11,7,FALSE) -> 27161.591 | G19: =F19*E19*D19 -> 597555
B20: T3 | C20: Auxiliar de campo (Avifauna) | D20: 1 | E20: =3*4+2*5 -> 22 | F20: =VLOOKUP(B20,CustosUnit!A$5:G$11,7,FALSE) -> 3195.4813 | G20: =F20*E20*D20 -> 70300.589
B21: P2 | C21: Biólogo (Mastofauna) | D21: 1 | E21: =3*4+2*5 -> 22 | F21: =VLOOKUP(B21,CustosUnit!A$5:G$11,7,FALSE) -> 27161.591 | G21: =F21*E21*D21 -> 597555
B22: T3 | C22: Auxiliar de campo (Mastofauna) | D22: 1 | E22: =3*4+2*5 -> 22 | F22: =VLOOKUP(B22,CustosUnit!A$5:G$11,7,FALSE) -> 3195.4813 | G22: =F22*E22*D22 -> 70300.589
B23: P2 | C23: Biólogo (Quirópteros) | D23: 1 | E23: =3*4+2*5 -> 22 | F23: =VLOOKUP(B23,CustosUnit!A$5:G$11,7,FALSE) -> 27161.591 | G23: =F23*E23*D23 -> 597555
B24: T3 | C24: Auxiliar de campo (Quirópteros) | D24: 1 | E24: =3*4+2*5 -> 22 | F24: =VLOOKUP(B24,CustosUnit!A$5:G$11,7,FALSE) -> 3195.4813 | G24: =F24*E24*D24 -> 70300.589
B25: P2 | C25: Médico veterinário | D25: 1 | E25: =240/30 -> 8 | F25: =VLOOKUP(B25,CustosUnit!A$5:G$11,7,FALSE) -> 27161.591 | G25: =F25*E25*D25 -> 217292.73
B26: T2 | C26: Ajudante de serviços gerais (CRAS) | D26: 1 | E26: 48 | F26: =VLOOKUP(B26,CustosUnit!A$5:G$11,7,FALSE) -> 3515.0294 | G26: =F26*E26*D26 -> 168721.41
B27: Subtotal: | G27: =SUM(G17:G26) -> 3057436.5
A28: Programa de Educação Ambiental | B28: P2 | C28: Sociólogo | D28: 1 | E28: =(48+4*12)/2 -> 48 | F28: =VLOOKUP(B28,CustosUnit!A$5:G$11,7,FALSE) -> 27161.591 | G28: =F28*E28*D28 -> 1303756.4
B29: P3 | C29: Engenheiro de Segurança do Trabalho | D29: 1 | E29: 48 | F29: =VLOOKUP(B29,CustosUnit!A$5:G$11,7,FALSE) -> 19172.888 | G29: =F29*E29*D29 -> 920298.61
B30: Subtotal: | G30: =SUM(G28:G29) -> 2224055
A31: Programa de Desapropriação e Reassentamento da População | B31: P2 | C31: Sociólogo | D31: 1 | E31: =(48+4*12)/2 -> 48 | F31: =VLOOKUP(B31,CustosUnit!A$5:G$11,7,FALSE) -> 27161.591 | G31: =F31*E31*D31 -> 1303756.4
B32: Subtotal: | G32: =SUM(G31:G31) -> 1303756.4
A33: Programa de Recuperação de Áreas Degradadas | B33: P2 | C33: Geólogo | D33: 1 | E33: =2*5 -> 10 | F33: =VLOOKUP(B33,CustosUnit!A$5:G$11,7,FALSE) -> 27161.591 | G33: =F33*E33*D33 -> 271615.91
B34: P2 | C34: Eng. Florestal | D34: 1 | E34: =2*5 -> 10 | F34: =VLOOKUP(B34,CustosUnit!A$5:G$11,7,FALSE) -> 27161.591 | G34: =F34*E34*D34 -> 271615.91
B35: Subtotal: | G35: =SUM(G33:G34) -> 543231.82
A36: Programa de Comabte a Incêndios | B36: T1 | C36: Supervisor de Focos de Incêndio | D36: 1 | E36: 48 | F36: =VLOOKUP(B36,CustosUnit!A$5:G$11,7,FALSE) -> 3834.5776 | G36: =F36*E36*D36 -> 184059.72
B37: P2 | C37: Especialista em prevenção de incêndios | D37: 1 | E37: =2*20 -> 40 | F37: =VLOOKUP(B37,CustosUnit!A$5:G$11,7,FALSE) -> 27161.591 | G37: =F37*E37*D37 -> 1086463.6
B38: Subtotal: | G38: =SUM(G36:G37) -> 1270523.4
A40: Resumo quantitativo de materiais e serviços para os programas
A41: Programa | B41: Categoria | C41: Discriminação | E41: Unidade | F41: Qtde | G41: Ocorrências | H41: Valor Unitário | I41: Preço Final
...

Sheet CronogramaFin
B1: Total | C1: 2027 | D1: 2028 | E1: 2029 | F1: 2030 | G1: 2031 | H1: 2032 | I1: 2033 | J1: 2034 | K1: 2035 | L1: 2036 | M1: 2037 | N1: 2038 | O1: 2039 | P1: 2040 | Q1: 2041 | R1: 2042 | S1: 2043 | T1: 2044 | U1: 2045 | V1: 2046 | W1: 2047 | X1: 2048 | Y1: 2049 | Z1: 2050 | AA1: 2051 | AB1: 2052 | AC1: 2053 | AD1: 2054 | AE1: 2055 | AF1: 2056 | AG1: 2057 | AH1: 2058 | AI1: 2059 | AJ1: 2060 | AK1: 2061
A2: Licenças / Autorizações | B2: =SUM(B3:B4) -> 277156.46 | C2: =SUM(C3:C4) -> 277156.46
A3: Taxas para obtenção de Licenças Ambientais | B3: =ROUND(CalcTaxas!F7,0) -> 37223 | C3: =B3 -> 37223
A4: Processo de Autorização de Intervenção Ambiental | B4: =Tabela2[[#Totals],[Custo (R$)]] -> 239933.46 | C4: =B4 -> 239933.46
A5: Estudos e Ações | B5: =SUM(B6:B9) -> 4960000 | C5: =SUM(C6:C9) -> 4960000 | D5: =SUM(D6:D9) -> 0 | E5: =SUM(E6:E9) -> 0 | F5: =SUM(F6:F9) -> 0 | G5: =SUM(G6:G9) -> 0 | H5: =SUM(H6:H9) -> 0 | I5: =SUM(I6:I9) -> 0 | ... AK5: =SUM(AK6:AK9) -> 0
A6: Inventário Florestal - Projeto de Intervenção Ambiental | B6: =CustosEstudos!H7 -> 1710000 | C6: =B6 -> 1710000
A7: EIA/RIMA | B7: =CustosEstudos!H6 -> 2850000 | C7: =B7 -> 2850000
A8: Estudos de Critério Locacional (Estudos Espeleológicos) | B8: 200000 | C8: =B8 -> 200000
A9: Elaboração do PCA | B9: 200000 | C9: =B9 -> 200000
A10: Programas Ambientais | B10: =SUM(B11:B23) -> 90757462 | C10: =SUM(C11:C23) -> 17696247 | D10: =SUM(D11:D23) -> 14876280 | E10: =SUM(E11:E23) -> 14876280 | F10: =SUM(F11:F23) -> 14876280 | G10: =SUM(G11:G23) -> 1669231.6 | H10: =SUM(H11:H23) -> 1669231.6 | I10: =SUM(I11:I23) -> 1669231.6 | ... AK10: =SUM(AK11:AK23) -> 299000.66
A11: =CalcProgramas!A116 -> Programa de Gestão Ambiental do Empreendimento | B11: =CalcProgramas!D116 -> 7656100.9 | C11: =(CalcProgramas!I42+CalcProgramas!I43+CalcProgramas!I44+CalcProgramas!I53+CalcProgramas!I54+CalcProgramas!I55)+(CalcProgramas!$I$45+CalcProgramas!$I$47+CalcProgramas!$I$49+CalcProgramas!$I$52)/4+(CalcProgramas!$G$4+CalcProgramas!$G$5)/4+(CalcProgramas!$G$7)/8+(CalcProgramas!$G$6+CalcProgramas!$I$46+CalcProgramas!$I$48+CalcProgramas!$I$50+CalcProgramas!$I$51)/35 -> 1133272.3 | D11: =(CalcProgramas!$I$45+CalcProgramas!$I$47+CalcProgramas!$I$49+CalcProgramas!$I$52)/4+(CalcProgramas!$G$4+CalcProgramas!$G$5)/4+(CalcProgramas!$G$7)/8+(CalcProgramas!$G$6+CalcProgramas!$I$46+CalcProgramas!$I$48+CalcProgramas!$I$50+CalcProgramas!$I$51)/35 -> 906302.05 | E11: =(CalcProgramas!$I$45+CalcProgramas!$I$47+CalcProgramas!$I$49+CalcProgramas!$I$52)/4+(CalcProgramas!$G$4+CalcProgramas!$G$5)/4+(CalcProgramas!$G$7)/8+(CalcProgramas!$G$6+CalcProgramas!$I$46+CalcProgramas!$I$48+CalcProgramas!$I$50+CalcProgramas!$I$51)/35 -> 906302.05 | F11: =(CalcProgramas!$I$45+CalcProgramas!$I$47+CalcProgramas!$I$49+CalcProgramas!$I$52)/4+(CalcProgramas!$G$4+CalcProgramas!$G$5)/4+(CalcProgramas!$G$7)/8+(CalcProgramas!$G$6+CalcProgramas!$I$46+CalcProgramas!$I$48+CalcProgramas!$I$50+CalcProgramas!$I$51)/35 -> 906302.05 | G11: =(CalcProgramas!$G$7)/8+(CalcProgramas!$G$6+CalcProgramas!$I$46+CalcProgramas!$I$48+CalcProgramas!$I$50+CalcProgramas!$I$51)/35 -> 156105.11 | H11: =(CalcProgramas!$G$7)/8+(CalcProgramas!$G$6+CalcProgramas!$I$46+CalcProgramas!$I$48+CalcProgramas!$I$50+CalcProgramas!$I$51)/35 -> 156105.11 | I11: =(CalcProgramas!$G$7)/8+(CalcProgramas!$G$6+CalcProgramas!$I$46+CalcProgramas!$I$48+CalcProgramas!$I$50+CalcProgramas!$I$51)/35 -> 156105.11 | J11: =(CalcProgramas!$G$7)/8+(CalcProgramas!$G$6+CalcProgramas!$I$46+CalcProgramas!$I$48+CalcProgramas!$I$50+CalcProgramas!$I$51)/35 -> 156105.11 | K11: =(CalcProgramas!$G$6+CalcProgramas!$I$46+CalcProgramas!$I$48+CalcProgramas!$I$50+CalcProgramas!$I$51)/35 -> 117759.33 | L11: =(CalcProgramas!$G$6+CalcProgramas!$I$46+CalcProgramas!$I$48+CalcProgramas!$I$50+CalcProgramas!$I$51)/35 -> 117759.33 | M11: =(CalcProgramas!$G$6+CalcProgramas!$I$46+CalcProgramas!$I$48+CalcProgramas!$I$50+CalcProgramas!$I$51)/35 -> 117759.33 | N11: =(CalcProgramas!$G$6+CalcProgramas!$I$46+CalcProgramas!$I$48+CalcProgramas!$I$50+CalcProgramas!$I$51)/35 -> 117759.33 | O11: =(CalcProgramas!$G$6+CalcProgramas!$I$46+CalcProgramas!$I$48+CalcProgramas!$I$50+CalcProgramas!$I$51)/35 -> 117759.33 | P11: =(CalcProgramas!$G$6+CalcProgramas!$I$46+CalcProgramas!$I$48+CalcProgramas!$I$50+CalcProgramas!$I$51)/35 -> 117759.33 | Q11: =(CalcProgramas!$G$6+CalcProgramas!$I$46+CalcProgramas!$I$48+CalcProgramas!$I$50+CalcProgramas!$I$51)/35 -> 117759.33 | R11: =(CalcProgramas!$G$6+CalcProgramas!$I$46+CalcProgramas!$I$48+CalcProgramas!$I$50+CalcProgramas!$I$51)/35 -> 117759.33 | ... AK11: =(CalcProgramas!$G$6+CalcProgramas!$I$46+CalcProgramas!$I$48+CalcProgramas!$I$50+CalcProgramas!$I$51)/35 -> 117759.33
A12: =CalcProgramas!A117 -> Programa de Monitoramento e Controle de Processos Erosivos | B12: =CalcProgramas!D117 -> 217292.73 | C12: =$B$12/4 -> 54323.182 | D12: =$B$12/4 -> 54323.182 | E12: =$B$12/4 -> 54323.182 | F12: =$B$12/4 -> 54323.182
A13: =CalcProgramas!A118 -> Programa de Monitoramento da Qualidade das Águas Subterrâneas | B13: =CalcProgramas!D118 -> 1966875 | C13: =CalcProgramas!$H$57*4 -> 104900 | D13: =CalcProgramas!$H$57*3 -> 78675 | E13: =CalcProgramas!$H$57*3 -> 78675 | F13: =CalcProgramas!$H$57*3 -> 78675 | G13: =CalcProgramas!$H$57*2 -> 52450 | H13: =CalcProgramas!$H$57*2 -> 52450 | I13: =CalcProgramas!$H$57*2 -> 52450 | J13: =CalcProgramas!$H$57*2 -> 52450 | K13: =CalcProgramas!$H$57*2 -> 52450 | L13: =CalcProgramas!$H$57*2 -> 52450 | M13: =CalcProgramas!$H$57*2 -> 52450 | N13: =CalcProgramas!$H$57*2 -> 52450 | ... AK13: =CalcProgramas!$H$57*2 -> 52450
A14: =CalcProgramas!A119 -> Programa de Monitoramento da Qualidade das Águas Superficiais | B14: =CalcProgramas!D119 -> 1966875 | C14: =CalcProgramas!$H$59*4 -> 104900 | D14: =CalcProgramas!$H$59*3 -> 78675 | E14: =CalcProgramas!$H$59*3 -> 78675 | F14: =CalcProgramas!$H$59*3 -> 78675 | G14: =CalcProgramas!$H$59*2 -> 52450 | H14: =CalcProgramas!$H$59*2 -> 52450 | I14: =CalcProgramas!$H$59*2 -> 52450 | J14: =CalcProgramas!$H$59*2 -> 52450 | K14: =CalcProgramas!$H$59*2 -> 52450 | L14: =CalcProgramas!$H$59*2 -> 52450 | M14: =CalcProgramas!$H$59*2 -> 52450 | N14: =CalcProgramas!$H$59*2 -> 52450 | ... AK14: =CalcProgramas!$H$59*2 -> 52450
A15: =CalcProgramas!A120 -> Programa de Monitoramento dos Solos | B15: =CalcProgramas!D120 -> 2671946.6 | C15: =CalcProgramas!$H$61 -> 76341.33 | D15: =CalcProgramas!$H$61 -> 76341.33 | E15: =CalcProgramas!$H$61 -> 76341.33 | F15: =CalcProgramas!$H$61 -> 76341.33 | G15: =CalcProgramas!$H$61 -> 76341.33 | H15: =CalcProgramas!$H$61 -> 76341.33 | I15: =CalcProgramas!$H$61 -> 76341.33 | J15: =CalcProgramas!$H$61 -> 76341.33 | ... AK15: =CalcProgramas!$H$61 -> 76341.33
A16: =CalcProgramas!A121 -> Programa de Supressão de Vegetação e Manejo da Flora | B16: =CalcProgramas!D121 -> 3686383.5 | C16: =$B$16/4 -> 921595.88 | D16: =$B$16/4 -> 921595.88 | E16: =$B$16/4 -> 921595.88 | F16: =$B$16/4 -> 921595.88
A17: =CalcProgramas!A122 -> Programa de Compensação Ambiental | B17: =CalcProgramas!D122 -> 55428294 | C17: =CalcProgramas!I72+(CalcProgramas!$I$73+CalcProgramas!$I$74)/4+(CalcProgramas!$I$70+CalcProgramas!$I$71)/20 -> 11388556 | D17: =(CalcProgramas!$I$73+CalcProgramas!$I$74)/4+(CalcProgramas!$I$70+CalcProgramas!$I$71)/20 -> 8888555.7 | E17: =(CalcProgramas!$I$73+CalcProgramas!$I$74)/4+(CalcProgramas!$I$70+CalcProgramas!$I$71)/20 -> 8888555.7 | F17: =(CalcProgramas!$I$73+CalcProgramas!$I$74)/4+(CalcProgramas!$I$70+CalcProgramas!$I$71)/20 -> 8888555.7 | G17: =(CalcProgramas!$I$70+CalcProgramas!$I$71)/20 -> 1085879.4 | H17: =(CalcProgramas!$I$70+CalcProgramas!$I$71)/20 -> 1085879.4 | I17: =(CalcProgramas!$I$70+CalcProgramas!$I$71)/20 -> 1085879.4 | J17: =(CalcProgramas!$I$70+CalcProgramas!$I$71)/20 -> 1085879.4 | K17: =(CalcProgramas!$I$70+CalcProgramas!$I$71)/20 -> 1085879.4 | L17: =(CalcProgramas!$I$70+CalcProgramas!$I$71)/20 -> 1085879.4 | M17: =(CalcProgramas!$I$70+CalcProgramas!$I$71)/20 -> 1085879.4 | N17: =(CalcProgramas!$I$70+CalcProgramas!$I$71)/20 -> 1085879.4 | ... V17: =(CalcProgramas!$I$70+CalcProgramas!$I$71)/20 -> 1085879.4
A18: =CalcProgramas!A123 -> Programa de Afugentamento, Monitoramento e Conservação da Fauna | B18: =CalcProgramas!D123 -> 10790495 | C18: =$B$18/4 -> 2697623.7 | D18: =$B$18/4 -> 2697623.7 | E18: =$B$18/4 -> 2697623.7 | F18: =$B$18/4 -> 2697623.7
A19: =CalcProgramas!A124 -> Programa de Educação Ambiental | B19: =CalcProgramas!D124 -> 2513316.3 | C19: =(CalcProgramas!I87+CalcProgramas!I92+CalcProgramas!I94+CalcProgramas!I95+CalcProgramas!I96+CalcProgramas!I89)+(CalcProgramas!$G$29+CalcProgramas!$I$91+CalcProgramas!$I$93)/4+(CalcProgramas!$G$28+CalcProgramas!$I$84+CalcProgramas!$I$85+CalcProgramas!$I$86+CalcProgramas!$I$88+CalcProgramas!$I$90)/8 -> 463683.65 | D19: =(CalcProgramas!$G$29+CalcProgramas!$I$91+CalcProgramas!$I$93)/4+(CalcProgramas!$G$28+CalcProgramas!$I$84+CalcProgramas!$I$85+CalcProgramas!$I$86+CalcProgramas!$I$88+CalcProgramas!$I$90)/8 -> 427634.19 | E19: =(CalcProgramas!$G$29+CalcProgramas!$I$91+CalcProgramas!$I$93)/4+(CalcProgramas!$G$28+CalcProgramas!$I$84+CalcProgramas!$I$85+CalcProgramas!$I$86+CalcProgramas!$I$88+CalcProgramas!$I$90)/8 -> 427634.19 | F19: =(CalcProgramas!$G$29+CalcProgramas!$I$91+CalcProgramas!$I$93)/4+(CalcProgramas!$G$28+CalcProgramas!$I$84+CalcProgramas!$I$85+CalcProgramas!$I$86+CalcProgramas!$I$88+CalcProgramas!$I$90)/8 -> 427634.19 | G19: =(CalcProgramas!$G$28+CalcProgramas!$I$84+CalcProgramas!$I$85+CalcProgramas!$I$86+CalcProgramas!$I$88+CalcProgramas!$I$90)/8 -> 191682.51 | H19: =(CalcProgramas!$G$28+CalcProgramas!$I$84+CalcProgramas!$I$85+CalcProgramas!$I$86+CalcProgramas!$I$88+CalcProgramas!$I$90)/8 -> 191682.51 | I19: =(CalcProgramas!$G$28+CalcProgramas!$I$84+CalcProgramas!$I$85+CalcProgramas!$I$86+CalcProgramas!$I$88+CalcProgramas!$I$90)/8 -> 191682.51 | J19: =(CalcProgramas!$G$28+CalcProgramas!$I$84+CalcProgramas!$I$85+CalcProgramas!$I$86+CalcProgramas!$I$88+CalcProgramas!$I$90)/8 -> 191682.51
A20: =CalcProgramas!A125 -> Programa de Desapropriação e Reassentamento da População | B20: =CalcProgramas!D125 -> 1518123.6 | C20: =(CalcProgramas!$G$31+CalcProgramas!$I$98+CalcProgramas!$I$99+CalcProgramas!$I$100+CalcProgramas!$I$101)/4 -> 379530.9 | D20: =(CalcProgramas!$G$31+CalcProgramas!$I$98+CalcProgramas!$I$99+CalcProgramas!$I$100+CalcProgramas!$I$101)/4 -> 379530.9 | E20: =(CalcProgramas!$G$31+CalcProgramas!$I$98+CalcProgramas!$I$99+CalcProgramas!$I$100+CalcProgramas!$I$101)/4 -> 379530.9 | F20: =(CalcProgramas!$G$31+CalcProgramas!$I$98+CalcProgramas!$I$99+CalcProgramas!$I$100+CalcProgramas!$I$101)/4 -> 379530.9
A21: =CalcProgramas!A126 -> Programa de Apoio às Prefeituras da AII | B21: =CalcProgramas!D126 -> 500000 | C21: =$B$21/4 -> 125000 | D21: =$B$21/4 -> 125000 | E21: =$B$21/4 -> 125000 | F21: =$B$21/4 -> 125000
A22: =CalcProgramas!A127 -> Programa de Combate a Incêndios Florestais nas Áreas de Reserva Legal | B22: =CalcProgramas!D127 -> 1298528.3 | C22: =(CalcProgramas!I104+CalcProgramas!I105+CalcProgramas!I106+CalcProgramas!I107)+(CalcProgramas!$I$103+CalcProgramas!$I$108+CalcProgramas!$G$36)/4+CalcProgramas!$G$37/20 -> 110711.95 | D22: =(CalcProgramas!$I$103+CalcProgramas!$I$108+CalcProgramas!$G$36)/4+CalcProgramas!$G$37/20 -> 106215.13 | E22: =(CalcProgramas!$I$103+CalcProgramas!$I$108+CalcProgramas!$G$36)/4+CalcProgramas!$G$37/20 -> 106215.13 | F22: =(CalcProgramas!$I$103+CalcProgramas!$I$108+CalcProgramas!$G$36)/4+CalcProgramas!$G$37/20 -> 106215.13 | G22: =CalcProgramas!$G$37/20 -> 54323.182 | H22: =CalcProgramas!$G$37/20 -> 54323.182 | I22: =CalcProgramas!$G$37/20 -> 54323.182 | J22: =CalcProgramas!$G$37/20 -> 54323.182 | K22: =CalcProgramas!$G$37/20 -> 54323.182 | L22: =CalcProgramas!$G$37/20 -> 54323.182 | M22: =CalcProgramas!$G$37/20 -> 54323.182 | N22: =CalcProgramas!$G$37/20 -> 54323.182 | ... V22: =CalcProgramas!$G$37/20 -> 54323.182
A23: =CalcProgramas!A128 -> Programa de Recuperação de Áreas Degradadas | B23: =CalcProgramas!D128 -> 543231.82 | C23: =$B$23/4 -> 135807.96 | D23: =$B$23/4 -> 135807.96 | E23: =$B$23/4 -> 135807.96 | F23: =$B$23/4 -> 135807.96
A24: Total Acumulado | B24: =B10+B5+B2 -> 95994619 | C24: =C10+C5+C2 -> 22933403 | D24: =C24+D10+D5+D2 -> 37809683 | E24: =D24+E10+E5+E2 -> 52685963 | F24: =E24+F10+F5+F2 -> 67562243 | G24: =F24+G10+G5+G2 -> 69231475 | H24: =G24+H10+H5+H2 -> 70900706 | I24: =H24+I10+I5+I2 -> 72569938 | J24: =I24+J10+J5+J2 -> 74239169 | K24: =J24+K10+K5+K2 -> 75678373 | ... AK24: =AJ24+AK10+AK5+AK2 -> 95994619
