Workbook
Name _ftn1: Benchmarking!$A$35
Name _ftn2: Benchmarking!$A$36
Name _ftnref1: Benchmarking!#REF!
Name _ftnref2: Benchmarking!#REF!

Sheet CAPA
B8: Fundo de Desenvolvimento da Infraestrutura Sustentável – FDIRS
B14: Serviços Técnicos relativos à Estruturação e o Desenvolvimento de Concessão do Perímetro Irrigado do Jaíba (Etapas III e IV) da Companhia de Desenvolvimento dos Vales do São Francisco e do Parnaíba - CODEVASF
B19: CONTRATO: 01/2025
B25: Estudo de Planejamento Agrícola - Jaíba Etapas 3 e 4
B31: Produto 7 - Estudo Mercado e Demanda - Planejamento Agrícola
K45: 46233
A51: CONSÓRCIO Nova Irrigação Jaíba/MG
B63: NOME DO ARQUIVO: JB_E3-4.PA.AGR.PL.001_R0-EST.PLANEJ.AGRICOLA

Sheet Lista de Abas
A1: Aba | B1: Descrição
A2: CAPA | B2: Informações referentes ao projeto e descrição do documento
A3: Premissas | B3: Descrição das principais premissas adotadas para a elaboração do estudo
A4: Planejamento Global | B4: Planilha consolidada com os resultados do Planejamento Global, por ano,da área em estudo, somando todos os cultivos. Na mesma aba contém o planejamento por cultura.
A5: Balanço custo - receita-modelos | B5: Planilha gerencial com os resumos dos balanços de receita/custo das culturas estudadas
A6: Área Plant-Colh e Produção | B6: Planilha Gerencial com o resultado dos principais indicados por ano (do 1 aou 35) por cultura: Ocupação de área, Produção ano, Valor de Venda e Custos de Implantação + Operacionais
A7: Resumos -> | B7: aba de identificação das abas à direita
A8: Resumo-Cult.Perma. | B8: Planilha resumo da rentabilidade das culturas permanentes por ha, considerando os gastos com a implantação, os custos operacionais e a receita anual do ano 1 ao ano 35.
A9: Resumo-Cult.Temp. | B9: Planilha resumo da rentabilidade das culturas temporárias por ha, considerando os gastos com a implantação, os custos operacionais e a receita anual do ano 1 ao ano 35.
A10: Custo diversos Manga.Limão | B10: Aba oculta - desconsiderar
A11: Custo diversos - Cult.anuais | B11: Aba oculta - desconsiderar
A12: Custo diversos - Cana | B12: Aba oculta - desconsiderar
... A41: Inflação | B41: Banco de dados com índices de inflação adotados

Sheet Premissas
C3: PREMISSAS
B4: 1 - | C4: Área bruta de 26.652 ha, área bruta das etapas 3 e 4
B5: 2 - | C5: Área irrigável conforme Projeto de 20.788 ha
B6: 3 - | C6: Área efetivamente irrigada conforme Projeto de 17.254 ha
B7: 4 - | C7: Adotou-se culturas que dominam 80% da área cultivada nas etapas 1 e 2
B8: 5 - | C8: Área de supressão vegetal conforme Projeto de 7.120, que representa 41,3% da área irrigada
B9: 6 - | C9: Os preços adotados de venda dos produtos foram em nível de propriedade, livres de impostos e fretes até o ponto de venda
B10: 7 - | C10: Os preços de venda refletem a media de 5 anos para Banana, Manga, limão
B11: 8 - | C11: O preço dos produtos milho, soja, feijão, reflete média de um periodo dos últimso 5 anos, dolarizado.
B12: 9 - | C12: O custo de produção refletem custos atuais praticados na região
B13: 10 - | C13: Admitiu-se um cronogra de liberção de área conforme cronograma de engenharia para as obras de infraestrutura de uso comum
B14: 11 - | C14: Admitiu-se que a área cultivada será realizada no ano posterior da liberação da obra
B15: 12 - | C15: Admitiu-se uma renovação da cultura da cana a cada 10 anos
... B19: 16 - | C19: Admitiu-se para as demais culturas irrigação tipo Pivô central

Sheet Planejamento Global
A1: Global | B1: 2 | D1: 4 | E1: 5 | F1: 6 | G1: 7 | H1: 8 | I1: 9 | J1: 10 | K1: 11 | L1: 12 | M1: 13 | N1: 14 | O1: 15 | P1: 16 | Q1: 17 | R1: 18 | S1: 19 | T1: 20 | U1: 21 | V1: 22 | W1: 23 | X1: 24 | Y1: 25 | Z1: 26 | AA1: 27 | AB1: 28 | AC1: 29 | AD1: 30 | AE1: 31 | AF1: 32 | AG1: 33 | AH1: 34 | AI1: 35 | AJ1: 36 | AK1: 37
A2: PLANEJAMENTO GLOBAL
A3: Planejamento total das culturas
A4: ITEM | B4: COMPONENTES | C4: ANOS DE IMPLANTAÇÃO DA CULTURA
C5: 1 | D5: =C5+1 -> 2 | E5: =D5+1 -> 3 | F5: =E5+1 -> 4 | G5: =F5+1 -> 5 | H5: =G5+1 -> 6 | I5: =H5+1 -> 7 | J5: =I5+1 -> 8 | K5: =J5+1 -> 9 | ... AK5: =AJ5+1 -> 35
A6: 1 | B6: INVESTIMENTOS | D6: =D16 -> 0 | E6: =E16 -> 0 | F6: =F16 -> 47330068 | G6: =G16 -> 48471840 | H6: =H16 -> 58006516 | I6: =I16 -> 1.1120001e+08 | J6: =J16 -> 1.0569294e+08 | K6: =K16 -> 1.0850775e+08 | ... AK6: =AK16 -> 0
A7: 1.1 | B7: Supressão vegetal | D7: =D48+D79+D110+D141+D172+D203+D234+D265+D296 -> 0 | E7: =E48+E79+E110+E141+E172+E203+E234+E265+E296 -> 0 | F7: =F48+F79+F110+F141+F172+F203+F234+F265+F296 -> 1628328.5 | G7: =G48+G79+G110+G141+G172+G203+G234+G265+G296 -> 1628328.5 | H7: =H48+H79+H110+H141+H172+H203+H234+H265+H296 -> 1956356.4 | I7: =I48+I79+I110+I141+I172+I203+I234+I265+I296 -> 3778495.2 | J7: =J48+J79+J110+J141+J172+J203+J234+J265+J296 -> 3545075 | K7: =K48+K79+K110+K141+K172+K203+K234+K265+K296 -> 3647546 | ... AK7: =AK48+AK79+AK110+AK141+AK172+AK203+AK234+AK265+AK296 -> 0
A8: 1.2 | B8: Sistema de irrigação localizada | C8: =C49+C80+C111+C142+C173+C204+C235+C266+C297 -> 0 | D8: =D49+D80+D111+D142+D173+D204+D235+D266+D297 -> 0 | E8: =E49+E80+E111+E142+E173+E204+E235+E266+E297 -> 0 | F8: =F49+F80+F111+F142+F173+F204+F235+F266+F297 -> 7363311.3 | G8: =G49+G80+G111+G142+G173+G204+G235+G266+G297 -> 7363311.3 | H8: =H49+H80+H111+H142+H173+H204+H235+H266+H297 -> 8846655.6 | I8: =I49+I80+I111+I142+I173+I204+I235+I266+I297 -> 17086378 | J8: =J49+J80+J111+J142+J173+J204+J235+J266+J297 -> 16030850 | ... AK8: =AK49+AK80+AK111+AK142+AK173+AK204+AK235+AK266+AK297 -> 0
A9: 1.3 | B9: Sistema de irrigação pivô central | C9: =C50+C81+C112+C143+C174+C205+C236+C267+C298 -> 0 | D9: =D50+D81+D112+D143+D174+D205+D236+D267+D298 -> 0 | E9: =E50+E81+E112+E143+E174+E205+E236+E267+E298 -> 0 | F9: =F50+F81+F112+F143+F174+F205+F236+F267+F298 -> 16998550 | G9: =G50+G81+G112+G143+G174+G205+G236+G267+G298 -> 16998550 | H9: =H50+H81+H112+H143+H174+H205+H236+H267+H298 -> 20422920 | I9: =I50+I81+I112+I143+I174+I205+I236+I267+I298 -> 39444707 | J9: =J50+J81+J112+J143+J174+J205+J236+J267+J298 -> 37007972 | ... AK9: =AK50+AK81+AK112+AK143+AK174+AK205+AK236+AK267+AK298 -> 0
A10: 1.4 | B10: Demais infraestrutura | C10: =C51+C82+C113+C144+C175+C206+C237+C268+C299 -> 0 | D10: =D51+D82+D113+D144+D175+D206+D237+D268+D299 -> 0 | E10: =E51+E82+E113+E144+E175+E206+E237+E268+E299 -> 0 | F10: =F51+F82+F113+F144+F175+F206+F237+F268+F299 -> 8300771.6 | G10: =G51+G82+G113+G144+G175+G206+G237+G268+G299 -> 8300771.6 | H10: =H51+H82+H113+H144+H175+H206+H237+H268+H299 -> 9972967.9 | I10: =I51+I82+I113+I144+I175+I206+I237+I268+I299 -> 19261731 | J10: =J51+J82+J113+J144+J175+J206+J237+J268+J299 -> 18071819 | ... AK10: =AK51+AK82+AK113+AK144+AK175+AK206+AK237+AK268+AK299 -> 0
B11: Ano de formação da cultura
A12: 1.5 | B12: Gasto com insumos | C12: =C53+C84+C115+C146+C177+C208+C239+C270+C301 -> 0 | D12: =D53+D84+D115+D146+D177+D208+D239+D270+D301 -> 0 | E12: =E53+E84+E115+E146+E177+E208+E239+E270+E301 -> 0 | F12: =F53+F84+F115+F146+F177+F208+F239+F270+F301 -> 6783097.9 | G12: =G53+G84+G115+G146+G177+G208+G239+G270+G301 -> 7252911.9 | H12: =H53+H84+H115+H146+H177+H208+H239+H270+H301 -> 8619371.8 | I12: =I53+I84+I115+I146+I177+I208+I239+I270+I301 -> 16304466 | J12: =J53+J84+J115+J146+J177+J208+J239+J270+J301 -> 15857845 | ... AK12: =AK53+AK84+AK115+AK146+AK177+AK208+AK239+AK270+AK301 -> 0
A13: 1.6 | B13: Gasto com mão de obra | C13: =C54+C85+C116+C147+C178+C209+C240+C271+C302 -> 0 | D13: =D54+D85+D116+D147+D178+D209+D240+D271+D302 -> 0 | E13: =E54+E85+E116+E147+E178+E209+E240+E271+E302 -> 0 | F13: =F54+F85+F116+F147+F178+F209+F240+F271+F302 -> 2248856 | G13: =G54+G85+G116+G147+G178+G209+G240+G271+G302 -> 2364403.3 | H13: =H54+H85+H116+H147+H178+H209+H240+H271+H302 -> 2817436.9 | I13: =I54+I85+I116+I147+I178+I209+I240+I271+I302 -> 5357238 | J13: =J54+J85+J116+J147+J178+J209+J240+J271+J302 -> 5164165.7 | ... AK13: =AK54+AK85+AK116+AK147+AK178+AK209+AK240+AK271+AK302 -> 0
A14: 1.7 | B14: Gasto com trator e equipamentos e avaição agrícola | C14: =C55+C86+C117+C148+C179+C210+C241+C272+C303 -> 0 | D14: =D55+D86+D117+D148+D179+D210+D241+D272+D303 -> 0 | E14: =E55+E86+E117+E148+E179+E210+E241+E272+E303 -> 0 | F14: =F55+F86+F117+F148+F179+F210+F241+F272+F303 -> 2580809.1 | G14: =G55+G86+G117+G148+G179+G210+G241+G272+G303 -> 2848279.9 | H14: =H55+H86+H117+H148+H179+H210+H241+H272+H303 -> 3368185.7 | I14: =I55+I86+I117+I148+I179+I210+I241+I272+I303 -> 6310055.4 | J14: =J55+J86+J117+J148+J179+J210+J241+J272+J303 -> 6239403.6 | ... AK14: =AK55+AK86+AK117+AK148+AK179+AK210+AK241+AK272+AK303 -> 0
A15: 1.8 | B15: Outros custos | C15: =C56+C87+C118+C149+C180+C211+C242+C273+C304 -> 0 | D15: =D56+D87+D118+D149+D180+D211+D242+D273+D304 -> 0 | E15: =E56+E87+E118+E149+E180+E211+E242+E273+E304 -> 0 | F15: =F56+F87+F118+F149+F180+F211+F242+F273+F304 -> 1426343.2 | G15: =G56+G87+G118+G149+G180+G211+G242+G273+G304 -> 1715283.5 | H15: =H56+H87+H118+H149+H180+H211+H242+H273+H304 -> 2002621.4 | I15: =I56+I87+I118+I149+I180+I211+I242+I273+I304 -> 3656941 | J15: =J56+J87+J118+J149+J180+J211+J242+J273+J304 -> 3775806.4 | ... AK15: =AK56+AK87+AK118+AK149+AK180+AK211+AK242+AK273+AK304 -> 0
B16: Sub-total - Investimentos | D16: =SUM(D7:D15) -> 0 | E16: =SUM(E7:E15) -> 0 | F16: =SUM(F7:F15) -> 47330068 | G16: =SUM(G7:G15) -> 48471840 | H16: =SUM(H7:H15) -> 58006516 | I16: =SUM(I7:I15) -> 1.1120001e+08 | J16: =SUM(J7:J15) -> 1.0569294e+08 | K16: =SUM(K7:K15) -> 1.0850775e+08 | ... AK16: =SUM(AK7:AK15) -> 0
A18: 2 | B18: CUSTOS OPERACIONAIS | D18: =D23 -> 0 | E18: =E23 -> 0 | F18: =F23 -> 14066016 | G18: =G23 -> 36860509 | H18: =H23 -> 65167661 | I18: =I23 -> 1.1157721e+08 | J18: =J23 -> 1.674746e+08 | K18: =K23 -> 2.264871e+08 | ... AK18: =AK23 -> 3.9093546e+08 | AM18: =AM23 -> 0 | AN18: =AN23 -> 0 | AO18: =AO23 -> 0 | AP18: =AP23 -> 0 | AQ18: =AQ23 -> 0 | AR18: =AR23 -> 0 | AS18: =AS23 -> 0 | AT18: =AT23 -> 0 | ... IS18: =IS23 -> 0
A19: 2.1 | B19: Gasto com insumos | D19: =D60+D91+D122+D153+D184+D215+D246+D277+D308 -> 0 | E19: =E60+E91+E122+E153+E184+E215+E246+E277+E308 -> 0 | F19: =F60+F91+F122+F153+F184+F215+F246+F277+F308 -> 6675345.2 | G19: =G60+G91+G122+G153+G184+G215+G246+G277+G308 -> 16493984 | H19: =H60+H91+H122+H153+H184+H215+H246+H277+H308 -> 28673773 | I19: =I60+I91+I122+I153+I184+I215+I246+I277+I308 -> 49465510 | J19: =J60+J91+J122+J153+J184+J215+J246+J277+J308 -> 73248307 | K19: =K60+K91+K122+K153+K184+K215+K246+K277+K308 -> 98580328 | ... AK19: =AK60+AK91+AK122+AK153+AK184+AK215+AK246+AK277+AK308 -> 1.6798231e+08 | AM19: =AM60+AM91+AM122+AM153+AM184+AM215+AM246+AM277+AM308 -> 0 | AN19: =AN60+AN91+AN122+AN153+AN184+AN215+AN246+AN277+AN308 -> 0 | AO19: =AO60+AO91+AO122+AO153+AO184+AO215+AO246+AO277+AO308 -> 0 | AP19: =AP60+AP91+AP122+AP153+AP184+AP215+AP246+AP277+AP308 -> 0 | AQ19: =AQ60+AQ91+AQ122+AQ153+AQ184+AQ215+AQ246+AQ277+AQ308 -> 0 | AR19: =AR60+AR91+AR122+AR153+AR184+AR215+AR246+AR277+AR308 -> 0 | AS19: =AS60+AS91+AS122+AS153+AS184+AS215+AS246+AS277+AS308 -> 0 | AT19: =AT60+AT91+AT122+AT153+AT184+AT215+AT246+AT277+AT308 -> 0 | ... IS19: =IS60+IS91+IS122+IS153+IS184+IS215+IS246+IS277+IS308 -> 0
A20: 2.2 | B20: Gasto com mão de obra | D20: =D61+D92+D123+D154+D185+D216+D247+D278+D309 -> 0 | E20: =E61+E92+E123+E154+E185+E216+E247+E278+E309 -> 0 | F20: =F61+F92+F123+F154+F185+F216+F247+F278+F309 -> 1425933.6 | G20: =G61+G92+G123+G154+G185+G216+G247+G278+G309 -> 6204525.1 | H20: =H61+H92+H123+H154+H185+H216+H247+H278+H309 -> 11732605 | I20: =I61+I92+I123+I154+I185+I216+I247+I278+I309 -> 19454736 | J20: =J61+J92+J123+J154+J185+J216+J247+J278+J309 -> 31189920 | K20: =K61+K92+K123+K154+K185+K216+K247+K278+K309 -> 42959387 | ... AK20: =AK61+AK92+AK123+AK154+AK185+AK216+AK247+AK278+AK309 -> 73576697 | AM20: =AM61+AM92+AM123+AM154+AM185+AM216+AM247+AM278+AM309 -> 0 | AN20: =AN61+AN92+AN123+AN154+AN185+AN216+AN247+AN278+AN309 -> 0 | AO20: =AO61+AO92+AO123+AO154+AO185+AO216+AO247+AO278+AO309 -> 0 | AP20: =AP61+AP92+AP123+AP154+AP185+AP216+AP247+AP278+AP309 -> 0 | AQ20: =AQ61+AQ92+AQ123+AQ154+AQ185+AQ216+AQ247+AQ278+AQ309 -> 0 | AR20: =AR61+AR92+AR123+AR154+AR185+AR216+AR247+AR278+AR309 -> 0 | AS20: =AS61+AS92+AS123+AS154+AS185+AS216+AS247+AS278+AS309 -> 0 | AT20: =AT61+AT92+AT123+AT154+AT185+AT216+AT247+AT278+AT309 -> 0 | ... IS20: =IS61+IS92+IS123+IS154+IS185+IS216+IS247+IS278+IS309 -> 0
A21: 2.3 | B21: Gasto com trator e equipamentos e avaição agrícola | D21: =D62+D93+D124+D155+D186+D217+D248+D279+D310 -> 0 | E21: =E62+E93+E124+E155+E186+E217+E248+E279+E310 -> 0 | F21: =F62+F93+F124+F155+F186+F217+F248+F279+F310 -> 3295711.1 | G21: =G62+G93+G124+G155+G186+G217+G248+G279+G310 -> 7622915.2 | H21: =H62+H93+H124+H155+H186+H217+H248+H279+H310 -> 13021699 | I21: =I62+I93+I124+I155+I186+I217+I248+I279+I310 -> 22368652 | J21: =J62+J93+J124+J155+J186+J217+J248+J279+J310 -> 32574426 | K21: =K62+K93+K124+K155+K186+K217+K248+K279+K310 -> 43285229 | ... AK21: =AK62+AK93+AK124+AK155+AK186+AK217+AK248+AK279+AK310 -> 69212206 | AM21: =AM62+AM93+AM124+AM155+AM186+AM217+AM248+AM279+AM310 -> 0 | AN21: =AN62+AN93+AN124+AN155+AN186+AN217+AN248+AN279+AN310 -> 0 | AO21: =AO62+AO93+AO124+AO155+AO186+AO217+AO248+AO279+AO310 -> 0 | AP21: =AP62+AP93+AP124+AP155+AP186+AP217+AP248+AP279+AP310 -> 0 | AQ21: =AQ62+AQ93+AQ124+AQ155+AQ186+AQ217+AQ248+AQ279+AQ310 -> 0 | AR21: =AR62+AR93+AR124+AR155+AR186+AR217+AR248+AR279+AR310 -> 0 | AS21: =AS62+AS93+AS124+AS155+AS186+AS217+AS248+AS279+AS310 -> 0 | AT21: =AT62+AT93+AT124+AT155+AT186+AT217+AT248+AT279+AT310 -> 0 | ... IS21: =IS62+IS93+IS124+IS155+IS186+IS217+IS248+IS279+IS310 -> 0
A22: 2.4 | B22: Outros custos | D22: =D63+D94+D125+D156+D187+D218+D249+D280+D311 -> 0 | E22: =E63+E94+E125+E156+E187+E218+E249+E280+E311 -> 0 | F22: =F63+F94+F125+F156+F187+F218+F249+F280+F311 -> 2669025.7 | G22: =G63+G94+G125+G156+G187+G218+G249+G280+G311 -> 6539084.9 | H22: =H63+H94+H125+H156+H187+H218+H249+H280+H311 -> 11739584 | I22: =I63+I94+I125+I156+I187+I218+I249+I280+I311 -> 20288311 | J22: =J63+J94+J125+J156+J187+J218+J249+J280+J311 -> 30461944 | K22: =K63+K94+K125+K156+K187+K218+K249+K280+K311 -> 41662157 | ... AK22: =AK63+AK94+AK125+AK156+AK187+AK218+AK249+AK280+AK311 -> 80164245 | AM22: =AM63+AM94+AM125+AM156+AM187+AM218+AM249+AM280+AM311 -> 0 | AN22: =AN63+AN94+AN125+AN156+AN187+AN218+AN249+AN280+AN311 -> 0 | AO22: =AO63+AO94+AO125+AO156+AO187+AO218+AO249+AO280+AO311 -> 0 | AP22: =AP63+AP94+AP125+AP156+AP187+AP218+AP249+AP280+AP311 -> 0 | AQ22: =AQ63+AQ94+AQ125+AQ156+AQ187+AQ218+AQ249+AQ280+AQ311 -> 0 | AR22: =AR63+AR94+AR125+AR156+AR187+AR218+AR249+AR280+AR311 -> 0 | AS22: =AS63+AS94+AS125+AS156+AS187+AS218+AS249+AS280+AS311 -> 0 | AT22: =AT63+AT94+AT125+AT156+AT187+AT218+AT249+AT280+AT311 -> 0 | ... IS22: =IS63+IS94+IS125+IS156+IS187+IS218+IS249+IS280+IS311 -> 0
B23: Sub-total - custos operacionais | D23: =SUM(D19:D22) -> 0 | E23: =SUM(E19:E22) -> 0 | F23: =SUM(F19:F22) -> 14066016 | G23: =SUM(G19:G22) -> 36860509 | H23: =SUM(H19:H22) -> 65167661 | I23: =SUM(I19:I22) -> 1.1157721e+08 | J23: =SUM(J19:J22) -> 1.674746e+08 | K23: =SUM(K19:K22) -> 2.264871e+08 | ... AK23: =SUM(AK19:AK22) -> 3.9093546e+08
A25: 3 | B25: ENTRADA - VALOR DA PRODUÇÃO | D25: =D35 -> 0 | E25: =E35 -> 0 | F25: =F35 -> 27876817 | G25: =G35 -> 72672258 | H25: =H35 -> 1.2688813e+08 | I25: =I35 -> 2.1675471e+08 | J25: =J35 -> 3.2944018e+08 | K25: =K35 -> 4.4506236e+08 | ... AK25: =AK35 -> 7.5819938e+08 | AM25: =AM35 -> 0 | AN25: =AN35 -> 0 | AO25: =AO35 -> 0 | AP25: =AP35 -> 0 | AQ25: =AQ35 -> 0 | AR25: =AR35 -> 0 | AS25: =AS35 -> 0 | AT25: =AT35 -> 0 | ... IS25: =IS35 -> 0
A26: 3.1 | B26: =VLOOKUP($A26,$A$44:$AK$321,B$1,0) -> Valor da produção Banana Nanica | D26: =VLOOKUP($A26,$A$44:$AK$321,D$1,0) -> 0 | E26: =VLOOKUP($A26,$A$44:$AK$321,E$1,0) -> 0 | F26: =VLOOKUP($A26,$A$44:$AK$321,F$1,0) -> 0 | G26: =VLOOKUP($A26,$A$44:$AK$321,G$1,0) -> 11074420 | H26: =VLOOKUP($A26,$A$44:$AK$321,H$1,0) -> 21456689 | I26: =VLOOKUP($A26,$A$44:$AK$321,I$1,0) -> 33377757 | J26: =VLOOKUP($A26,$A$44:$AK$321,J$1,0) -> 57551932 | K26: =VLOOKUP($A26,$A$44:$AK$321,K$1,0) -> 79224626 | ... AK26: =VLOOKUP($A26,$A$44:$AK$321,AK$1,0) -> 1.2028766e+08
A27: 3.2 | B27: =VLOOKUP($A27,$A$44:$AK$321,B$1,0) -> Valor da produção Banana Prata | D27: =VLOOKUP($A27,$A$44:$AK$321,D$1,0) -> 0 | E27: =VLOOKUP($A27,$A$44:$AK$321,E$1,0) -> 0 | F27: =VLOOKUP($A27,$A$44:$AK$321,F$1,0) -> 0 | G27: =VLOOKUP($A27,$A$44:$AK$321,G$1,0) -> 5167534.1 | H27: =VLOOKUP($A27,$A$44:$AK$321,H$1,0) -> 9929771.4 | I27: =VLOOKUP($A27,$A$44:$AK$321,I$1,0) -> 15327715 | J27: =VLOOKUP($A27,$A$44:$AK$321,J$1,0) -> 26151584 | K27: =VLOOKUP($A27,$A$44:$AK$321,K$1,0) -> 35424482 | ... AK27: =VLOOKUP($A27,$A$44:$AK$321,AK$1,0) -> 53872476
A28: 3.3 | B28: =VLOOKUP($A28,$A$44:$AK$321,B$1,0) -> Valor da produção Manga | D28: =VLOOKUP($A28,$A$44:$AK$321,D$1,0) -> 0 | E28: =VLOOKUP($A28,$A$44:$AK$321,E$1,0) -> 0 | F28: =VLOOKUP($A28,$A$44:$AK$321,F$1,0) -> 0 | G28: =VLOOKUP($A28,$A$44:$AK$321,G$1,0) -> 0 | H28: =VLOOKUP($A28,$A$44:$AK$321,H$1,0) -> 2171232.8 | I28: =VLOOKUP($A28,$A$44:$AK$321,I$1,0) -> 4892511.3 | J28: =VLOOKUP($A28,$A$44:$AK$321,J$1,0) -> 10222419 | K28: =VLOOKUP($A28,$A$44:$AK$321,K$1,0) -> 18642841 | ... AK28: =VLOOKUP($A28,$A$44:$AK$321,AK$1,0) -> 1.0183927e+08
A29: 3.4 | B29: =VLOOKUP($A29,$A$44:$AK$321,B$1,0) -> Valor da produção Limão | D29: =VLOOKUP($A29,$A$44:$AK$321,D$1,0) -> 0 | E29: =VLOOKUP($A29,$A$44:$AK$321,E$1,0) -> 0 | F29: =VLOOKUP($A29,$A$44:$AK$321,F$1,0) -> 0 | G29: =VLOOKUP($A29,$A$44:$AK$321,G$1,0) -> 676669.43 | H29: =VLOOKUP($A29,$A$44:$AK$321,H$1,0) -> 4084183.3 | I29: =VLOOKUP($A29,$A$44:$AK$321,I$1,0) -> 9223019.3 | J29: =VLOOKUP($A29,$A$44:$AK$321,J$1,0) -> 20889216 | K29: =VLOOKUP($A29,$A$44:$AK$321,K$1,0) -> 34699771 | ... AK29: =VLOOKUP($A29,$A$44:$AK$321,AK$1,0) -> 1.0006598e+08
A30: 3.5 | B30: =VLOOKUP($A30,$A$44:$AK$321,B$1,0) -> Valor da produção Cana | D30: =VLOOKUP($A30,$A$44:$AK$321,D$1,0) -> 0 | E30: =VLOOKUP($A30,$A$44:$AK$321,E$1,0) -> 0 | F30: =VLOOKUP($A30,$A$44:$AK$321,F$1,0) -> 0 | G30: =VLOOKUP($A30,$A$44:$AK$321,G$1,0) -> 0 | H30: =VLOOKUP($A30,$A$44:$AK$321,H$1,0) -> 0 | I30: =VLOOKUP($A30,$A$44:$AK$321,I$1,0) -> 0 | J30: =VLOOKUP($A30,$A$44:$AK$321,J$1,0) -> 0 | K30: =VLOOKUP($A30,$A$44:$AK$321,K$1,0) -> 0 | ... AK30: =VLOOKUP($A30,$A$44:$AK$321,AK$1,0) -> 0
A31: 3.6 | B31: =VLOOKUP($A31,$A$44:$AK$321,B$1,0) -> Valor da produção Soja | D31: =VLOOKUP($A31,$A$44:$AK$321,D$1,0) -> 0 | E31: =VLOOKUP($A31,$A$44:$AK$321,E$1,0) -> 0 | F31: =VLOOKUP($A31,$A$44:$AK$321,F$1,0) -> 8725410.6 | G31: =VLOOKUP($A31,$A$44:$AK$321,G$1,0) -> 17450821 | H31: =VLOOKUP($A31,$A$44:$AK$321,H$1,0) -> 27933972 | I31: =VLOOKUP($A31,$A$44:$AK$321,I$1,0) -> 48181067 | J31: =VLOOKUP($A31,$A$44:$AK$321,J$1,0) -> 67177378 | K31: =VLOOKUP($A31,$A$44:$AK$321,K$1,0) -> 86722781 | ... AK31: =VLOOKUP($A31,$A$44:$AK$321,AK$1,0) -> 1.1960749e+08
A32: 3.7 | B32: =VLOOKUP($A32,$A$44:$AK$321,B$1,0) -> Valor da produção Feijão | D32: =VLOOKUP($A32,$A$44:$AK$321,D$1,0) -> 0 | E32: =VLOOKUP($A32,$A$44:$AK$321,E$1,0) -> 0 | F32: =VLOOKUP($A32,$A$44:$AK$321,F$1,0) -> 5146765.8 | G32: =VLOOKUP($A32,$A$44:$AK$321,G$1,0) -> 10293532 | H32: =VLOOKUP($A32,$A$44:$AK$321,H$1,0) -> 16477117 | I32: =VLOOKUP($A32,$A$44:$AK$321,I$1,0) -> 28420057 | J32: =VLOOKUP($A32,$A$44:$AK$321,J$1,0) -> 39625211 | K32: =VLOOKUP($A32,$A$44:$AK$321,K$1,0) -> 51154251 | ... AK32: =VLOOKUP($A32,$A$44:$AK$321,AK$1,0) -> 70551606
A33: 3.8 | B33: =VLOOKUP($A33,$A$44:$AK$321,B$1,0) -> Valor da produção Milho 1 | D33: =VLOOKUP($A33,$A$44:$AK$321,D$1,0) -> 0 | E33: =VLOOKUP($A33,$A$44:$AK$321,E$1,0) -> 0 | F33: =VLOOKUP($A33,$A$44:$AK$321,F$1,0) -> 5059916.5 | G33: =VLOOKUP($A33,$A$44:$AK$321,G$1,0) -> 10119833 | H33: =VLOOKUP($A33,$A$44:$AK$321,H$1,0) -> 16199073 | I33: =VLOOKUP($A33,$A$44:$AK$321,I$1,0) -> 27940482 | J33: =VLOOKUP($A33,$A$44:$AK$321,J$1,0) -> 38956553 | K33: =VLOOKUP($A33,$A$44:$AK$321,K$1,0) -> 50291046 | ... AK33: =VLOOKUP($A33,$A$44:$AK$321,AK$1,0) -> 69361080
A34: 3.9 | B34: =VLOOKUP($A34,$A$44:$AK$321,B$1,0) -> Valor da produção Milho 2 | D34: =VLOOKUP($A34,$A$44:$AK$321,D$1,0) -> 0 | E34: =VLOOKUP($A34,$A$44:$AK$321,E$1,0) -> 0 | F34: =VLOOKUP($A34,$A$44:$AK$321,F$1,0) -> 8944724 | G34: =VLOOKUP($A34,$A$44:$AK$321,G$1,0) -> 17889448 | H34: =VLOOKUP($A34,$A$44:$AK$321,H$1,0) -> 28636093 | I34: =VLOOKUP($A34,$A$44:$AK$321,I$1,0) -> 49392099 | J34: =VLOOKUP($A34,$A$44:$AK$321,J$1,0) -> 68865883 | K34: =VLOOKUP($A34,$A$44:$AK$321,K$1,0) -> 88902560 | ... AK34: =VLOOKUP($A34,$A$44:$AK$321,AK$1,0) -> 1.2261383e+08
B35: Sub-total - valor da produção | D35: =SUM(D26:D34) -> 0 | E35: =SUM(E26:E34) -> 0 | F35: =SUM(F26:F34) -> 27876817 | G35: =SUM(G26:G34) -> 72672258 | H35: =SUM(H26:H34) -> 1.2688813e+08 | I35: =SUM(I26:I34) -> 2.1675471e+08 | J35: =SUM(J26:J34) -> 3.2944018e+08 | K35: =SUM(K26:K34) -> 4.4506236e+08 | ... AK35: =SUM(AK26:AK34) -> 7.5819938e+08
A37: 4 | B37: BALANÇO Anual (Item 3 - item 1 - item 2) | D37: =D35-D23-D16 -> 0 | E37: =E35-E23-E16 -> 0 | F37: =F35-F23-F16 -> -33519267 | G37: =G35-G23-G16 -> -12660092 | H37: =H35-H23-H16 -> 3713954.7 | I37: =I35-I23-I16 -> -6022512.6 | J37: =J35-J23-J16 -> 56272644 | K37: =K35-K23-K16 -> 1.1006751e+08 | ... AK37: =AK35-AK23-AK16 -> 3.6726393e+08
A39: 5 | B39: BALANÇO ACUMULADO | D39: =D37 -> 0 | E39: =D39+E37 -> 0 | F39: =E39+F37 -> -33519267 | G39: =F39+G37 -> -46179359 | H39: =G39+H37 -> -42465404 | I39: =H39+I37 -> -48487916 | J39: =I39+J37 -> 7784727.1 | K39: =J39+K37 -> 1.1785223e+08 | L39: =K39+L37 -> 2.9924036e+08 | ... AK39: =AJ39+AK37 -> 8.3318127e+09
A42: PLANEJAMENTO POR CULTURA
A43: Banana Nanica
A44: Planejamento Banana Nanica
A45: ITEM | B45: COMPONENTES | C45: ANO DE IMPLANTAÇÃO DA CULTURA
C46: 1 | D46: =C46+1 -> 2 | E46: =D46+1 -> 3 | F46: =E46+1 -> 4 | G46: =F46+1 -> 5 | H46: =G46+1 -> 6 | I46: =H46+1 -> 7 | J46: =I46+1 -> 8 | K46: =J46+1 -> 9 | ... AK46: =AJ46+1 -> 35
...

Sheet Balanço custo - receita-modelos
A2: BALANÇO RECEITA/CUSTO
G3: MODELOS | H3: Modelos | I3: Balanço receita/custo
A4: Cultura | B4: R$/ha/Ano (1) | I4: R$/ha/Ano(1)
A5: ='Resumo-Cult.Perma.'!A4 -> Banana Nanica | B5: ='Resumo-Cult.Perma.'!D35 -> 28049.03 | G5: Modelo 1 | H5: Banana Nanica | I5: =B5 -> 28049.03
A6: ='Resumo-Cult.Perma.'!A37 -> Banana Prata | B6: ='Resumo-Cult.Perma.'!D68 -> 28159.097 | G6: Modelo 2 | H6: Banana Prata | I6: =B6 -> 28159.097
A7: ='Resumo-Cult.Perma.'!A70 -> Manga | B7: ='Resumo-Cult.Perma.'!D101 -> 28623.958 | G7: Modelo 3 | H7: Manga | I7: =B7 -> 28623.958
A8: ='Resumo-Cult.Perma.'!A103 -> Limão | B8: ='Resumo-Cult.Perma.'!D134 -> 24626.385 | G8: Modelo 4 | H8: Limão | I8: =B8 -> 24626.385
A9: ='Resumo-Cult.Perma.'!A136 -> Cana | B9: ='Resumo-Cult.Perma.'!D162 -> 7441.2819 | G9: Modelo 5 | H9: Soja + Milho 2 | I9: =B10+B13 -> 13548.454
A10: ='Resumo-Cult.Temp.'!A4 -> Soja | B10: ='Resumo-Cult.Temp.'!D30 -> 6876.1567 | G10: Modelo 6 | H10: Milho 1 + Feijão | I10: =B11+B12 -> 15958.443
A11: ='Resumo-Cult.Temp.'!A32 -> Feijão | B11: ='Resumo-Cult.Temp.'!D58 -> 9006.6557 | G11: Modelo 7 | H11: Cana | I11: =B9 -> 7441.2819
A12: ='Resumo-Cult.Temp.'!A60 -> Milho 1 | B12: ='Resumo-Cult.Temp.'!D86 -> 6951.7873 | G12: (1) - Resultado médio período de 35 anos - Receita - custo
A13: ='Resumo-Cult.Temp.'!A88 -> Milho 2 | B13: ='Resumo-Cult.Temp.'!D114 -> 6672.297 | G13: custo = investimentos + operacionais
A14: (1) - Resultado médio período de 35 anos - Receita - custo
A15: custo = investimentos + operacionais

Sheet Área Plant-Colh e Produção
A2: ÁREA PLANTADA
A4: Ano | B4: Banana Nanica | C4: Banana Prata | D4: Manga | E4: Limão | F4: Soja | G4: Milho 1 | H4: Milho 2 | I4: Feijão | J4: TOTAL
A5: 2 | B5: {=TRANSPOSE('Critérios de Implantação'!$E39:$P39)} -> 0 | C5: {=TRANSPOSE('Critérios de Implantação'!$E40:$P40)} -> 0 | D5: {=TRANSPOSE('Critérios de Implantação'!$F41:$P41)} -> 0 | E5: {=TRANSPOSE('Critérios de Implantação'!$E42:$P42)} -> 0 | F5: {=TRANSPOSE('Critérios de Implantação'!$D43:$P43)} -> 0 | G5: {=TRANSPOSE('Critérios de Implantação'!$D45:$P45)} -> 0 | H5: {=TRANSPOSE('Critérios de Implantação'!$D44:$P44)} -> 0 | I5: {=TRANSPOSE('Critérios de Implantação'!$D46:$P46)} -> 0 | J5: =SUM(B5:I5) -> 0
A6: =A5+1 -> 3 | B6: 0 | C6: 0 | D6: 0 | E6: 0 | F6: 0 | G6: 0 | H6: 0 | I6: 0 | J6: =SUM(B6:I6) -> 0
A7: =A6+1 -> 4 | B7: 113.28171 | C7: 62.934285 | D7: 62.934285 | E7: 100.69486 | F7: 604.16913 | G7: 314.67142 | H7: 604.16913 | I7: 314.67142 | J7: =SUM(B7:I7) -> 2177.5262
A8: =A7+1 -> 5 | B8: 226.56342 | C8: 125.86857 | D8: 125.86857 | E8: 201.38971 | F8: 1208.3383 | G8: 629.34285 | H8: 1208.3383 | I8: 629.34285 | J8: =SUM(B8:I8) -> 4355.0525
A9: =A8+1 -> 6 | B9: 362.66582 | C9: 201.48101 | D9: 201.48101 | E9: 322.36962 | F9: 1934.2177 | G9: 1007.4051 | H9: 1934.2177 | I9: 1007.4051 | J9: =SUM(B9:I9) -> 6971.2429
A10: =A9+1 -> 7 | B10: 625.53317 | C10: 347.51843 | D10: 347.51843 | E10: 556.02949 | F10: 3336.1769 | G10: 1737.5922 | H10: 3336.1769 | I10: 1737.5922 | J10: =SUM(B10:I10) -> 12024.138
A11: =A10+1 -> 8 | B11: 872.16164 | C11: 484.53425 | D11: 484.53425 | E11: 775.25479 | F11: 4651.5288 | G11: 2422.6712 | H11: 4651.5288 | I11: 2422.6712 | J11: =SUM(B11:I11) -> 16764.885
A12: =A11+1 -> 9 | B12: 1125.9189 | C12: 625.51053 | D12: 625.51053 | E12: 1000.8168 | F12: 6004.9011 | G12: 3127.5526 | H12: 6004.9011 | I12: 3127.5526 | J12: =SUM(B12:I12) -> 21642.664
A13: =A12+1 -> 10 | B13: 1332.621 | C13: 740.34503 | D13: 740.34503 | E13: 1184.552 | F13: 7107.3122 | G13: 3701.7251 | H13: 7107.3122 | I13: 3701.7251 | J13: =SUM(B13:I13) -> 25615.938
A14: =A13+1 -> 11 | B14: 1479.1447 | C14: 821.74704 | D14: 821.74704 | E14: 1314.7953 | F14: 7888.7716 | G14: 4108.7352 | H14: 7888.7716 | I14: 4108.7352 | J14: =SUM(B14:I14) -> 28432.448
A15: =A14+1 -> 12 | B15: 1552.86 | C15: 862.7 | D15: 862.7 | E15: 1380.32 | F15: 8281.92 | G15: 4313.5 | H15: 8281.92 | I15: 4313.5 | J15: =SUM(B15:I15) -> 29849.42
A16: =A15+1 -> 13 | B16: 1552.86 | C16: 862.7 | D16: =D15 -> 862.7 | E16: 1380.32 | F16: 8281.92 | G16: 4313.5 | H16: 8281.92 | I16: 4313.5 | J16: =SUM(B16:I16) -> 29849.42
A17: =A16+1 -> 14 | B17: =B16 -> 1552.86 | C17: =C16 -> 862.7 | D17: =D16 -> 862.7 | E17: =E16 -> 1380.32 | F17: 8281.92 | G17: 4313.5 | H17: 8281.92 | I17: 4313.5 | J17: =SUM(B17:I17) -> 29849.42
A18: =A17+1 -> 15 | B18: =B17 -> 1552.86 | C18: =C17 -> 862.7 | D18: =D17 -> 862.7 | E18: =E17 -> 1380.32 | F18: =F17 -> 8281.92 | G18: =G17 -> 4313.5 | H18: =H17 -> 8281.92 | I18: =I17 -> 4313.5 | J18: =SUM(B18:I18) -> 29849.42
A19: =A18+1 -> 16 | B19: =B18 -> 1552.86 | C19: =C18 -> 862.7 | D19: =D18 -> 862.7 | E19: =E18 -> 1380.32 | F19: =F18 -> 8281.92 | G19: =G18 -> 4313.5 | H19: =H18 -> 8281.92 | I19: =I18 -> 4313.5 | J19: =SUM(B19:I19) -> 29849.42
A20: =A19+1 -> 17 | B20: =B19 -> 1552.86 | C20: =C19 -> 862.7 | D20: =D19 -> 862.7 | E20: =E19 -> 1380.32 | F20: =F19 -> 8281.92 | G20: =G19 -> 4313.5 | H20: =H19 -> 8281.92 | I20: =I19 -> 4313.5 | J20: =SUM(B20:I20) -> 29849.42
A21: =A20+1 -> 18 | B21: =B20 -> 1552.86 | C21: =C20 -> 862.7 | D21: =D20 -> 862.7 | E21: =E20 -> 1380.32 | F21: =F20 -> 8281.92 | G21: =G20 -> 4313.5 | H21: =H20 -> 8281.92 | I21: =I20 -> 4313.5 | J21: =SUM(B21:I21) -> 29849.42
A22: =A21+1 -> 19 | B22: =B21 -> 1552.86 | C22: =C21 -> 862.7 | D22: =D21 -> 862.7 | E22: =E21 -> 1380.32 | F22: =F21 -> 8281.92 | G22: =G21 -> 4313.5 | H22: =H21 -> 8281.92 | I22: =I21 -> 4313.5 | J22: =SUM(B22:I22) -> 29849.42
A23: =A22+1 -> 20 | B23: =B22 -> 1552.86 | C23: =C22 -> 862.7 | D23: =D22 -> 862.7 | E23: =E22 -> 1380.32 | F23: =F22 -> 8281.92 | G23: =G22 -> 4313.5 | H23: =H22 -> 8281.92 | I23: =I22 -> 4313.5 | J23: =SUM(B23:I23) -> 29849.42
A24: =A23+1 -> 21 | B24: =B23 -> 1552.86 | C24: =C23 -> 862.7 | D24: =D23 -> 862.7 | E24: =E23 -> 1380.32 | F24: =F23 -> 8281.92 | G24: =G23 -> 4313.5 | H24: =H23 -> 8281.92 | I24: =I23 -> 4313.5 | J24: =SUM(B24:I24) -> 29849.42
A25: =A24+1 -> 22 | B25: =B24 -> 1552.86 | C25: =C24 -> 862.7 | D25: =D24 -> 862.7 | E25: =E24 -> 1380.32 | F25: =F24 -> 8281.92 | G25: =G24 -> 4313.5 | H25: =H24 -> 8281.92 | I25: =I24 -> 4313.5 | J25: =SUM(B25:I25) -> 29849.42
A26: =A25+1 -> 23 | B26: =B25 -> 1552.86 | C26: =C25 -> 862.7 | D26: =D25 -> 862.7 | E26: =E25 -> 1380.32 | F26: =F25 -> 8281.92 | G26: =G25 -> 4313.5 | H26: =H25 -> 8281.92 | I26: =I25 -> 4313.5 | J26: =SUM(B26:I26) -> 29849.42
A27: =A26+1 -> 24 | B27: =B26 -> 1552.86 | C27: =C26 -> 862.7 | D27: =D26 -> 862.7 | E27: =E26 -> 1380.32 | F27: =F26 -> 8281.92 | G27: =G26 -> 4313.5 | H27: =H26 -> 8281.92 | I27: =I26 -> 4313.5 | J27: =SUM(B27:I27) -> 29849.42
A28: =A27+1 -> 25 | B28: =B27 -> 1552.86 | C28: =C27 -> 862.7 | D28: =D27 -> 862.7 | E28: =E27 -> 1380.32 | F28: =F27 -> 8281.92 | G28: =G27 -> 4313.5 | H28: =H27 -> 8281.92 | I28: =I27 -> 4313.5 | J28: =SUM(B28:I28) -> 29849.42
A29: =A28+1 -> 26 | B29: =B28 -> 1552.86 | C29: =C28 -> 862.7 | D29: =D28 -> 862.7 | E29: =E28 -> 1380.32 | F29: =F28 -> 8281.92 | G29: =G28 -> 4313.5 | H29: =H28 -> 8281.92 | I29: =I28 -> 4313.5 | J29: =SUM(B29:I29) -> 29849.42
... A38: =A37+1 -> 35 | B38: =B37 -> 1552.86 | C38: =C37 -> 862.7 | D38: =D37 -> 862.7 | E38: =E37 -> 1380.32 | F38: =F37 -> 8281.92 | G38: =G37 -> 4313.5 | H38: =H37 -> 8281.92 | I38: =I37 -> 4313.5 | J38: =SUM(B38:I38) -> 29849.42
A39: Obs- Anos 1 de início da obra
A41: PRODUÇÃO em Toneladas | L41: VALOR DA PRODUÇÃO /1000R$
A43: Ano | B43: Banana Nanica | C43: Banana Prata | D43: Manga | E43: Limão | F43: Soja | G43: Milho 1 | H43: Milho 2 | I43: Feijão | L43: Ano | M43: Banana Nanica | N43: Banana Prata | O43: Manga | P43: Limão | Q43: Soja | R43: Milho 1 | S43: Milho 2 | T43: Feijão | U43: TOTAL
A44: 2 | F44: {=TRANSPOSE('Planejamento Global'!D223:AK223/'Rentabilidade-Cult.Temp.'!E68)} -> 0 | G44: {=TRANSPOSE('Planejamento Global'!D285:AK285/'Rentabilidade-Cult.Temp.'!I68)} -> 0 | H44: {=TRANSPOSE('Planejamento Global'!D316:AK316/'Rentabilidade-Cult.Temp.'!K68)} -> 0 | I44: {=TRANSPOSE('Planejamento Global'!D254:AK254/'Rentabilidade-Cult.Temp.'!G68)} -> 0 | L44: 2 | Q44: {=TRANSPOSE('Planejamento Global'!D223:AK223/1000)} -> 0 | R44: {=TRANSPOSE('Planejamento Global'!D285:AK285/1000)} -> 0 | S44: {=TRANSPOSE('Planejamento Global'!D316:AK316/1000)} -> 0 | T44: {=TRANSPOSE('Planejamento Global'!D254:AK254/1000)} -> 0 | U44: =SUM(M44:T44) -> 0
A45: =A44+1 -> 3 | B45: {=TRANSPOSE('Planejamento Global'!E68:AK68/'Rentabilidade-Cult.Perma.'!AN94)} -> 0 | C45: {=TRANSPOSE('Planejamento Global'!E99:AK99/'Rentabilidade-Cult.Perma.'!AN186)} -> 0 | E45: {=TRANSPOSE('Planejamento Global'!E161:AK161/'Rentabilidade-Cult.Perma.'!AN365)} -> 0 | F45: 0 | G45: 0 | H45: 0 | I45: 0 | L45: =L44+1 -> 3 | M45: {=TRANSPOSE('Planejamento Global'!E68:AK68/1000)} -> 0 | N45: {=TRANSPOSE('Planejamento Global'!E99:AK99/1000)} -> 0 | P45: {=TRANSPOSE('Planejamento Global'!E161:AK161/1000)} -> 0 | Q45: 0 | R45: 0 | S45: 0 | T45: 0 | U45: =SUM(M45:T45) -> 0
A46: =A45+1 -> 4 | B46: 0 | C46: 0 | D46: {=TRANSPOSE('Planejamento Global'!F130:AK130/'Rentabilidade-Cult.Perma.'!AN277)} -> 0 | E46: 0 | F46: 3008.7623 | G46: 3373.2777 | H46: 5963.1493 | I46: 887.37341 | L46: =L45+1 -> 4 | M46: 0 | N46: 0 | O46: {=TRANSPOSE('Planejamento Global'!F130:AK130/1000)} -> 0 | P46: 0 | Q46: 8725.4106 | R46: 5059.9165 | S46: 8944.724 | T46: 5146.7658 | U46: =SUM(M46:T46) -> 27876.817
A47: =A46+1 -> 5 | B47: 8518.7848 | C47: 2246.754 | D47: 0 | E47: 281.9456 | F47: 6017.5246 | G47: 6746.5553 | H47: 11926.299 | I47: 1774.7468 | L47: =L46+1 -> 5 | M47: 11074.42 | N47: 5167.5341 | O47: 0 | P47: 676.66943 | Q47: 17450.821 | R47: 10119.833 | S47: 17889.448 | T47: 10293.532 | U47: =SUM(M47:T47) -> 72672.258
A48: =A47+1 -> 6 | B48: 16505.145 | C48: 4317.2919 | D48: 472.00713 | E48: 1701.7431 | F48: 9632.4041 | G48: 10799.382 | H48: 19090.729 | I48: 2840.8822 | L48: =L47+1 -> 6 | M48: 21456.689 | N48: 9929.7714 | O48: 2171.2328 | P48: 4084.1833 | Q48: 27933.972 | R48: 16199.073 | S48: 28636.093 | T48: 16477.117 | U48: =SUM(M48:T48) -> 126888.13
A49: =A48+1 -> 7 | B49: 25675.197 | C49: 6664.2241 | D49: 1063.5894 | E49: 3842.9247 | F49: 16614.161 | G49: 18626.988 | H49: 32928.066 | I49: 4900.0099 | L49: =L48+1 -> 7 | M49: 33377.757 | N49: 15327.715 | O49: 4892.5113 | P49: 9223.0193 | Q49: 48181.067 | R49: 27940.482 | S49: 49392.099 | T49: 28420.057 | U49: =SUM(M49:T49) -> 216754.71
A50: =A49+1 -> 8 | B50: 44270.717 | C50: 11370.254 | D50: 2222.265 | E50: 8703.8402 | F50: 23164.613 | G50: 25971.036 | H50: 45910.589 | I50: 6831.9329 | L50: =L49+1 -> 8 | M50: 57551.932 | N50: 26151.584 | O50: 10222.419 | P50: 20889.216 | Q50: 67177.378 | R50: 38956.553 | S50: 68865.883 | T50: 39625.211 | U50: =SUM(M50:T50) -> 329440.18
A51: =A50+1 -> 9 | B51: 60942.02 | C51: 15401.949 | D51: 4052.7916 | E51: 14458.238 | F51: 29904.407 | G51: 33527.364 | H51: 59268.373 | I51: 8819.6984 | L51: =L50+1 -> 9 | M51: 79224.626 | N51: 35424.482 | O51: 18642.841 | P51: 34699.771 | Q51: 86722.781 | R51: 50291.046 | S51: 88902.56 | T51: 51154.251 | U51: =SUM(M51:T51) -> 445062.36
A52: =A51+1 -> 10 | B52: 77097.515 | C52: 19202.798 | D52: 6340.3409 | E52: 20775.847 | F52: 35394.415 | G52: 39682.493 | H52: 70149.172 | I52: 10438.865 | L52: =L51+1 -> 10 | M52: 100226.77 | N52: 44166.436 | O52: 29165.568 | P52: 49862.033 | Q52: 102643.8 | R52: 59523.74 | S52: 105223.76 | T52: 60545.416 | U52: =SUM(M52:T52) -> 551357.52
...

Sheet Resumos ->

Sheet Resumo-Cult.Perma.
A2: RESUMO - Culturas Permanentes
A4: Banana Nanica
A5: Custo 1 Ha
A6: ITEM | B6: COMPONENTES | C6: ANO DE IMPLANTAÇÃO DA CULTURA
C7: 1 | D7: =C7+1 -> 2 | E7: =D7+1 -> 3 | F7: =E7+1 -> 4 | G7: =F7+1 -> 5 | H7: =G7+1 -> 6 | I7: =H7+1 -> 7 | J7: =I7+1 -> 8 | K7: =J7+1 -> 9 | ... AK7: =AJ7+1 -> 35
A8: 1 | B8: INVESTIMENTOS
A9: 1.1 | B9: Supressão vegetal | C9: ='Custos Diversos'!E164 -> 1293.6736
A10: 1.2 | B10: Sistema de irrigação localizada | C10: ='Rentabilidade-Cult.Perma.'!AN65 -> 22500 | AA10: =O10 -> 0
A11: 1.3 | B11: Sistema de irrigação pivô central
A12: 1.4 | B12: Demais infraestrutura | C12: ='Rentabilidade-Cult.Perma.'!AN70-'Rentabilidade-Cult.Perma.'!AN65 -> 23438.4 | AA12: =O12 -> 0
B13: Ano 1 do plantio | O13: =C13 -> 0 | AA13: =O13 -> 0
A14: 1.5 | B14: Gasto com insumos | C14: ='Rentabilidade-Cult.Perma.'!AN23 -> 28262.63 | AA14: =O14 -> 0
A15: 1.6 | B15: Gasto com mão de obra | C15: ='Rentabilidade-Cult.Perma.'!AN44 -> 8787 | AA15: =O15 -> 0
A16: 1.7 | B16: Gasto com trator e equipamentos e avaição agrícola | C16: ='Rentabilidade-Cult.Perma.'!AN60 -> 7635 | AA16: =O16 -> 0
A17: 1.8 | B17: Outros custos | C17: =SUM('Rentabilidade-Cult.Perma.'!AN75:AN82) -> 3996.2008 | AA17: =O17 -> 0
B18: Sub-total - Investimentos | C18: =SUM(C9:C17) -> 95912.905 | D18: =SUM(D9:D17) -> 0 | E18: =SUM(E9:E17) -> 0 | F18: =SUM(F9:F17) -> 0 | G18: =SUM(G9:G17) -> 0 | H18: =SUM(H9:H17) -> 0 | I18: =SUM(I9:I17) -> 0 | J18: =SUM(J9:J17) -> 0 | ... AK18: =SUM(AK9:AK17) -> 0
A20: 2 | B20: CUSTOS OPERACIONAIS
A21: 2.1 | B21: Gasto com insumos | D21: ='Rentabilidade-Cult.Perma.'!AO23 -> 16388.242 | E21: ='Rentabilidade-Cult.Perma.'!AP23 -> 16378.492 | F21: ='Rentabilidade-Cult.Perma.'!AQ23 -> 16378.492 | G21: ='Rentabilidade-Cult.Perma.'!AR23 -> 14951.649 | H21: ='Rentabilidade-Cult.Perma.'!AS23 -> 14951.649 | I21: ='Rentabilidade-Cult.Perma.'!AT23 -> 14951.649 | J21: ='Rentabilidade-Cult.Perma.'!AU23 -> 14951.649 | K21: ='Rentabilidade-Cult.Perma.'!AV23 -> 14951.649 | ... AK21: ='Rentabilidade-Cult.Perma.'!BV23 -> 14951.649
A22: 2.2 | B22: Gasto com mão de obra | D22: ='Rentabilidade-Cult.Perma.'!AO44 -> 19308 | E22: ='Rentabilidade-Cult.Perma.'!AP44 -> 18342.312 | F22: ='Rentabilidade-Cult.Perma.'!AQ44 -> 17434.625 | G22: ='Rentabilidade-Cult.Perma.'!AR44 -> 17434.625 | H22: ='Rentabilidade-Cult.Perma.'!AS44 -> 17434.625 | I22: ='Rentabilidade-Cult.Perma.'!AT44 -> 16526.938 | J22: ='Rentabilidade-Cult.Perma.'!AU44 -> 16526.938 | K22: ='Rentabilidade-Cult.Perma.'!AV44 -> 13803.875 | ... AK22: ='Rentabilidade-Cult.Perma.'!BV44 -> 12896.188
A23: 2.3 | B23: Gasto com trator e equipamentos e avaição agrícola | D23: ='Rentabilidade-Cult.Perma.'!AO60 -> 3425 | E23: ='Rentabilidade-Cult.Perma.'!AP60 -> 2862.5 | F23: ='Rentabilidade-Cult.Perma.'!AQ60 -> 2800 | G23: ='Rentabilidade-Cult.Perma.'!AR60 -> 2862.5 | H23: ='Rentabilidade-Cult.Perma.'!AS60 -> 2800 | I23: ='Rentabilidade-Cult.Perma.'!AT60 -> 2862.5 | J23: ='Rentabilidade-Cult.Perma.'!AU60 -> 2800 | K23: ='Rentabilidade-Cult.Perma.'!AV60 -> 2862.5 | ... AK23: ='Rentabilidade-Cult.Perma.'!BV60 -> 2862.5
A24: 2.4 | B24: Outros custos | D24: =SUM('Rentabilidade-Cult.Perma.'!AO75:AO82) -> 4225.8928 | E24: =SUM('Rentabilidade-Cult.Perma.'!AP75:AP82) -> 4340.7388 | F24: =SUM('Rentabilidade-Cult.Perma.'!AQ75:AQ82) -> 4340.7388 | G24: =SUM('Rentabilidade-Cult.Perma.'!AR75:AR82) -> 4455.5848 | H24: =SUM('Rentabilidade-Cult.Perma.'!AS75:AS82) -> 4455.5848 | I24: =SUM('Rentabilidade-Cult.Perma.'!AT75:AT82) -> 4685.2768 | J24: =SUM('Rentabilidade-Cult.Perma.'!AU75:AU82) -> 4685.2768 | K24: =SUM('Rentabilidade-Cult.Perma.'!AV75:AV82) -> 4685.2768 | ... AK24: =SUM('Rentabilidade-Cult.Perma.'!BV75:BV82) -> 4685.2768
B25: Sub-total - custos operacionais | C25: =SUM(C21:C24) -> 0 | D25: =SUM(D21:D24) -> 43347.135 | E25: =SUM(E21:E24) -> 41924.044 | F25: =SUM(F21:F24) -> 40953.856 | G25: =SUM(G21:G24) -> 39704.359 | H25: =SUM(H21:H24) -> 39641.859 | I25: =SUM(I21:I24) -> 39026.364 | J25: =SUM(J21:J24) -> 38963.864 | ... AK25: =SUM(AK21:AK24) -> 35395.614
A27: 3 | B27: ENTRADA - VALOR DA PRODUÇÃO
A28: 3.1 | B28: Valor da produção banana nanica | C28: ='Rentabilidade-Cult.Perma.'!AN90 -> 0 | D28: ='Rentabilidade-Cult.Perma.'!AO90 -> 97760 | E28: ='Rentabilidade-Cult.Perma.'!AP90 -> 91650 | F28: ='Rentabilidade-Cult.Perma.'!AQ90 -> 85540 | G28: ='Rentabilidade-Cult.Perma.'!AR90 -> 85540 | H28: ='Rentabilidade-Cult.Perma.'!AS90 -> 85540 | I28: ='Rentabilidade-Cult.Perma.'!AT90 -> 79430 | J28: ='Rentabilidade-Cult.Perma.'!AU90 -> 79430 | ... AK28: ='Rentabilidade-Cult.Perma.'!BV90 -> 54990
B29: Sub-total - valor da produção | C29: =SUM(C28:C28) -> 0 | D29: =SUM(D28:D28) -> 97760 | E29: =SUM(E28:E28) -> 91650 | F29: =SUM(F28:F28) -> 85540 | G29: =SUM(G28:G28) -> 85540 | H29: =SUM(H28:H28) -> 85540 | I29: =SUM(I28:I28) -> 79430 | J29: =SUM(J28:J28) -> 79430 | ... AK29: =SUM(AK28:AK28) -> 54990
A31: 4 | B31: BALANÇO anual(Item 3 - item 1-item2) | C31: =C29-C25-C18 -> -95912.905 | D31: =D29-D25-D18 -> 54412.865 | E31: =E29-E25-E18 -> 49725.956 | F31: =F29-F25-F18 -> 44586.144 | G31: =G29-G25-G18 -> 45835.641 | H31: =H29-H25-H18 -> 45898.141 | I31: =I29-I25-I18 -> 40403.636 | J31: =J29-J25-J18 -> 40466.136 | ... AK31: =AK29-AK25-AK18 -> 19594.386
A33: 5 | B33: BALANÇO ACUMULADO | C33: =C31 -> -95912.905 | D33: =C33+D31 -> -41500.04 | E33: =D33+E31 -> 8225.9162 | F33: =E33+F31 -> 52812.06 | G33: =F33+G31 -> 98647.701 | H33: =G33+H31 -> 144545.84 | I33: =H33+I31 -> 184949.48 | J33: =I33+J31 -> 225415.61 | K33: =J33+K31 -> 250212.31 | ... AK33: =AJ33+AK31 -> 981716.06
C35: R$/ha/ano = | D35: =AK33/AK7 -> 28049.03 | E35: 35 anos
A37: Banana Prata
A38: Custo 1 Ha
A39: ITEM | B39: COMPONENTES | C39: ANO DE IMPLANTAÇÃO DA CULTURA
C40: 1 | D40: =C40+1 -> 2 | E40: =D40+1 -> 3 | F40: =E40+1 -> 4 | G40: =F40+1 -> 5 | H40: =G40+1 -> 6 | I40: =H40+1 -> 7 | J40: =I40+1 -> 8 | K40: =J40+1 -> 9 | ... AK40: =AJ40+1 -> 35
A41: 1 | B41: INVESTIMENTOS
A42: 1.1 | B42: Supressão vegetal | C42: ='Custos Diversos'!E164 -> 1293.6736
A43: 1.2 | B43: Sistema de irrigação localizada | C43: ='Rentabilidade-Cult.Perma.'!AN157 -> 22500
A44: 1.3 | B44: Sistema de irrigação pivô central
A45: 1.4 | B45: Demais infraestrutura | C45: ='Rentabilidade-Cult.Perma.'!AN162-'Rentabilidade-Cult.Perma.'!AN157 -> 23438.4
B46: Ano 1 do plantio
A47: 1.5 | B47: Gasto com insumos | C47: ='Rentabilidade-Cult.Perma.'!AN115 -> 15865.352
A48: 1.6 | B48: Gasto com mão de obra | C48: ='Rentabilidade-Cult.Perma.'!AN136 -> 7772
...

Sheet Resumo-Cult.Temp.
A2: RESUMO - Culturas Temporárias
A4: Soja
A5: Custo 1 Ha
A6: ITEM | B6: COMPONENTES | C6: ANO DE IMPLANTAÇÃO DA CULTURA
C7: 1 | D7: =C7+1 -> 2 | E7: =D7+1 -> 3 | F7: =E7+1 -> 4 | G7: =F7+1 -> 5 | H7: =G7+1 -> 6 | I7: =H7+1 -> 7 | J7: =I7+1 -> 8 | K7: =J7+1 -> 9 | ... AJ7: =AI7+1 -> 34 | AK7: 35
A8: 1 | B8: INVESTIMENTOS
A9: 1.1 | B9: Supressão vegetal | C9: ='Custos Diversos'!E165 -> 646.83682
A10: 1.2 | B10: Sistema de irrigação localizada
A11: 1.3 | B11: Sistema de irrigação pivô central | C11: ='Rentabilidade-Cult.Temp.'!E42 -> 9250
A12: 1.4 | B12: Demais infraestrutura | C12: ='Rentabilidade-Cult.Temp.'!E45-'Rentabilidade-Cult.Temp.'!E42 -> 1598.75
B13: Sub-total - Investimentos | C13: =SUM(C9:C12) -> 11495.587
A15: 2 | B15: CUSTOS OPERACIONAIS
A16: 2.1 | B16: Gasto com insumos | C16: ='Rentabilidade-Cult.Temp.'!E19 -> 3075 | D16: =C16 -> 3075 | E16: =D16 -> 3075 | F16: =E16 -> 3075 | G16: =F16 -> 3075 | H16: =G16 -> 3075 | I16: =H16 -> 3075 | J16: =I16 -> 3075 | K16: =J16 -> 3075 | ... AK16: =AJ16 -> 3075
A17: 2.2 | B17: Gasto com mão de obra | C17: ='Rentabilidade-Cult.Temp.'!E26 -> 795 | D17: =C17 -> 795 | E17: =D17 -> 795 | F17: =E17 -> 795 | G17: =F17 -> 795 | H17: =G17 -> 795 | I17: =H17 -> 795 | J17: =I17 -> 795 | K17: =J17 -> 795 | ... AK17: =AJ17 -> 795
A18: 2.3 | B18: Gasto com trator e equipamentos e avaição agrícola | C18: ='Rentabilidade-Cult.Temp.'!E38 -> 2042.5 | D18: =C18 -> 2042.5 | E18: =D18 -> 2042.5 | F18: =E18 -> 2042.5 | G18: =F18 -> 2042.5 | H18: =G18 -> 2042.5 | I18: =H18 -> 2042.5 | J18: =I18 -> 2042.5 | K18: =J18 -> 2042.5 | ... AK18: =AJ18 -> 2042.5
A19: 2.4 | B19: Outros custos | C19: =SUM('Rentabilidade-Cult.Temp.'!E50:E58) -> 1324.898 | D19: =C19 -> 1324.898 | E19: =D19 -> 1324.898 | F19: =E19 -> 1324.898 | G19: =F19 -> 1324.898 | H19: =G19 -> 1324.898 | I19: =H19 -> 1324.898 | J19: =I19 -> 1324.898 | K19: =J19 -> 1324.898 | ... AK19: =AJ19 -> 1324.898
B20: Sub-total - custos operacionais | C20: =SUM(C16:C19) -> 7237.398 | D20: =SUM(D16:D19) -> 7237.398 | E20: =SUM(E16:E19) -> 7237.398 | F20: =SUM(F16:F19) -> 7237.398 | G20: =SUM(G16:G19) -> 7237.398 | H20: =SUM(H16:H19) -> 7237.398 | I20: =SUM(I16:I19) -> 7237.398 | J20: =SUM(J16:J19) -> 7237.398 | ... AK20: =SUM(AK16:AK19) -> 7237.398
C21: =C20-7129 -> 108.39799
A22: 3 | B22: ENTRADA - VALOR DA PRODUÇÃO
A23: 3.1 | B23: Valor da produção soja | C23: ='Rentabilidade-Cult.Temp.'!E64 -> 14442 | D23: =C23 -> 14442 | E23: =D23 -> 14442 | F23: =E23 -> 14442 | G23: =F23 -> 14442 | H23: =G23 -> 14442 | I23: =H23 -> 14442 | J23: =I23 -> 14442 | K23: =J23 -> 14442 | ... AK23: =AJ23 -> 14442
B24: Sub-total - valor da produção | C24: =SUM(C23:C23) -> 14442 | D24: =SUM(D23:D23) -> 14442 | E24: =SUM(E23:E23) -> 14442 | F24: =SUM(F23:F23) -> 14442 | G24: =SUM(G23:G23) -> 14442 | H24: =SUM(H23:H23) -> 14442 | I24: =SUM(I23:I23) -> 14442 | J24: =SUM(J23:J23) -> 14442 | ... AK24: =SUM(AK23:AK23) -> 14442
A26: 4 | B26: BALANÇO anual(Item 3 - item 1-item2) | C26: =C24-C20-C13 -> -4290.9848 | D26: =D24-D20-D13 -> 7204.602 | E26: =E24-E20-E13 -> 7204.602 | F26: =F24-F20-F13 -> 7204.602 | G26: =G24-G20-G13 -> 7204.602 | H26: =H24-H20-H13 -> 7204.602 | I26: =I24-I20-I13 -> 7204.602 | J26: =J24-J20-J13 -> 7204.602 | ... AK26: =AK24-AK20-AK13 -> 7204.602
A28: 5 | B28: BALANÇO ACUMULADO | C28: =C26 -> -4290.9848 | D28: =C28+D26 -> 2913.6172 | E28: =D28+E26 -> 10118.219 | F28: =E28+F26 -> 17322.821 | G28: =F28+G26 -> 24527.423 | H28: =G28+H26 -> 31732.025 | I28: =H28+I26 -> 38936.627 | J28: =I28+J26 -> 46141.229 | K28: =J28+K26 -> 53345.831 | ... AK28: =AJ28+AK26 -> 240665.48
C30: R$/ha/ano = | D30: =AK28/AK7 -> 6876.1567 | E30: 35 anos
A32: Feijão
A33: Custo 1 Ha
A34: ITEM | B34: COMPONENTES | C34: ANO DE IMPLANTAÇÃO DA CULTURA
C35: 1 | D35: =C35+1 -> 2 | E35: =D35+1 -> 3 | F35: =E35+1 -> 4 | G35: =F35+1 -> 5 | H35: =G35+1 -> 6 | I35: =H35+1 -> 7 | J35: =I35+1 -> 8 | K35: =J35+1 -> 9 | ... AJ35: =AI35+1 -> 34 | AK35: 35
A36: 1 | B36: INVESTIMENTOS
A37: 1.1 | B37: Supressão vegetal | C37: ='Custos Diversos'!E165 -> 646.83682
A38: 1.2 | B38: Sistema de irrigação localizada
A39: 1.3 | B39: Sistema de irrigação pivô central | C39: ='Rentabilidade-Cult.Temp.'!G42 -> 9250
A40: 1.4 | B40: Demais infraestrutura | C40: ='Rentabilidade-Cult.Temp.'!G45-'Rentabilidade-Cult.Temp.'!G42 -> 1598.75
B41: Sub-total - Investimentos | C41: =SUM(C37:C40) -> 11495.587
A43: 2 | B43: CUSTOS OPERACIONAIS
A44: 2.1 | B44: Gasto com insumos | C44: ='Rentabilidade-Cult.Temp.'!G19 -> 3587.5 | D44: =C44 -> 3587.5 | E44: =D44 -> 3587.5 | F44: =E44 -> 3587.5 | G44: =F44 -> 3587.5 | H44: =G44 -> 3587.5 | I44: =H44 -> 3587.5 | J44: =I44 -> 3587.5 | K44: =J44 -> 3587.5 | ... AK44: =AJ44 -> 3587.5
A45: 2.2 | B45: Gasto com mão de obra | C45: ='Rentabilidade-Cult.Temp.'!G26 -> 683.7 | D45: =C45 -> 683.7 | E45: =D45 -> 683.7 | F45: =E45 -> 683.7 | G45: =F45 -> 683.7 | H45: =G45 -> 683.7 | I45: =H45 -> 683.7 | J45: =I45 -> 683.7 | K45: =J45 -> 683.7 | ... AK45: =AJ45 -> 683.7
A46: 2.3 | B46: Gasto com trator e equipamentos e avaição agrícola | C46: ='Rentabilidade-Cult.Temp.'!G38 -> 1410 | D46: =C46 -> 1410 | E46: =D46 -> 1410 | F46: =E46 -> 1410 | G46: =F46 -> 1410 | H46: =G46 -> 1410 | I46: =H46 -> 1410 | J46: =I46 -> 1410 | K46: =J46 -> 1410 | ... AK46: =AJ46 -> 1410
A47: 2.4 | B47: Outros custos | C47: =SUM('Rentabilidade-Cult.Temp.'!G50:G58) -> 1339.6989 | D47: =C47 -> 1339.6989 | E47: =D47 -> 1339.6989 | F47: =E47 -> 1339.6989 | G47: =F47 -> 1339.6989 | H47: =G47 -> 1339.6989 | I47: =H47 -> 1339.6989 | J47: =I47 -> 1339.6989 | K47: =J47 -> 1339.6989 | ... AK47: =AJ47 -> 1339.6989
B48: Sub-total - custos operacionais | C48: =SUM(C44:C47) -> 7020.8989 | D48: =SUM(D44:D47) -> 7020.8989 | E48: =SUM(E44:E47) -> 7020.8989 | F48: =SUM(F44:F47) -> 7020.8989 | G48: =SUM(G44:G47) -> 7020.8989 | H48: =SUM(H44:H47) -> 7020.8989 | I48: =SUM(I44:I47) -> 7020.8989 | J48: =SUM(J44:J47) -> 7020.8989 | ... AK48: =SUM(AK44:AK47) -> 7020.8989
...

Sheet Custo diversos Manga.Limão
A1: CUSTO DIVERSOS LIMÃO E MANGA
A4: custo mao de obra
A7: salario
A8: premiaçao media
A10: encargos
A11: TOTAL-1
A12: EPI
A13: Uniforme
A14: Total
A15: custo dh
A16: Alimentação
A17: Custo total dh
... A55: total
H84: =15*30/50 -> 9

Sheet Custo diversos - Cult.anuais
A1: CUSTO DIVERSOS culturas anuais
A4: custo mao de obra
A7: salario
A8: premiaçao media
A10: encargos
A11: TOTAL-1
A12: EPI
A13: Unifrome
A14: Total
A15: custo dh
A16: Alimentação
A17: Custo total dh
... A43: total

Sheet Custo diversos - Cana
A1: CUSTO DIVERSOS cana
A4: custo mao de obra
A7: salario
A8: premiaçao media
A10: encargos
A11: TOTAL-1
A12: EPI
A13: Unifrome
A14: Total
A15: custo dh
A16: Alimentação
A17: Custo total dh
... A43: total

Sheet Custo sup vegetal-Alimentação
A12: custo mao de obra apoio supressão vegetal
F14: Custo alimentação
A15: salario | F15: Salário mínimo
A16: premiaçao media
F17: encargos
A20: encargos
A21: TOTAL-1
A22: EPI | F22: cozinheira salário + gratificação + encargos
A23: Unifrome | F23: cantina
A24: Total | F24: fogao,etc
A25: custo dh | F25: total
A26: Alimentação | F26: custo dia | I26: adotar
A27: Custo total dh
A28: Adotado

Sheet Rentabilidade ->

Sheet Rentabilidade-Cult.Perma.
A2: RENTABILIDADE - Culturas Permanentes
A4: Banana Nanica
A5: GASTO COM INSUMOS
A6: Descrição | B6: Unidade | C6: Custo Unit. | D6: Quantidade por ha | AN6: Custo por ano - R$
D7: 1 | E7: 2 | F7: 3 | G7: 4 | H7: 5 | I7: 6 | J7: 7 | K7: 8 | L7: 9 | M7: 10 | N7: 11 | O7: 12 | P7: 13 | Q7: 14 | R7: 15 | S7: 16 | T7: 17 | U7: 18 | V7: 19 | W7: 20 | X7: 21 | Y7: 22 | Z7: 23 | AA7: 24 | AB7: 25 | AC7: 26 | AD7: 27 | AE7: 28 | AF7: 29 | AG7: 30 | AH7: 31 | AI7: 32 | AJ7: 33 | AK7: 34 | AL7: 35 | AN7: 1 | AO7: 2 | AP7: 3 | AQ7: 4 | AR7: 5 | AS7: 6 | AT7: 7 | AU7: 8 | AV7: 9 | AW7: 10 | AX7: 11 | AY7: 12 | AZ7: 13 | BA7: 14 | BB7: 15 | BC7: 16 | BD7: 17 | BE7: 18 | BF7: 19 | BG7: 20 | BH7: 21 | BI7: 22 | BJ7: 23 | BK7: 24 | BL7: 25 | BM7: 26 | BN7: 27 | BO7: 28 | BP7: 29 | BQ7: 30 | BR7: 31 | BS7: 32 | BT7: 33 | BU7: 34 | BV7: 35
A8: ='Quantidade-Cult.Perma.'!A12 -> Ácido Bórico | B8: ='Quantidade-Cult.Perma.'!B12 -> KG | C8: ='Quantidade-Cult.Perma.'!D12 -> 7.5 | D8: ='Quantidade-Cult.Perma.'!R12 -> 133.3 | E8: ='Quantidade-Cult.Perma.'!S12 -> 159.96 | F8: ='Quantidade-Cult.Perma.'!T12 -> 159.96 | G8: ='Quantidade-Cult.Perma.'!U12 -> 159.96 | H8: ='Quantidade-Cult.Perma.'!V12 -> 159.96 | I8: ='Quantidade-Cult.Perma.'!W12 -> 159.96 | J8: ='Quantidade-Cult.Perma.'!X12 -> 159.96 | K8: ='Quantidade-Cult.Perma.'!Y12 -> 159.96 | ... O8: ='Quantidade-Cult.Perma.'!AC12 -> 159.96 | P8: =D8 -> 133.3 | Q8: =E8 -> 159.96 | R8: =F8 -> 159.96 | S8: =G8 -> 159.96 | T8: =H8 -> 159.96 | U8: =I8 -> 159.96 | V8: =J8 -> 159.96 | W8: =K8 -> 159.96 | ... AA8: =O8 -> 159.96 | AB8: =D8 -> 133.3 | AC8: =E8 -> 159.96 | AD8: =F8 -> 159.96 | AE8: =G8 -> 159.96 | AF8: =H8 -> 159.96 | AG8: =I8 -> 159.96 | AH8: =J8 -> 159.96 | AI8: =K8 -> 159.96 | ... AL8: =N8 -> 159.96 | AN8: =$C$8*D8 -> 999.75 | AO8: =$C$8*E8 -> 1199.7 | AP8: =$C$8*F8 -> 1199.7 | AQ8: =$C$8*G8 -> 1199.7 | AR8: =$C$8*H8 -> 1199.7 | AS8: =$C$8*I8 -> 1199.7 | AT8: =$C$8*J8 -> 1199.7 | AU8: =$C$8*K8 -> 1199.7 | ... BV8: =$C$8*AL8 -> 1199.7
A9: ='Quantidade-Cult.Perma.'!A13 -> Calcário | B9: ='Quantidade-Cult.Perma.'!B13 -> T | C9: ='Quantidade-Cult.Perma.'!D13 -> 450 | D9: ='Quantidade-Cult.Perma.'!R13 -> 1.3 | E9: ='Quantidade-Cult.Perma.'!S13 -> 1 | F9: ='Quantidade-Cult.Perma.'!T13 -> 1 | G9: ='Quantidade-Cult.Perma.'!U13 -> 1 | H9: ='Quantidade-Cult.Perma.'!V13 -> 1 | I9: ='Quantidade-Cult.Perma.'!W13 -> 1 | J9: ='Quantidade-Cult.Perma.'!X13 -> 1 | K9: ='Quantidade-Cult.Perma.'!Y13 -> 1 | ... O9: ='Quantidade-Cult.Perma.'!AC13 -> 1 | P9: =D9 -> 1.3 | Q9: =E9 -> 1 | R9: =F9 -> 1 | S9: =G9 -> 1 | T9: =H9 -> 1 | U9: =I9 -> 1 | V9: =J9 -> 1 | W9: =K9 -> 1 | ... AA9: =O9 -> 1 | AB9: =D9 -> 1.3 | AC9: =E9 -> 1 | AD9: =F9 -> 1 | AE9: =G9 -> 1 | AF9: =H9 -> 1 | AG9: =I9 -> 1 | AH9: =J9 -> 1 | AI9: =K9 -> 1 | ... AL9: =N9 -> 1 | AN9: =$C$9*D9 -> 585 | AO9: =$C$9*E9 -> 450 | AP9: =$C$9*F9 -> 450 | AQ9: =$C$9*G9 -> 450 | AR9: =$C$9*H9 -> 450 | AS9: =$C$9*I9 -> 450 | AT9: =$C$9*J9 -> 450 | AU9: =$C$9*K9 -> 450 | ... BV9: =$C$9*AL9 -> 450
A10: ='Quantidade-Cult.Perma.'!A14 -> Fosfatado | B10: ='Quantidade-Cult.Perma.'!B14 -> T | C10: ='Quantidade-Cult.Perma.'!D14 -> 2650 | D10: ='Quantidade-Cult.Perma.'!R14 -> 1 | E10: ='Quantidade-Cult.Perma.'!S14 -> 1 | F10: ='Quantidade-Cult.Perma.'!T14 -> 1 | G10: ='Quantidade-Cult.Perma.'!U14 -> 1 | H10: ='Quantidade-Cult.Perma.'!V14 -> 1 | I10: ='Quantidade-Cult.Perma.'!W14 -> 1 | J10: ='Quantidade-Cult.Perma.'!X14 -> 1 | K10: ='Quantidade-Cult.Perma.'!Y14 -> 1 | ... O10: ='Quantidade-Cult.Perma.'!AC14 -> 1 | P10: =D10 -> 1 | Q10: =E10 -> 1 | R10: =F10 -> 1 | S10: =G10 -> 1 | T10: =H10 -> 1 | U10: =I10 -> 1 | V10: =J10 -> 1 | W10: =K10 -> 1 | ... AA10: =O10 -> 1 | AB10: =D10 -> 1 | AC10: =E10 -> 1 | AD10: =F10 -> 1 | AE10: =G10 -> 1 | AF10: =H10 -> 1 | AG10: =I10 -> 1 | AH10: =J10 -> 1 | AI10: =K10 -> 1 | ... AL10: =N10 -> 1 | AN10: =$C$10*D10 -> 2650 | AO10: =$C$10*E10 -> 2650 | AP10: =$C$10*F10 -> 2650 | AQ10: =$C$10*G10 -> 2650 | AR10: =$C$10*H10 -> 2650 | AS10: =$C$10*I10 -> 2650 | AT10: =$C$10*J10 -> 2650 | AU10: =$C$10*K10 -> 2650 | ... BV10: =$C$10*AL10 -> 2650
A11: ='Quantidade-Cult.Perma.'!A15 -> Foliar Completo | B11: ='Quantidade-Cult.Perma.'!B15 -> L | C11: ='Quantidade-Cult.Perma.'!D15 -> 25 | D11: ='Quantidade-Cult.Perma.'!R15 -> 2 | E11: ='Quantidade-Cult.Perma.'!S15 -> 4 | F11: ='Quantidade-Cult.Perma.'!T15 -> 4 | G11: ='Quantidade-Cult.Perma.'!U15 -> 4 | H11: ='Quantidade-Cult.Perma.'!V15 -> 4 | I11: ='Quantidade-Cult.Perma.'!W15 -> 4 | J11: ='Quantidade-Cult.Perma.'!X15 -> 4 | K11: ='Quantidade-Cult.Perma.'!Y15 -> 4 | ... O11: ='Quantidade-Cult.Perma.'!AC15 -> 4 | P11: =D11 -> 2 | Q11: =E11 -> 4 | R11: =F11 -> 4 | S11: =G11 -> 4 | T11: =H11 -> 4 | U11: =I11 -> 4 | V11: =J11 -> 4 | W11: =K11 -> 4 | ... AA11: =O11 -> 4 | AB11: =D11 -> 2 | AC11: =E11 -> 4 | AD11: =F11 -> 4 | AE11: =G11 -> 4 | AF11: =H11 -> 4 | AG11: =I11 -> 4 | AH11: =J11 -> 4 | AI11: =K11 -> 4 | ... AL11: =N11 -> 4 | AN11: =$C$11*D11 -> 50 | AO11: =$C$11*E11 -> 100 | AP11: =$C$11*F11 -> 100 | AQ11: =$C$11*G11 -> 100 | AR11: =$C$11*H11 -> 100 | AS11: =$C$11*I11 -> 100 | AT11: =$C$11*J11 -> 100 | AU11: =$C$11*K11 -> 100 | ... BV11: =$C$11*AL11 -> 100
A12: ='Quantidade-Cult.Perma.'!A16 -> KCL | B12: ='Quantidade-Cult.Perma.'!B16 -> T | C12: ='Quantidade-Cult.Perma.'!D16 -> 2700 | D12: ='Quantidade-Cult.Perma.'!R16 -> 1.70624 | E12: ='Quantidade-Cult.Perma.'!S16 -> 2.23944 | F12: ='Quantidade-Cult.Perma.'!T16 -> 2.23944 | G12: ='Quantidade-Cult.Perma.'!U16 -> 2.23944 | H12: ='Quantidade-Cult.Perma.'!V16 -> 1.91952 | I12: ='Quantidade-Cult.Perma.'!W16 -> 1.91952 | J12: ='Quantidade-Cult.Perma.'!X16 -> 1.91952 | K12: ='Quantidade-Cult.Perma.'!Y16 -> 1.91952 | ... O12: ='Quantidade-Cult.Perma.'!AC16 -> 1.91952 | P12: =D12 -> 1.70624 | Q12: =E12 -> 2.23944 | R12: =F12 -> 2.23944 | S12: =G12 -> 2.23944 | T12: =H12 -> 1.91952 | U12: =I12 -> 1.91952 | V12: =J12 -> 1.91952 | W12: =K12 -> 1.91952 | ... AA12: =O12 -> 1.91952 | AB12: =D12 -> 1.70624 | AC12: =E12 -> 2.23944 | AD12: =F12 -> 2.23944 | AE12: =G12 -> 2.23944 | AF12: =H12 -> 1.91952 | AG12: =I12 -> 1.91952 | AH12: =J12 -> 1.91952 | AI12: =K12 -> 1.91952 | ... AL12: =N12 -> 1.91952 | AN12: =$C$12*D12 -> 4606.848 | AO12: =$C$12*E12 -> 6046.488 | AP12: =$C$12*F12 -> 6046.488 | AQ12: =$C$12*G12 -> 6046.488 | AR12: =$C$12*H12 -> 5182.704 | AS12: =$C$12*I12 -> 5182.704 | AT12: =$C$12*J12 -> 5182.704 | AU12: =$C$12*K12 -> 5182.704 | ... BV12: =$C$12*AL12 -> 5182.704
A13: ='Quantidade-Cult.Perma.'!A17 -> Sulfato de Magnésio | B13: ='Quantidade-Cult.Perma.'!B17 -> KG | C13: ='Quantidade-Cult.Perma.'!D17 -> 1.5 | D13: ='Quantidade-Cult.Perma.'!R17 -> 266.6 | E13: ='Quantidade-Cult.Perma.'!S17 -> 319.92 | F13: ='Quantidade-Cult.Perma.'!T17 -> 319.92 | G13: ='Quantidade-Cult.Perma.'!U17 -> 319.92 | H13: ='Quantidade-Cult.Perma.'!V17 -> 319.92 | I13: ='Quantidade-Cult.Perma.'!W17 -> 319.92 | J13: ='Quantidade-Cult.Perma.'!X17 -> 319.92 | K13: ='Quantidade-Cult.Perma.'!Y17 -> 319.92 | ... O13: ='Quantidade-Cult.Perma.'!AC17 -> 319.92 | P13: =D13 -> 266.6 | Q13: =E13 -> 319.92 | R13: =F13 -> 319.92 | S13: =G13 -> 319.92 | T13: =H13 -> 319.92 | U13: =I13 -> 319.92 | V13: =J13 -> 319.92 | W13: =K13 -> 319.92 | ... AA13: =O13 -> 319.92 | AB13: =D13 -> 266.6 | AC13: =E13 -> 319.92 | AD13: =F13 -> 319.92 | AE13: =G13 -> 319.92 | AF13: =H13 -> 319.92 | AG13: =I13 -> 319.92 | AH13: =J13 -> 319.92 | AI13: =K13 -> 319.92 | ... AL13: =N13 -> 319.92 | AN13: =$C$13*D13 -> 399.9 | AO13: =$C$13*E13 -> 479.88 | AP13: =$C$13*F13 -> 479.88 | AQ13: =$C$13*G13 -> 479.88 | AR13: =$C$13*H13 -> 479.88 | AS13: =$C$13*I13 -> 479.88 | AT13: =$C$13*J13 -> 479.88 | AU13: =$C$13*K13 -> 479.88 | ... BV13: =$C$13*AL13 -> 479.88
A14: ='Quantidade-Cult.Perma.'!A18 -> Sulfato de Zinco | B14: ='Quantidade-Cult.Perma.'!B18 -> KG | C14: ='Quantidade-Cult.Perma.'!D18 -> 6 | D14: ='Quantidade-Cult.Perma.'!R18 -> 133.3 | E14: ='Quantidade-Cult.Perma.'!S18 -> 159.96 | F14: ='Quantidade-Cult.Perma.'!T18 -> 159.96 | G14: ='Quantidade-Cult.Perma.'!U18 -> 159.96 | H14: ='Quantidade-Cult.Perma.'!V18 -> 159.96 | I14: ='Quantidade-Cult.Perma.'!W18 -> 159.96 | J14: ='Quantidade-Cult.Perma.'!X18 -> 159.96 | K14: ='Quantidade-Cult.Perma.'!Y18 -> 159.96 | ... O14: ='Quantidade-Cult.Perma.'!AC18 -> 159.96 | P14: =D14 -> 133.3 | Q14: =E14 -> 159.96 | R14: =F14 -> 159.96 | S14: =G14 -> 159.96 | T14: =H14 -> 159.96 | U14: =I14 -> 159.96 | V14: =J14 -> 159.96 | W14: =K14 -> 159.96 | ... AA14: =O14 -> 159.96 | AB14: =D14 -> 133.3 | AC14: =E14 -> 159.96 | AD14: =F14 -> 159.96 | AE14: =G14 -> 159.96 | AF14: =H14 -> 159.96 | AG14: =I14 -> 159.96 | AH14: =J14 -> 159.96 | AI14: =K14 -> 159.96 | ... AL14: =N14 -> 159.96 | AN14: =$C$14*D14 -> 799.8 | AO14: =$C$14*E14 -> 959.76 | AP14: =$C$14*F14 -> 959.76 | AQ14: =$C$14*G14 -> 959.76 | AR14: =$C$14*H14 -> 959.76 | AS14: =$C$14*I14 -> 959.76 | AT14: =$C$14*J14 -> 959.76 | AU14: =$C$14*K14 -> 959.76 | ... BV14: =$C$14*AL14 -> 959.76
A15: ='Quantidade-Cult.Perma.'!A19 -> Esterco de Gado | B15: ='Quantidade-Cult.Perma.'!B19 -> M3 | C15: ='Quantidade-Cult.Perma.'!D19 -> 80 | D15: ='Quantidade-Cult.Perma.'!R19 -> 53.32 | E15: ='Quantidade-Cult.Perma.'!S19 -> 0 | F15: ='Quantidade-Cult.Perma.'!T19 -> 0 | G15: ='Quantidade-Cult.Perma.'!U19 -> 0 | H15: ='Quantidade-Cult.Perma.'!V19 -> 0 | I15: ='Quantidade-Cult.Perma.'!W19 -> 0 | J15: ='Quantidade-Cult.Perma.'!X19 -> 0 | K15: ='Quantidade-Cult.Perma.'!Y19 -> 0 | ... O15: ='Quantidade-Cult.Perma.'!AC19 -> 0 | P15: =D15 -> 53.32 | Q15: =E15 -> 0 | R15: =F15 -> 0 | S15: =G15 -> 0 | T15: =H15 -> 0 | U15: =I15 -> 0 | V15: =J15 -> 0 | W15: =K15 -> 0 | ... AA15: =O15 -> 0 | AB15: =D15 -> 53.32 | AC15: =E15 -> 0 | AD15: =F15 -> 0 | AE15: =G15 -> 0 | AF15: =H15 -> 0 | AG15: =I15 -> 0 | AH15: =J15 -> 0 | AI15: =K15 -> 0 | ... AL15: =N15 -> 0 | AN15: =$C$15*D15 -> 4265.6 | AO15: =$C$15*E15 -> 0 | AP15: =$C$15*F15 -> 0 | AQ15: =$C$15*G15 -> 0 | AR15: =$C$15*H15 -> 0 | AS15: =$C$15*I15 -> 0 | AT15: =$C$15*J15 -> 0 | AU15: =$C$15*K15 -> 0 | ... BV15: =$C$15*AL15 -> 0
A16: ='Quantidade-Cult.Perma.'!A20 -> Nitrato de Amonia | B16: ='Quantidade-Cult.Perma.'!B20 -> T | C16: ='Quantidade-Cult.Perma.'!D20 -> 2200 | D16: ='Quantidade-Cult.Perma.'!R20 -> 1.364992 | E16: ='Quantidade-Cult.Perma.'!S20 -> 1.791552 | F16: ='Quantidade-Cult.Perma.'!T20 -> 1.791552 | G16: ='Quantidade-Cult.Perma.'!U20 -> 1.791552 | H16: ='Quantidade-Cult.Perma.'!V20 -> 1.535616 | I16: ='Quantidade-Cult.Perma.'!W20 -> 1.535616 | J16: ='Quantidade-Cult.Perma.'!X20 -> 1.535616 | K16: ='Quantidade-Cult.Perma.'!Y20 -> 1.535616 | ... O16: ='Quantidade-Cult.Perma.'!AC20 -> 1.535616 | P16: =D16 -> 1.364992 | Q16: =E16 -> 1.791552 | R16: =F16 -> 1.791552 | S16: =G16 -> 1.791552 | T16: =H16 -> 1.535616 | U16: =I16 -> 1.535616 | V16: =J16 -> 1.535616 | W16: =K16 -> 1.535616 | ... AA16: =O16 -> 1.535616 | AB16: =D16 -> 1.364992 | AC16: =E16 -> 1.791552 | AD16: =F16 -> 1.791552 | AE16: =G16 -> 1.791552 | AF16: =H16 -> 1.535616 | AG16: =I16 -> 1.535616 | AH16: =J16 -> 1.535616 | AI16: =K16 -> 1.535616 | ... AL16: =N16 -> 1.535616 | AN16: =$C$16*D16 -> 3002.9824 | AO16: =$C$16*E16 -> 3941.4144 | AP16: =$C$16*F16 -> 3941.4144 | AQ16: =$C$16*G16 -> 3941.4144 | AR16: =$C$16*H16 -> 3378.3552 | AS16: =$C$16*I16 -> 3378.3552 | AT16: =$C$16*J16 -> 3378.3552 | AU16: =$C$16*K16 -> 3378.3552 | ... BV16: =$C$16*AL16 -> 3378.3552
A17: ='Quantidade-Cult.Perma.'!A21 -> Fungicida | B17: ='Quantidade-Cult.Perma.'!B21 -> L | C17: ='Quantidade-Cult.Perma.'!D21 -> 75 | D17: ='Quantidade-Cult.Perma.'!R21 -> 0.5 | E17: ='Quantidade-Cult.Perma.'!S21 -> 2.5 | F17: ='Quantidade-Cult.Perma.'!T21 -> 2.5 | G17: ='Quantidade-Cult.Perma.'!U21 -> 2.5 | H17: ='Quantidade-Cult.Perma.'!V21 -> 2.5 | I17: ='Quantidade-Cult.Perma.'!W21 -> 2.5 | J17: ='Quantidade-Cult.Perma.'!X21 -> 2.5 | K17: ='Quantidade-Cult.Perma.'!Y21 -> 2.5 | ... O17: ='Quantidade-Cult.Perma.'!AC21 -> 2.5 | P17: =D17 -> 0.5 | Q17: =E17 -> 2.5 | R17: =F17 -> 2.5 | S17: =G17 -> 2.5 | T17: =H17 -> 2.5 | U17: =I17 -> 2.5 | V17: =J17 -> 2.5 | W17: =K17 -> 2.5 | ... AA17: =O17 -> 2.5 | AB17: =D17 -> 0.5 | AC17: =E17 -> 2.5 | AD17: =F17 -> 2.5 | AE17: =G17 -> 2.5 | AF17: =H17 -> 2.5 | AG17: =I17 -> 2.5 | AH17: =J17 -> 2.5 | AI17: =K17 -> 2.5 | ... AL17: =N17 -> 2.5 | AN17: =$C$17*D17 -> 37.5 | AO17: =$C$17*E17 -> 187.5 | AP17: =$C$17*F17 -> 187.5 | AQ17: =$C$17*G17 -> 187.5 | AR17: =$C$17*H17 -> 187.5 | AS17: =$C$17*I17 -> 187.5 | AT17: =$C$17*J17 -> 187.5 | AU17: =$C$17*K17 -> 187.5 | ... BV17: =$C$17*AL17 -> 187.5
