Workbook

Sheet base
A1: Nº PROPRIE- DADE | B1: ÁREA PROPRIEDADE (ha) | C1: PASTO (ha) | D1: VEGETAÇÃO NATIVA (ha) | E1: % EXPLORAÇÃO | G1: PIVÔ (ha) | H1: Possui PIVÔ (ha) | I1: IRRIGAÇÃO LOCALIZADA (ha) | J1: Possui IRRIGAÇÃO LOCALIZADA (ha) | K1: CULTURA EXPLORADA | L1: PAINEL SOLAR (m²) | M1: Possui PAINEL SOLAR (m²) | N1: BENFEITORIAS | O1: RECURSOS HÍDRICOS | P1: ENERGIA
E2: PASTO | F2: VEG.NAT.
A3: 1 | B3: 1206.7749 | C3: 572.96761 | D3: 633.80734 | E3: =C3/B3 -> 0.47479243 | F3: =D3/B3 -> 0.52520757 | N3: Casa Alvenaria; Curral; Bebedouro; Viveiro de Mudas; | P3: X
A4: 2 | B4: 3666.8488 | C4: 2600.6799 | D4: 1066.1689 | E4: =C4/B4 -> 0.70924111 | F4: =D4/B4 -> 0.29075889 | L4: 511.7231 | M4: X | N4: Estrutura Diversa; Casa Alvenaria; Estrutura Metálica; Reservatório; | O4: X | P4: X
A5: 3 | B5: 12.146215 | C5: 12.054604 | D5: 0.09161116 | E5: =C5/B5 -> 0.99245764 | F5: =D5/B5 -> 0.0075423626 | P5: X
A6: 4 | B6: 15.914785 | C6: 15.914785 | E6: =C6/B6 -> 1 | F6: =D6/B6 -> 0 | P6: X
A7: 5 | B7: 93.414859 | C7: 82.127624 | D7: 11.287235 | E7: =C7/B7 -> 0.87917088 | F7: =D7/B7 -> 0.12082912 | N7: Bebedouro; | P7: X
A8: 6 | B8: 108.07807 | C8: 22.476286 | D8: 81.009443 | E8: =C8/B8 -> 0.20796343 | F8: =D8/B8 -> 0.74954562 | I8: 4.59234 | J8: X | K8: Banana | N8: Estrutura Diversa; Casa Alvenaria; Estrutura Metálica; Reservatório; | O8: X | P8: X
A9: 7 | B9: 53.319423 | C9: 17.032642 | D9: 36.286781 | E9: =C9/B9 -> 0.31944536 | F9: =D9/B9 -> 0.68055464 | P9: X
A10: 8 | B10: 30.146132 | C10: 9.3378293 | D10: 20.808303 | E10: =C10/B10 -> 0.30975215 | F10: =D10/B10 -> 0.69024785 | P10: X
A11: 9 | B11: 223.79593 | C11: 204.09329 | D11: 19.702639 | E11: =C11/B11 -> 0.91196159 | F11: =D11/B11 -> 0.088038414 | N11: Estrutura Diversa; Casa Alvenaria; Estrutura de Concreto; Reservatório; Curral; | O11: X | P11: X
A12: 10 | B12: 20.086431 | C12: 16.377264 | D12: 2.8160724 | E12: =C12/B12 -> 0.81533965 | F12: =D12/B12 -> 0.14019775 | I12: 0.89309493 | J12: X | K12: Limão | P12: X
A13: 11 | B13: 31.177793 | C13: 7.1158069 | D13: 24.061986 | E13: =C13/B13 -> 0.22823318 | F13: =D13/B13 -> 0.77176682 | N13: Estrutura Diversa; Casa Alvenaria; Reservatório; | O13: X | P13: X
A14: 12 | B14: 30.077264 | C14: 7.2797137 | D14: 22.797551 | E14: =C14/B14 -> 0.24203377 | F14: =D14/B14 -> 0.75796623 | N14: Estrutura Diversa; Casa Alvenaria; Reservatório; | O14: X | P14: X
A15: 13 | B15: 49.176021 | C15: 9.1121382 | D15: 40.063883 | E15: =C15/B15 -> 0.18529637 | F15: =D15/B15 -> 0.81470363 | N15: Estrutura Diversa; Casa Alvenaria; Reservatório; | O15: X | P15: X
A16: 14 | B16: 28.103318 | D16: 28.103318 | E16: =C16/B16 -> 0 | F16: =D16/B16 -> 1 | P16: X
A17: 15 | B17: 31.473609 | C17: 1.7939745 | D17: 26.481062 | E17: =C17/B17 -> 0.056999324 | F17: =D17/B17 -> 0.84137352 | I17: 3.1985733 | J17: X | K17: Limão | N17: Estrutura Diversa; Casa Alvenaria; Reservatório; | O17: X | P17: X
A18: 16 | B18: 29.811365 | C18: 3.3303031 | D18: 26.481062 | E18: =C18/B18 -> 0.11171253 | F18: =D18/B18 -> 0.88828747 | N18: Casa Alvenaria; Bebedouro; | P18: X
A19: 17 | B19: 29.640944 | C19: 9.8787929 | D19: 12.515501 | E19: =C19/B19 -> 0.33328199 | F19: =D19/B19 -> 0.42223693 | G19: 2.2801 | H19: X | I19: 4.9665502 | J19: X | K19: Ciclo Anual | N19: Estrutura Diversa; Casa Alvenaria; Reservatório; | O19: X | P19: X
A20: 18 | B20: 8.0706058 | C20: 3.7902881 | D20: 4.2803176 | E20: =C20/B20 -> 0.46964109 | F20: =D20/B20 -> 0.53035891 | P20: X
A21: 19* | B21: 97.47998 | C21: 69.9936 | D21: 3.4863802 | E21: =C21/B21 -> 0.71803051 | F21: =D21/B21 -> 0.035765089 | G21: 20 | H21: X | I21: 4 | J21: X | K21: Banana | N21: Estrutura Diversa; Casa Alvenaria; Reservatório; | O21: X | P21: X | Q21: **Obs.: A Propriedade 19 possui áreas com CAR e áreas sem CAR.
A22: 20 | B22: 43.60409 | D22: 43.60409 | E22: =C22/B22 -> 0 | F22: =D22/B22 -> 1 | P22: X
A23: 21 | B23: 38.616421 | C23: 9.4852664 | D23: 29.131154 | E23: =C23/B23 -> 0.2456278 | F23: =D23/B23 -> 0.7543722 | N23: Estrutura Diversa; Casa Alvenaria; | P23: X
A24: 22 | B24: 33.659597 | C24: 9.4253462 | D24: 24.234251 | E24: =C24/B24 -> 0.28001958 | F24: =D24/B24 -> 0.71998042 | N24: Estrutura Diversa; Casa Alvenaria; | P24: X
A25: 23 | B25: 148.72492 | C25: 5.343799 | D25: 143.38112 | E25: =C25/B25 -> 0.035930758 | F25: =D25/B25 -> 0.96406924 | N25: Estrutura Diversa; Casa Alvenaria; | P25: X
A26: 24 | B26: 146.2572 | C26: 129.50176 | D26: 16.755433 | E26: =C26/B26 -> 0.88543857 | F26: =D26/B26 -> 0.11456143 | N26: Estrutura Diversa; Casa Alvenaria; | P26: X
A27: 25 | B27: 45.43599 | C27: 28.228487 | D27: 17.207503 | E27: =C27/B27 -> 0.62128033 | F27: =D27/B27 -> 0.37871967 | P27: X
A28: 26 | B28: 693.41037 | C28: 283.40072 | D28: 390.80334 | E28: =C28/B28 -> 0.40870563 | F28: =D28/B28 -> 0.56359604 | I28: 19.206314 | J28: X | K28: Limão | N28: Casa Alvenaria; Reservatório; | O28: X | P28: X
A29: 27 | B29: 81.972571 | D29: 81.972571 | E29: =C29/B29 -> 0 | F29: =D29/B29 -> 1 | N29: Casa Alvenaria; Reservatório; | O29: X | P29: X
A30: 28 | B30: 244.45631 | C30: 5.9094185 | D30: 238.54689 | E30: =C30/B30 -> 0.024173721 | F30: =D30/B30 -> 0.97582628 | P30: X
A31: 29 | B31: 40.615095 | C31: 40.615095 | E31: =C31/B31 -> 1 | F31: =D31/B31 -> 0 | N31: Casa Alvenaria; Curral; | P31: X
A32: 30 | B32: 40.576268 | C32: 18.468836 | D32: 22.107432 | E32: =C32/B32 -> 0.4551635 | F32: =D32/B32 -> 0.5448365 | N32: Casa Alvenaria; | P32: X
A33: 31 | B33: 82.712954 | C33: 22.779882 | D33: 59.933072 | E33: =C33/B33 -> 0.27540888 | F33: =D33/B33 -> 0.72459112 | P33: X
A34: 32 | B34: 44.620108 | C34: 26.202262 | D34: 18.417846 | E34: =C34/B34 -> 0.58722991 | F34: =D34/B34 -> 0.41277009 | N34: Casa Alvenaria; | P34: X
A35: 33 | B35: 80.644455 | C35: 6.4966872 | D35: 74.147768 | E35: =C35/B35 -> 0.080559626 | F35: =D35/B35 -> 0.91944037 | N35: Casa Alvenaria; Reservatório; | O35: X | P35: X
A36: 34 | B36: 1369.7731 | C36: 1222.9325 | D36: 146.84067 | E36: =C36/B36 -> 0.89279928 | F36: =D36/B36 -> 0.10720072 | N36: Estrutura Diversa; Casa Alvenaria; Estrutura de Concreto; Bebedouro; | P36: X
A37: 35 | B37: 26.870599 | C37: 21.349982 | D37: 5.5206169 | E37: =C37/B37 -> 0.79454805 | F37: =D37/B37 -> 0.20545195 | P37: X
A38: 36 | B38: 26.870026 | C38: 21.096398 | D38: 5.7736282 | E38: =C38/B38 -> 0.78512755 | F38: =D38/B38 -> 0.21487245 | N38: Casa Alvenaria; Estrutura Metálica; Reservatório; | O38: X | P38: X
A39: 37 | B39: 0.50077895 | C39: 0.50077895 | E39: =C39/B39 -> 1 | F39: =D39/B39 -> 0 | P39: X
A40: 38 | B40: 3.9824501 | C40: 0.53543386 | D40: 3.4470163 | E40: =C40/B40 -> 0.13444835 | F40: =D40/B40 -> 0.86555165 | P40: X
...

Sheet Lista de Abas
A1: LISTA DE ABAS
A2: Capa | B2: Identificação do documento.
A3: Cálculo Depre.-Sist. Irrig. | B3: Memória de cálculo do valor avaliado dos sistemas de irrigação baseado na depreciação.
A4: Estimativa Valores-Painéis Sol. | B4: Base da estimativa dos valores dos painéis solares.
A5: Cálculo Valor Avaliação-Cultura | B5: Memória de cálculo do valor de avaliação das culturas de Banana, Limão e Manga.
A6: Cálculo Geral de Propriedades | B6: Planilha geral do cálculo dos valores por propriedade.
A7: Valores Est. por Propriedade | B7: Planilha resumo dos valores estimados das propriedades geral.
A8: Valores Est. por Prop. ET.3e4 | B8: Planilha resumo dos valores estimados das propriedades nas Etapas 3 e 4.

Sheet Capa
B8: Fundo de Desenvolvimento da Infraestrutura Sustentável – FDIRS
B14: Serviços Técnicos relativos à Estruturação e o Desenvolvimento de Concessão do Perímetro Irrigado do Jaíba (Etapas III e IV) da Companhia de Desenvolvimento dos Vales do São Francisco e do Parnaíba - CODEVASF
B19: CONTRATO: 01/2025
B25: RELATÓRIO TÉCNICO-AVALIAÇÃO FUNDIÁRIA
B31: MEMÓRIA DE CÁLCULO DO VALOR DE CADA PROPRIEDADE
K45: 46204
A51: CONSÓRCIO Nova Irrigação Jaíba/MG
A63: JB_E3-4.05.TOP.PL.002_R1-Mem. Cálculo vl propriedades

Sheet Cálculo Depre.-Sist. Irrig.
E2: DISCRIMINAÇÃO | F2: IDADE APARENTE | G2: VIDA ÚTIL - ANOS | H2: C.M. | I2: C.T. | J2: VALOR RESIDUAL (% DO VALOR TOTAL) | K2: VALOR DO BEM USADO / REFORM. (R$) | L2: VALOR DO BEM NOVO (R$) | M2: VALOR DEPREC. (R$) | N2: F.L. (%) | O2: VALOR DEPREC. x FATOR DE LIQUIDEZ (R$) | P2: VALOR AVALIADO UNITÁRIO (R$) | Q2: VALOR AVALIADO UNITÁRIO / VALOR NOVO (%) | R2: VALOR AVALIADO TOTAL (R$)
E3: sistema de irrigação-Microaspersão | F3: 12 | G3: 25 | H3: 10 | I3: 10 | J3: 0 | L3: =L20 -> 24000 | M3: =((1-J3/100)*1.347961431/(1+0.347961431*EXP(3.579760093*(F3/G3)*0.85308171*EXP(0.067348748*I3-0.041679277*H3-0.00102286*I3*H3)))+J3/100)*L3 -> 11060.23 | N3: 0.7 | O3: =M3*N3 -> 7742.1613 | P3: =+ROUND(O3,-2) -> 7700 | R3: =P3*D3 -> 0
E4: sistema de irrigação- Pivô central | F4: 12 | G4: 25 | H4: 10 | I4: 10 | J4: 0 | L4: =H22 -> 21000 | M4: =((1-J4/100)*1.347961431/(1+0.347961431*EXP(3.579760093*(F4/G4)*0.85308171*EXP(0.067348748*I4-0.041679277*H4-0.00102286*I4*H4)))+J4/100)*L4 -> 9677.7016 | N4: 0.7 | O4: =M4*N4 -> 6774.3911 | P4: =+ROUND(O4,-2) -> 6800 | R4: =P4*D4 -> 0
B6: CÁLCULO DA DEPRECIAÇÃO PELO MÉTODO DE CAIRES
B8: Equação:
B9: VB = ( ( 1 - VR ) x 1,347961431 / ( 1 + 0,347961431 x EXP ( 3,579760093 x ( IA / VU ) x 0,853081710 x EXP ( 0,067348748 x CT - 0,041679277 x CM - 0,001022860 x CT x CM ) ) ) + VR ) x VN
C11: onde: | E11: VB = Valor do bem avaliando, em R$ | G11: Coeficiente de Trabalho | J11: Coeficiente de Manutenção | M11: Fator de Liquidez
E12: VR = Valor residual, em %, do bem avaliando | G12: 0 | H12: Nulo | J12: 0 | K12: Inexistente | M12: 90 | N12: Médio
E13: IA = Idade aparente do bem avaliando, em anos | G13: 5 | H13: Leve | J13: 5 | K13: Sofrível | M13: 80 | N13: Baixo
E14: VU = Vida útil total do bem avaliando, em anos | G14: 10 | H14: Normal | J14: 10 | K14: Normal | M14: 70 | N14: Baixíssimo
E15: CT = Coeficiente de trabalho do bem avaliando | G15: 15 | H15: Pesado | J15: 15 | K15: Rigorosa
E16: CM = Coeficiente de manutenção do bem avaliando | G16: 20 | H16: Extremo | J16: 20 | K16: Perfeita
E17: VN = Valor de similar novo, em R$
B20: Valor médio de um sistema novo de Microaspersão (para atender cultura de limão, manga, banana), para 16 ha (média das pr0priedades) - R$/ha = | L20: 24000
B22: Valor médio de um sistema novo de Pivô central para 28 ha(média das propriedades) - R$/ha = | H22: 21000
B24: Fonte do valor novo sistema de Irrigação - Tecminas -irrigação (038)991138754

Sheet Estimativa Valores-Painéis Sol.
B2: ESTIMATIVA DE VALOR DE m² DE PLACA DE PAINEL SOLAR
B3: Propriedade | C3: Área - m² | D3: Valor da Placa | E3: Valor / m²
B4: 2 | C4: 511.7231 | D4: 72000 | E4: =D4/C4 -> 140.70109
B5: 50 | C5: 112549.37 | D5: 10200000 | E5: =D5/C5 -> 90.626892
B6: 52 | C6: 25.5894 | D6: 6600 | E6: =D6/C6 -> 257.91929
B7: 172 | C7: 330.6577 | D7: 68000 | E7: =D7/C7 -> 205.65074
B8: 194 | C8: 20.602 | D8: 5300 | E8: =D8/C8 -> 257.25658
B9: 263 | C9: 612 | D9: 87000 | E9: =D9/C9 -> 142.15686
B10: 301 | C10: 35 | D10: 9000 | E10: =D10/C10 -> 257.14286
B11: 314 | C11: 2833.6 | D11: 348000 | E11: =D11/C11 -> 122.81197
B12: 324 | C12: 569.6373 | D12: 81000 | E12: =D12/C12 -> 142.19574
B13: 333 | C13: 19.5516 | D13: 7300 | E13: =D13/C13 -> 373.37098
B14: 336 | C14: 175.0993 | D14: 36000 | E14: =D14/C14 -> 205.59762
B15: 339 | C15: 549.3691 | D15: 78000 | E15: =D15/C15 -> 141.98105
... B24: 375 | C24: 12.2172 | D24: 4500 | E24: =D24/C24 -> 368.33317
B26: *OBS: Fonte Painel Solar = PORTAL SOLAR- 31-972132657 - Contato@portalsolar.com.br - Data de Referência- Janeiro/2025 - Valores médios praticados no Brasil.

Sheet Cálculo Valor Avaliação-Cultura
A1: Banana 1/ | G1: Manga 2/ | O1: Limão 3/
A2: GASTO COM INSUMOS | G2: GASTO COM INSUMOS | O2: GASTO COM INSUMOS
A3: Descrição | B3: Unidade | C3: Custo Unit. | D3: Quantidade por ha | E3: Custo por ano - R$ | G3: Descrição | H3: Unidade | I3: Custo Unit. | J3: Quantidade por ha por ano | L3: Custo por ano - R$ | O3: Descrição | P3: Unidade | Q3: Custo Unit. | R3: Quantidade por ha | T3: Custo por ano - R$
D4: 1 | E4: 1 | J4: 1 | K4: 2 | L4: 1 | M4: 2 | R4: 1 | S4: 2 | T4: 1 | U4: 2
A5: Ácido Bórico | B5: KG | C5: 7.5 | D5: 133.3 | E5: =C5*D5 -> 999.75 | G5: Ácido Bórico | H5: KG | I5: 7.5 | J5: 15.52 | K5: 46.56 | L5: =I5*J5 -> 116.4 | M5: =I5*K5 -> 349.2 | O5: Ácido Bórico | P5: KG | Q5: 7.5 | R5: 5.25 | S5: 21 | T5: =$Q5*R5 -> 39.375 | U5: =$Q5*S5 -> 157.5
A6: Calcário | B6: T | C6: 450 | D6: 1.3 | E6: =C6*D6 -> 585 | G6: Calcário | H6: T | I6: 450 | J6: 1 | K6: 1 | L6: =I6*J6 -> 450 | M6: =I6*K6 -> 450 | O6: Calcário | P6: T | Q6: 450 | R6: 1 | S6: 1 | T6: =$Q6*R6 -> 450 | U6: =$Q6*S6 -> 450
A7: Fosfatado | B7: T | C7: 2650 | D7: 1 | E7: =C7*D7 -> 2650 | G7: Fosfatado | H7: T | I7: 2650 | J7: 1 | K7: 1 | L7: =I7*J7 -> 2650 | M7: =I7*K7 -> 2650 | O7: Fosfatado | P7: T | Q7: 2650 | R7: 1 | S7: 1 | T7: =$Q7*R7 -> 2650 | U7: =$Q7*S7 -> 2650
A8: Foliar Completo | B8: L | C8: 25 | D8: 2 | E8: =C8*D8 -> 50 | G8: Foliar Completo | H8: L | I8: 25 | J8: 3 | K8: 12 | L8: =I8*J8 -> 75 | M8: =I8*K8 -> 300 | O8: Foliar Completo | P8: L | Q8: 25 | R8: 3 | S8: 12 | T8: =$Q8*R8 -> 75 | U8: =$Q8*S8 -> 300
A9: KCL | B9: T | C9: 2700 | D9: 1.27968 | E9: =C9*D9 -> 3455.136 | G9: KCL | H9: T | I9: 2700 | J9: 0.194 | K9: 0.27936 | L9: =I9*J9 -> 523.8 | M9: =I9*K9 -> 754.272 | O9: KCL | P9: T | Q9: 2700 | R9: 0.063 | S9: 0.126 | T9: =$Q9*R9 -> 170.1 | U9: =$Q9*S9 -> 340.2
A10: Sulfato de Magnésio | B10: KG | C10: 1.5 | D10: 199.95 | E10: =C10*D10 -> 299.925 | G10: Sulfato de Magnésio | H10: KG | I10: 1.5 | J10: 116.4 | K10: 186.24 | L10: =I10*J10 -> 174.6 | M10: =I10*K10 -> 279.36 | O10: Nitrato de Potássio | P10: KG | Q10: 8.9 | R10: 0 | S10: 0 | T10: =$Q10*R10 -> 0 | U10: =$Q10*S10 -> 0
A11: Sulfato de Zinco | B11: KG | C11: 6 | D11: 99.975 | E11: =C11*D11 -> 599.85 | G11: Sulfato de Zinco | H11: KG | I11: 6 | J11: 77.6 | K11: 93.12 | L11: =I11*J11 -> 465.6 | M11: =I11*K11 -> 558.72 | O11: Sulfato de Magnésio | P11: KG | Q11: 1.5 | R11: 31.5 | S11: 84 | T11: =$Q11*R11 -> 47.25 | U11: =$Q11*S11 -> 126
A12: Esterco de Gado | B12: M3 | C12: 80 | D12: 39.99 | E12: =C12*D12 -> 3199.2 | G12: Esterco de Gado | H12: M3 | I12: 80 | J12: 7.76 | K12: 7.76 | L12: =I12*J12 -> 620.8 | M12: =I12*K12 -> 620.8 | O12: Sulfato de Zinco | P12: KG | Q12: 6 | R12: 10.5 | S12: 42 | T12: =$Q12*R12 -> 63 | U12: =$Q12*S12 -> 252
A13: Nitrato de Amonia | B13: T | C13: 2200 | D13: 1.023744 | E13: =C13*D13 -> 2252.2368 | G13: Nitrato de Amonia | H13: T | I13: 2200 | J13: 0.194 | K13: 0.194 | L13: =I13*J13 -> 426.8 | M13: =I13*K13 -> 426.8 | O13: Esterco de Gado | P13: M3 | Q13: 80 | R13: 7 | S13: 7 | T13: =$Q13*R13 -> 560 | U13: =$Q13*S13 -> 560
A14: Fungicida | B14: L | C14: 85 | D14: 0.5 | E14: =C14*D14 -> 42.5 | G14: Fungicida | H14: L | I14: 85 | J14: 3 | K14: 8 | L14: =I14*J14 -> 255 | M14: =I14*K14 -> 680 | O14: Nitrato de Amonia | P14: T | Q14: 2200 | R14: 0.0105 | S14: 0.063 | T14: =$Q14*R14 -> 23.1 | U14: =$Q14*S14 -> 138.6
A15: Inseticida | B15: L | C15: 40 | D15: 1 | E15: =C15*D15 -> 40 | G15: Inseticida | H15: L | I15: 40 | J15: 3 | K15: 4 | L15: =I15*J15 -> 120 | M15: =I15*K15 -> 160 | O15: Fungicida | P15: L | Q15: 85 | R15: 3 | S15: 12 | T15: =$Q15*R15 -> 255 | U15: =$Q15*S15 -> 1020
A16: Espalhante | B16: L | C16: 15 | D16: 0.25 | E16: =C16*D16 -> 3.75 | G16: Espalhante | H16: L | I16: 15 | J16: 0.36 | K16: 0.4 | L16: =I16*J16 -> 5.4 | M16: =I16*K16 -> 6 | O16: Inseticida | P16: L | Q16: 40 | R16: 6 | S16: 6 | T16: =$Q16*R16 -> 240 | U16: =$Q16*S16 -> 240
... A19: Muda Banana | B19: UD | C19: 4 | D19: 2000 | E19: =C19*D19 -> 8000 | G19: Muda Manga | H19: UD | I19: 21 | J19: 776 | K19: 0 | L19: =I19*J19 -> 16296 | M19: =I19*K19 -> 0 | O19: Óleo Mineral | P19: L | Q19: 10 | R19: 3 | S19: 24 | T19: =$Q19*R19 -> 30 | U19: =$Q19*S19 -> 240
A20: SUB-TOTAL-INSUMOS = | E20: =SUM(E5:E19) -> 22364.848 | G20: SUB-TOTAL-INSUMOS = | L20: =SUM(L5:L19) -> 22379.4 | M20: =SUM(M5:M19) -> 7585.152 | O20: Muda Limao | P20: UD | Q20: 20 | R20: 350 | S20: 0 | T20: =$Q20*R20 -> 7000 | U20: =$Q20*S20 -> 0
O21: SUB-TOTAL-INSUMOS = | T21: =SUM(T5:T20) -> 11778.225 | U21: =SUM(U5:U20) -> 6651.5
A23: GASTO COM MÃO DE OBRA | G23: GASTO COM MÃO DE OBRA | O23: GASTO COM MÃO DE OBRA
A24: Descrição | B24: Unidade | C24: Custo Unit. | D24: Quantidade por ha | E24: Custo por ano - R$ | G24: Descrição | H24: Unidade | I24: Custo Unit. | J24: Quantidade por ha | L24: Custo por ano - R$ | O24: Descrição | P24: Unidade | Q24: Custo Unit. | R24: Quantidade por ha | T24: Custo por ano - R$
D25: 1 | E25: 1 | J25: 1 | K25: 2 | L25: 1 | M25: 2 | R25: 1 | S25: 2 | T25: 1 | U25: 2
A26: Preparao cova | B26: dh | C26: 145 | D26: 15 | E26: =C26*D26 -> 2175 | G26: Preparao cova | H26: dh | I26: 136 | J26: 8 | L26: =I26*J26 -> 1088 | M26: =I26*K26 -> 0 | O26: Preparao cova | P26: dh | Q26: 136 | R26: 8 | T26: =$Q26*R26 -> 1088 | U26: =$Q26*S26 -> 0
A27: plantio | B27: dh | C27: 145 | D27: 12 | E27: =C27*D27 -> 1740 | G27: plantio | H27: dh | I27: 136 | J27: 8 | L27: =I27*J27 -> 1088 | M27: =I27*K27 -> 0 | O27: plantio | P27: dh | Q27: 136 | R27: 8 | T27: =$Q27*R27 -> 1088 | U27: =$Q27*S27 -> 0
A28: ad. Manual | B28: dh | C28: 145 | D28: 8 | E28: =C28*D28 -> 1160 | G28: ad. Manual | H28: dh | I28: 136 | J28: 4 | L28: =I28*J28 -> 544 | M28: =I28*K28 -> 0 | O28: ad. Manual | P28: dh | Q28: 136 | R28: 4 | T28: =$Q28*R28 -> 544 | U28: =$Q28*S28 -> 0
A29: herbicida | B29: dh | C29: 145 | D29: 0.5 | E29: =C29*D29 -> 72.5 | G29: herbicida | H29: dh | I29: 136 | J29: 0.5 | K29: 0.5 | L29: =I29*J29 -> 68 | M29: =I29*K29 -> 68 | O29: herbicida | P29: dh | Q29: 136 | R29: 0.5 | S29: 0.5 | T29: =$Q29*R29 -> 68 | U29: =$Q29*S29 -> 68
A30: isca | B30: dh | C30: 145 | D30: 0.1 | E30: =C30*D30 -> 14.5 | G30: Apoio a pulveizações | H30: dh | I30: 136 | J30: 1 | K30: 1.5 | L30: =I30*J30 -> 136 | M30: =I30*K30 -> 204 | O30: Apoio a pulveizações | P30: dh | Q30: 136 | R30: 1 | S30: 1.5 | T30: =$Q30*R30 -> 136 | U30: =$Q30*S30 -> 204
A31: Aplicação defensivo | B31: dh | C31: 145 | D31: 0.5 | E31: =C31*D31 -> 72.5 | G31: rocada manual | H31: dh | I31: 136 | J31: 1 | K31: 0.25 | L31: =I31*J31 -> 136 | M31: =I31*K31 -> 34 | O31: rocada manual | P31: dh | Q31: 136 | R31: 1 | S31: 0.25 | T31: =$Q31*R31 -> 136 | U31: =$Q31*S31 -> 34
A32: rocada manual | B32: dh | C32: 145 | D32: 1 | E32: =C32*D32 -> 145 | G32: Aplicação esterco/calcário/fosfatado | H32: dh | I32: 136 | J32: 3 | K32: 0.25 | L32: =I32*J32 -> 408 | M32: =I32*K32 -> 34 | O32: desbrota | P32: dh | Q32: 136 | R32: 3 | S32: 3 | T32: =$Q32*R32 -> 408 | U32: =$Q32*S32 -> 408
A33: desfolha | B33: dh | C33: 145 | D33: 5 | E33: =C33*D33 -> 725 | G33: Manejo do sist irrigação | H33: dh | I33: 136 | J33: 4 | K33: 6 | L33: =I33*J33 -> 544 | M33: =I33*K33 -> 816 | O33: colheita | P33: dh | Q33: 145 | R33: 0 | S33: 15 | T33: =$Q33*R33 -> 0 | U33: =$Q33*S33 -> 2175
A34: desbrota | B34: dh | C34: 145 | D34: 3 | E34: =C34*D34 -> 435 | G34: Atividades diversa | H34: dh | I34: 136 | J34: 3 | K34: 5 | L34: =I34*J34 -> 408 | M34: =I34*K34 -> 680 | O34: Aplicação esterco/calcário/fosfatado | P34: dh | Q34: 136 | R34: 3 | S34: 0.25 | T34: =$Q34*R34 -> 408 | U34: =$Q34*S34 -> 34
A35: contaagem cachos | B35: dh | C35: 145 | D35: 3 | E35: =C35*D35 -> 435 | G35: SUB-TOTAL- MÃO DE OBRA = | L35: =SUM(L26:L34) -> 4420 | M35: =SUM(M26:M34) -> 1836 | O35: Manejo do sist irrigação | P35: dh | Q35: 136 | R35: 4 | S35: 6 | T35: =$Q35*R35 -> 544 | U35: =$Q35*S35 -> 816
A36: Controle moleque | B36: dh | C36: 145 | D36: 1.5 | E36: =C36*D36 -> 217.5 | O36: Atividades diversa | P36: dh | Q36: 136 | R36: 3 | S36: 5 | T36: =$Q36*R36 -> 408 | U36: =$Q36*S36 -> 680
A37: Aplicação esterco/calcário/fosfatado | B37: dh | C37: 145 | D37: 3 | E37: =C37*D37 -> 435 | O37: SUB-TOTAL- MÃO DE OBRA = | T37: =SUM(T26:T36) -> 4828 | U37: =SUM(U26:U36) -> 4419
A38: Manejo do sist irrigação | B38: dh | C38: 145 | D38: 5 | E38: =C38*D38 -> 725
A39: Atividades diversa | B39: dh | C39: 145 | D39: 3 | E39: =C39*D39 -> 435
A40: SUB-TOTAL- MÃO DE OBRA = | E40: =SUM(E26:E39) -> 8787
A42: GASTO COM TRATOR E EQUIPAMENTOS E AVIAÇÃO AGRÍCOLA | G42: GASTO COM TRATOR E EQUIPAMENTOS E AVIAÇÃO AGRÍCOLA | O42: GASTO COM TRATOR E EQUIPAMENTOS E AVIAÇÃO AGRÍCOLA
A43: Descrição | B43: Unidade | C43: Custo Unit. | D43: Quantidade por ha | E43: Custo por ano - R$ | G43: Descrição | H43: Unidade | I43: Custo Unit. | J43: Quantidade por ha | L43: Custo por ano - R$ | O43: Descrição | P43: Unidade | Q43: Custo Unit. | R43: Quantidade por ha | T43: Custo por ano - R$
D44: 1 | E44: 1 | J44: 1 | K44: 2 | L44: 1 | M44: 2 | R44: 1 | S44: 2 | T44: 1 | U44: 2
...

Sheet Cálculo Geral de Propriedades
A1: Nº PROPRIE- DADE | B1: ÁREA PROPRIEDADE (ha) | C1: ÍNDICE | D1: RECURSOS HÍDRICOS | E1: ENERGIA | F1: PASTO (ha) | G1: VEGETAÇÃO NATIVA (ha) | H1: % EXPLORAÇÃO | J1: VALOR | K1: FATOR OFERTA 2/ | L1: FATOR DE AJUSTE - ACESSO 1 - 3/ | M1: VALOR COM | N1: VALOR TOTAL R$ 5/ | O1: PIVÔ (ha) | P1: VALOR | Q1: IRRIGAÇÃO LOCALIZADA (ha) | R1: VALOR | S1: CULTURA EXPLORADA | T1: ÁREA DA CULTURA EXPLORADA | U1: VALOR | V1: PAINEL SOLAR (m²) | W1: VALOR | X1: VALOR | Y1: BENFEITORIAS
C2: BENFEITORIA | H2: PASTO | I2: VEG.NAT. | J2: UNITÁRIO-HA 1/ | M2: FATOR OFERTA E LOCALIZAÇÃO 4/ | P2: PIVO 6/ | R2: IRRIGAÇÃO 7/ | U2: CULTURA 8/ | W2: PAINEL 9/ | X2: TOTAL GERAL 10/
A3: 1 | B3: 984.9005 | C3: 1 | E3: X | F3: 351.09316 | G3: 633.80734 | H3: =F3/B3 -> 0.35647577 | I3: =G3/B3 -> 0.64352423 | J3: 6534.5 | K3: =$B$318 -> 0.95 | L3: =$B$320 -> 1.15 | M3: =J3*K3*L3 -> 7138.9412 | N3: =B3*M3 -> 7031146.8 | X3: =N3+P3+R3+U3+W3 -> 7031146.8
A4: 2 | B4: 3666.8488 | C4: 3 | D4: X | E4: X | F4: 2600.6799 | G4: 1066.1689 | H4: =F4/B4 -> 0.70924111 | I4: =G4/B4 -> 0.29075889 | J4: 8354.59 | K4: =$B$318 -> 0.95 | L4: =$B$320 -> 1.15 | M4: =J4*K4*L4 -> 9127.3896 | N4: =B4*M4 -> 33468757 | V4: 511.7231 | W4: =VLOOKUP(V4,'Estimativa Valores-Painéis Sol.'!$C$4:$D$24,2,FALSE) -> 72000 | X4: =N4+P4+R4+U4+W4 -> 33540757 | Y4: Estrutura Diversa; Casa Alvenaria; Estrutura Metálica; Reservatório;
A5: 22 | B5: 33.659597 | C5: 2 | E5: X | F5: 9.4253462 | G5: 24.234251 | H5: =F5/B5 -> 0.28001958 | I5: =G5/B5 -> 0.71998042 | J5: 14989.84 | K5: =$B$318 -> 0.95 | L5: =$B$321 -> 1 | M5: =J5*K5*L5 -> 14240.348 | N5: =B5*M5 -> 479324.37 | X5: =N5+P5+R5+U5+W5 -> 479324.37 | Y5: Estrutura Diversa; Casa Alvenaria;
A6: 23 | B6: 148.72492 | C6: 2 | E6: X | F6: 5.343799 | G6: 143.38112 | H6: =F6/B6 -> 0.035930758 | I6: =G6/B6 -> 0.96406924 | J6: 14768.69 | K6: =$B$318 -> 0.95 | L6: =$B$321 -> 1 | M6: =J6*K6*L6 -> 14030.255 | N6: =B6*M6 -> 2086648.6 | X6: =N6+P6+R6+U6+W6 -> 2086648.6 | Y6: Estrutura Diversa; Casa Alvenaria;
A7: 24 | B7: 146.2572 | C7: 2 | E7: X | F7: 129.50176 | G7: 16.755433 | H7: =F7/B7 -> 0.88543857 | I7: =G7/B7 -> 0.11456143 | J7: 16272.19 | K7: =$B$318 -> 0.95 | L7: =$B$321 -> 1 | M7: =J7*K7*L7 -> 15458.581 | N7: =B7*M7 -> 2260928.6 | X7: =N7+P7+R7+U7+W7 -> 2260928.6 | Y7: Estrutura Diversa; Casa Alvenaria;
A8: 25 | B8: 45.43599 | C8: 1 | E8: X | F8: 28.228487 | G8: 17.207503 | H8: =F8/B8 -> 0.62128033 | I8: =G8/B8 -> 0.37871967 | J8: 8960.41 | K8: =$B$318 -> 0.95 | L8: =$B$321 -> 1 | M8: =J8*K8*L8 -> 8512.3895 | N8: =B8*M8 -> 386768.85 | X8: =N8+P8+R8+U8+W8 -> 386768.85
A9: 26 | B9: 662.64008 | C9: 2 | D9: X | E9: X | F9: 271.83674 | G9: 390.80334 | H9: =F9/B9 -> 0.41023287 | I9: =G9/B9 -> 0.58976713 | J9: 13750.15 | K9: =$B$318 -> 0.95 | L9: =$B$321 -> 1 | M9: =J9*K9*L9 -> 13062.642 | N9: =M9*B9 -> 8655830.5 | Q9: 19.206314 | R9: ='Cálculo Depre.-Sist. Irrig.'!$P$3*Q9 -> 147888.62 | S9: Limão | T9: =Q9 -> 19.206314 | U9: ='Cálculo Valor Avaliação-Cultura'!$P$79*T9 -> 452661.91 | X9: =N9+P9+R9+U9+W9 -> 9256381 | Y9: Casa Alvenaria; Reservatório;
A10: 27 | B10: 81.972571 | C10: 2 | D10: X | E10: X | G10: 81.972571 | H10: =F10/B10 -> 0 | I10: =G10/B10 -> 1 | J10: 15717.96 | K10: =$B$319 -> 0.9 | L10: =$B$321 -> 1 | M10: =J10*K10*L10 -> 14146.164 | N10: =M10*B10 -> 1159597.4 | X10: =N10+P10+R10+U10+W10 -> 1159597.4 | Y10: Casa Alvenaria; Reservatório;
A11: 28 | B11: 244.45631 | C11: 1 | E11: X | F11: 5.9094185 | G11: 238.54689 | H11: =F11/B11 -> 0.024173721 | I11: =G11/B11 -> 0.97582628 | J11: 6475.63 | K11: =$B$318 -> 0.95 | L11: =$B$320 -> 1.15 | M11: =J11*K11*L11 -> 7074.6258 | N11: =B11*M11 -> 1729436.9 | X11: =N11+P11+R11+U11+W11 -> 1729436.9
A12: 29 | B12: 40.615095 | C12: 2 | E12: X | F12: 40.615095 | H12: =F12/B12 -> 1 | I12: =G12/F12 -> 0 | J12: 9684.66 | K12: =$B$318 -> 0.95 | L12: =$B$320 -> 1.15 | M12: =J12*K12*L12 -> 10580.491 | N12: =M12*F12 -> 429727.65 | X12: =N12+P12+R12+U12+W12 -> 429727.65 | Y12: Casa Alvenaria; Curral;
A13: 30 | B13: 40.576268 | C13: 2 | E13: X | F13: 18.468836 | G13: 22.107432 | H13: =F13/B13 -> 0.4551635 | I13: =G13/B13 -> 0.5448365 | J13: 8998.53 | K13: =$B$318 -> 0.95 | L13: =$B$320 -> 1.15 | M13: =J13*K13*L13 -> 9830.894 | N13: =B13*M13 -> 398900.99 | X13: =N13+P13+R13+U13+W13 -> 398900.99 | Y13: Casa Alvenaria;
A14: 31 | B14: 82.712954 | C14: 1 | E14: X | F14: 22.779882 | G14: 59.933072 | H14: =F14/B14 -> 0.27540888 | I14: =G14/B14 -> 0.72459112 | J14: 6539.07 | K14: =$B$318 -> 0.95 | L14: =$B$320 -> 1.15 | M14: =J14*K14*L14 -> 7143.934 | N14: =B14*M14 -> 590895.88 | X14: =N14+P14+R14+U14+W14 -> 590895.88
A15: 32 | B15: 44.620108 | C15: 1 | E15: X | F15: 26.202262 | G15: 18.417846 | H15: =F15/B15 -> 0.58722991 | I15: =G15/B15 -> 0.41277009 | J15: 6554.19 | K15: =$B$318 -> 0.95 | L15: =$B$320 -> 1.15 | M15: =J15*K15*L15 -> 7160.4526 | N15: =B15*M15 -> 319500.17 | X15: =N15+P15+R15+U15+W15 -> 319500.17
A16: 33 | B16: 80.644455 | C16: 2 | D16: X | E16: X | F16: 6.4966872 | G16: 74.147768 | H16: =F16/B16 -> 0.080559626 | I16: =G16/B16 -> 0.91944037 | J16: 9645.45 | K16: =$B$318 -> 0.95 | L16: =$B$320 -> 1.15 | M16: =J16*K16*L16 -> 10537.654 | N16: =B16*M16 -> 849803.37 | X16: =N16+P16+R16+U16+W16 -> 849803.37 | Y16: Casa Alvenaria; Reservatório;
A17: 34 | B17: 1369.7731 | C17: 2 | E17: X | F17: 1222.9325 | G17: 146.84067 | H17: =F17/B17 -> 0.89279928 | I17: =G17/B17 -> 0.10720072 | J17: 8101.33 | K17: =$B$318 -> 0.95 | L17: =$B$320 -> 1.15 | M17: =J17*K17*L17 -> 8850.703 | N17: =B17*M17 -> 12123455 | X17: =N17+P17+R17+U17+W17 -> 12123455 | Y17: Estrutura Diversa; Casa Alvenaria; Estrutura de Concreto; Bebedouro;
A18: 45 | B18: 27.410207 | C18: 2 | E18: X | F18: 19.740562 | G18: 7.669645 | H18: =F18/B18 -> 0.72019018 | I18: =G18/B18 -> 0.27980982 | J18: 16569.01 | K18: =$B$318 -> 0.95 | L18: =$B$321 -> 1 | M18: =J18*K18*L18 -> 15740.559 | N18: =B18*M18 -> 431451.99 | X18: =N18+P18+R18+U18+W18 -> 431451.99 | Y18: Estrutura Diversa; Casa Alvenaria;
A19: 46 | B19: 29.865446 | C19: 2 | E19: X | F19: 29.865446 | H19: =F19/B19 -> 1 | I19: =G19/F19 -> 0 | J19: 16562.66 | K19: =$B$318 -> 0.95 | L19: =$B$321 -> 1 | M19: =J19*K19*L19 -> 15734.527 | N19: =M19*F19 -> 469918.67 | X19: =N19+P19+R19+U19+W19 -> 469918.67 | Y19: Casa Alvenaria; Bebedouro;
A20: 47 | B20: 153.33063 | C20: 1 | E20: X | F20: 20.29323 | G20: 133.0374 | H20: =F20/B20 -> 0.13234949 | I20: =G20/B20 -> 0.86765051 | J20: 8875.93 | K20: =$B$318 -> 0.95 | L20: =$B$321 -> 1 | M20: =J20*K20*L20 -> 8432.1335 | N20: =B20*M20 -> 1292904.3 | X20: =N20+P20+R20+U20+W20 -> 1292904.3
A21: 48 | B21: 10.840117 | C21: 2 | E21: X | F21: 10.840117 | H21: =F21/B21 -> 1 | I21: =G21/F21 -> 0 | J21: 15034.13 | K21: =$B$318 -> 0.95 | L21: =$B$321 -> 1 | M21: =J21*K21*L21 -> 14282.423 | N21: =M21*F21 -> 154823.14 | X21: =N21+P21+R21+U21+W21 -> 154823.14
A22: 49 | B22: 20.453242 | C22: 2 | E22: X | F22: 20.453242 | H22: =F22/B22 -> 1 | I22: =G22/F22 -> 0 | J22: 16586.57 | K22: =$B$318 -> 0.95 | L22: =$B$321 -> 1 | M22: =J22*K22*L22 -> 15757.241 | N22: =M22*F22 -> 322286.67 | X22: =N22+P22+R22+U22+W22 -> 322286.67 | Y22: Estrutura Diversa;
A23: 50 | B23: 41.573141 | C23: 1 | E23: X | F23: 2.67539 | G23: 27.642814 | H23: =F23/B23 -> 0.064353809 | I23: =G23/B23 -> 0.66492002 | J23: 8963.4 | K23: =$B$318 -> 0.95 | L23: =$B$321 -> 1 | M23: =J23*K23*L23 -> 8515.23 | N23: =B23*M23 -> 354004.86 | V23: 112549.37 | W23: =VLOOKUP(V23,'Estimativa Valores-Painéis Sol.'!$C$4:$D$24,2,FALSE) -> 10200000 | X23: =N23+P23+R23+U23+W23 -> 10554005
A24: 51 | B24: 31.415908 | C24: 2 | D24: X | E24: X | F24: 13.972915 | G24: 17.442993 | H24: =F24/B24 -> 0.44477196 | I24: =G24/B24 -> 0.55522804 | J24: 14994.28 | K24: =$B$318 -> 0.95 | L24: =$B$321 -> 1 | M24: =J24*K24*L24 -> 14244.566 | N24: =B24*M24 -> 447505.97 | X24: =N24+P24+R24+U24+W24 -> 447505.97 | Y24: Estrutura Diversa; Casa Alvenaria; Reservatório;
A25: 52 | B25: 10.693703 | C25: 2 | D25: X | E25: X | F25: 6.4317115 | G25: 4.2619916 | H25: =F25/B25 -> 0.60144848 | I25: =G25/B25 -> 0.39855152 | J25: 18558.54 | K25: =$B$318 -> 0.95 | L25: =$B$321 -> 1 | M25: =J25*K25*L25 -> 17630.613 | N25: =B25*M25 -> 188536.54 | V25: 25.5894 | W25: =VLOOKUP(V25,'Estimativa Valores-Painéis Sol.'!$C$4:$D$24,2,FALSE) -> 6600 | X25: =N25+P25+R25+U25+W25 -> 195136.54 | Y25: Estrutura Diversa; Casa Alvenaria; Reservatório; Curral;
A26: 53 | B26: 80.856749 | C26: 2 | E26: X | F26: 71.987821 | G26: 8.8689284 | H26: =F26/B26 -> 0.89031307 | I26: =G26/B26 -> 0.10968693 | J26: 16434.13 | K26: =$B$318 -> 0.95 | L26: =$B$321 -> 1 | M26: =J26*K26*L26 -> 15612.424 | N26: =B26*M26 -> 1262369.8 | X26: =N26+P26+R26+U26+W26 -> 1262369.8 | Y26: Casa Alvenaria; Curral;
A27: 54 | B27: 80.335977 | C27: 1 | E27: X | F27: 70.614149 | G27: 9.7218281 | H27: =F27/B27 -> 0.87898538 | I27: =G27/B27 -> 0.12101462 | J27: 9779.83 | K27: =$B$318 -> 0.95 | L27: =$B$321 -> 1 | M27: =J27*K27*L27 -> 9290.8385 | N27: =B27*M27 -> 746388.59 | X27: =N27+P27+R27+U27+W27 -> 746388.59
A28: 55 | B28: 72.790069 | C28: 1 | E28: X | F28: 68.134162 | G28: 4.6559075 | H28: =F28/B28 -> 0.9360365 | I28: =G28/B28 -> 0.063963499 | J28: 6893.61 | K28: =$B$318 -> 0.95 | L28: =$B$320 -> 1.15 | M28: =J28*K28*L28 -> 7531.2689 | N28: =B28*M28 -> 548201.59 | X28: =N28+P28+R28+U28+W28 -> 548201.59
A29: 56 | B29: 80.064317 | C29: 2 | E29: X | F29: 48.38884 | G29: 31.675477 | H29: =F29/B29 -> 0.60437461 | I29: =G29/B29 -> 0.39562539 | J29: 9645.94 | K29: =$B$318 -> 0.95 | L29: =$B$320 -> 1.15 | M29: =J29*K29*L29 -> 10538.189 | N29: =B29*M29 -> 843732.94 | X29: =N29+P29+R29+U29+W29 -> 843732.94 | Y29: Casa Alvenaria; Estrutura de Concreto; Estrutura Metálica;
A30: 57 | B30: 91.414957 | C30: 1 | E30: X | F30: 4.1386031 | G30: 87.276353 | H30: =F30/B30 -> 0.045272713 | I30: =G30/B30 -> 0.95472729 | J30: 6451.16 | K30: =$B$318 -> 0.95 | L30: =$B$320 -> 1.15 | M30: =J30*K30*L30 -> 7047.8923 | N30: =B30*M30 -> 644282.77 | X30: =N30+P30+R30+U30+W30 -> 644282.77
A31: 58 | B31: 331.19828 | C31: 2 | E31: X | F31: 160.03871 | G31: 171.15957 | H31: =F31/B31 -> 0.48321116 | I31: =G31/B31 -> 0.51678884 | J31: 8238.9 | K31: =$B$318 -> 0.95 | L31: =$B$320 -> 1.15 | M31: =J31*K31*L31 -> 9000.9982 | N31: =B31*M31 -> 2981115.1 | X31: =N31+P31+R31+U31+W31 -> 2981115.1 | Y31: Casa Alvenaria;
A32: 81 | B32: 25.169105 | C32: 2 | E32: X | F32: 18.593632 | G32: 3.9698468 | H32: =F32/B32 -> 0.73874824 | I32: =G32/B32 -> 0.15772697 | J32: 16574.6 | K32: =$B$318 -> 0.95 | L32: =$B$321 -> 1 | M32: =J32*K32*L32 -> 15745.87 | N32: =M32*B32 -> 396309.46 | Q32: 2.6056261 | R32: ='Cálculo Depre.-Sist. Irrig.'!$P$3*Q32 -> 20063.321 | S32: Banana | T32: =Q32 -> 2.6056261 | U32: ='Cálculo Valor Avaliação-Cultura'!$B$79*T32 -> 37504.716 | X32: =N32+P32+R32+U32+W32 -> 453877.5 | Y32: Casa Alvenaria;
A33: 82 | B33: 85.282298 | C33: 2 | E33: X | F33: 85.282298 | H33: =F33/B33 -> 1 | I33: =G33/F33 -> 0 | J33: 14890.35 | K33: =$B$318 -> 0.95 | L33: =$B$321 -> 1 | M33: =J33*K33*L33 -> 14145.833 | N33: =M33*F33 -> 1206389.1 | X33: =N33+P33+R33+U33+W33 -> 1206389.1
A34: 83 | B34: 152.22302 | C34: 1 | E34: X | F34: 121.15452 | G34: 31.068508 | H34: =F34/B34 -> 0.79590139 | I34: =G34/B34 -> 0.20409861 | J34: 9716.57 | K34: =$B$318 -> 0.95 | L34: =$B$321 -> 1 | M34: =J34*K34*L34 -> 9230.7415 | N34: =B34*M34 -> 1405131.4 | X34: =N34+P34+R34+U34+W34 -> 1405131.4
A35: 84 | B35: 31.1133 | C35: 2 | E35: X | F35: 31.1133 | H35: =F35/B35 -> 1 | I35: =G35/F35 -> 0 | J35: 14994.86 | K35: =$B$318 -> 0.95 | L35: =$B$321 -> 1 | M35: =J35*K35*L35 -> 14245.117 | N35: =M35*F35 -> 443212.6 | X35: =N35+P35+R35+U35+W35 -> 443212.6
A36: 85 | B36: 87.209039 | C36: 2 | D36: X | E36: X | F36: 20.824199 | G36: 66.38484 | H36: =F36/B36 -> 0.23878487 | I36: =G36/B36 -> 0.76121513 | J36: 14886.69 | K36: =$B$318 -> 0.95 | L36: =$B$321 -> 1 | M36: =J36*K36*L36 -> 14142.355 | N36: =B36*M36 -> 1233341.2 | X36: =N36+P36+R36+U36+W36 -> 1233341.2 | Y36: Estrutura Diversa; Casa Alvenaria; Cisterna;
A37: 86 | B37: 90.685413 | C37: 2 | D37: X | E37: X | F37: 64.247784 | G37: 26.437628 | H37: =F37/B37 -> 0.70846879 | I37: =G37/B37 -> 0.29153121 | J37: 16409.65 | K37: =$B$318 -> 0.95 | L37: =$B$321 -> 1 | M37: =J37*K37*L37 -> 15589.168 | N37: =B37*M37 -> 1413710.1 | X37: =N37+P37+R37+U37+W37 -> 1413710.1 | Y37: Estrutura Diversa; Casa Alvenaria; Reservatório;
A38: 87 | B38: 200.28119 | C38: 2 | E38: X | F38: 166.72913 | G38: 33.552056 | H38: =F38/B38 -> 0.83247525 | I38: =G38/B38 -> 0.16752475 | J38: 16140.87 | K38: =$B$318 -> 0.95 | L38: =$B$321 -> 1 | M38: =J38*K38*L38 -> 15333.826 | N38: =B38*M38 -> 3071077 | X38: =N38+P38+R38+U38+W38 -> 3071077 | Y38: Casa Alvenaria;
A39: 88 | B39: 120.59786 | C39: 2 | E39: X | F39: 120.59786 | H39: =F39/B39 -> 1 | I39: =G39/F39 -> 0 | J39: 16335.44 | K39: =$B$318 -> 0.95 | L39: =$B$321 -> 1 | M39: =J39*K39*L39 -> 15518.668 | N39: =M39*F39 -> 1871518.2 | X39: =N39+P39+R39+U39+W39 -> 1871518.2 | Y39: Estrutura Diversa; Casa Alvenaria; Curral;
A40: 89 | B40: 119.6151 | C40: 2 | E40: X | F40: 19.615774 | G40: 99.999327 | H40: =F40/B40 -> 0.16399078 | I40: =G40/B40 -> 0.83600922 | J40: 14824.45 | K40: =$B$318 -> 0.95 | L40: =$B$321 -> 1 | M40: =J40*K40*L40 -> 14083.228 | N40: =B40*M40 -> 1684566.7 | X40: =N40+P40+R40+U40+W40 -> 1684566.7 | Y40: Casa Alvenaria;
...

Sheet Valores Est. por Propriedade
G2: Parte 01/03
B3: Nº PROPRIEDADE | C3: VALOR ESTIMADO (R$) | D3: Nº PROPRIEDADE | E3: VALOR ESTIMADO (R$) | F3: Nº PROPRIEDADE | G3: VALOR ESTIMADO (R$)
B4: ='Cálculo Geral de Propriedades'!A3 -> 1 | C4: =VLOOKUP(B4,'Cálculo Geral de Propriedades'!A:X,24,FALSE) -> 7031146.8 | D4: ='Cálculo Geral de Propriedades'!A29 -> 56 | E4: =VLOOKUP(D4,'Cálculo Geral de Propriedades'!A:X,24,FALSE) -> 843732.94 | F4: ='Cálculo Geral de Propriedades'!A55 -> 123 | G4: =VLOOKUP(F4,'Cálculo Geral de Propriedades'!A:X,24,FALSE) -> 188413.37
B5: ='Cálculo Geral de Propriedades'!A4 -> 2 | C5: =VLOOKUP(B5,'Cálculo Geral de Propriedades'!A:X,24,FALSE) -> 33540757 | D5: ='Cálculo Geral de Propriedades'!A30 -> 57 | E5: =VLOOKUP(D5,'Cálculo Geral de Propriedades'!A:X,24,FALSE) -> 644282.77 | F5: ='Cálculo Geral de Propriedades'!A56 -> 124 | G5: =VLOOKUP(F5,'Cálculo Geral de Propriedades'!A:X,24,FALSE) -> 1481682.2
B6: ='Cálculo Geral de Propriedades'!A5 -> 22 | C6: =VLOOKUP(B6,'Cálculo Geral de Propriedades'!A:X,24,FALSE) -> 479324.37 | D6: ='Cálculo Geral de Propriedades'!A31 -> 58 | E6: =VLOOKUP(D6,'Cálculo Geral de Propriedades'!A:X,24,FALSE) -> 2981115.1 | F6: ='Cálculo Geral de Propriedades'!A57 -> 125 | G6: =VLOOKUP(F6,'Cálculo Geral de Propriedades'!A:X,24,FALSE) -> 153588.78
B7: ='Cálculo Geral de Propriedades'!A6 -> 23 | C7: =VLOOKUP(B7,'Cálculo Geral de Propriedades'!A:X,24,FALSE) -> 2086648.6 | D7: ='Cálculo Geral de Propriedades'!A32 -> 81 | E7: =VLOOKUP(D7,'Cálculo Geral de Propriedades'!A:X,24,FALSE) -> 453877.5 | F7: ='Cálculo Geral de Propriedades'!A58 -> 126 | G7: =VLOOKUP(F7,'Cálculo Geral de Propriedades'!A:X,24,FALSE) -> 649723.73
B8: ='Cálculo Geral de Propriedades'!A7 -> 24 | C8: =VLOOKUP(B8,'Cálculo Geral de Propriedades'!A:X,24,FALSE) -> 2260928.6 | D8: ='Cálculo Geral de Propriedades'!A33 -> 82 | E8: =VLOOKUP(D8,'Cálculo Geral de Propriedades'!A:X,24,FALSE) -> 1206389.1 | F8: ='Cálculo Geral de Propriedades'!A59 -> 127 | G8: =VLOOKUP(F8,'Cálculo Geral de Propriedades'!A:X,24,FALSE) -> 49776.62
B9: ='Cálculo Geral de Propriedades'!A8 -> 25 | C9: =VLOOKUP(B9,'Cálculo Geral de Propriedades'!A:X,24,FALSE) -> 386768.85 | D9: ='Cálculo Geral de Propriedades'!A34 -> 83 | E9: =VLOOKUP(D9,'Cálculo Geral de Propriedades'!A:X,24,FALSE) -> 1405131.4 | F9: ='Cálculo Geral de Propriedades'!A60 -> 128 | G9: =VLOOKUP(F9,'Cálculo Geral de Propriedades'!A:X,24,FALSE) -> 28430.156
B10: ='Cálculo Geral de Propriedades'!A9 -> 26 | C10: =VLOOKUP(B10,'Cálculo Geral de Propriedades'!A:X,24,FALSE) -> 9256381 | D10: ='Cálculo Geral de Propriedades'!A35 -> 84 | E10: =VLOOKUP(D10,'Cálculo Geral de Propriedades'!A:X,24,FALSE) -> 443212.6 | F10: ='Cálculo Geral de Propriedades'!A61 -> 129 | G10: =VLOOKUP(F10,'Cálculo Geral de Propriedades'!A:X,24,FALSE) -> 28382.059
B11: ='Cálculo Geral de Propriedades'!A10 -> 27 | C11: =VLOOKUP(B11,'Cálculo Geral de Propriedades'!A:X,24,FALSE) -> 1159597.4 | D11: ='Cálculo Geral de Propriedades'!A36 -> 85 | E11: =VLOOKUP(D11,'Cálculo Geral de Propriedades'!A:X,24,FALSE) -> 1233341.2 | F11: ='Cálculo Geral de Propriedades'!A62 -> 130 | G11: =VLOOKUP(F11,'Cálculo Geral de Propriedades'!A:X,24,FALSE) -> 25918.217
B12: ='Cálculo Geral de Propriedades'!A11 -> 28 | C12: =VLOOKUP(B12,'Cálculo Geral de Propriedades'!A:X,24,FALSE) -> 1729436.9 | D12: ='Cálculo Geral de Propriedades'!A37 -> 86 | E12: =VLOOKUP(D12,'Cálculo Geral de Propriedades'!A:X,24,FALSE) -> 1413710.1 | F12: ='Cálculo Geral de Propriedades'!A63 -> 131 | G12: =VLOOKUP(F12,'Cálculo Geral de Propriedades'!A:X,24,FALSE) -> 28404.618
B13: ='Cálculo Geral de Propriedades'!A12 -> 29 | C13: =VLOOKUP(B13,'Cálculo Geral de Propriedades'!A:X,24,FALSE) -> 429727.65 | D13: ='Cálculo Geral de Propriedades'!A38 -> 87 | E13: =VLOOKUP(D13,'Cálculo Geral de Propriedades'!A:X,24,FALSE) -> 3071077 | F13: ='Cálculo Geral de Propriedades'!A64 -> 132 | G13: =VLOOKUP(F13,'Cálculo Geral de Propriedades'!A:X,24,FALSE) -> 28437.397
B14: ='Cálculo Geral de Propriedades'!A13 -> 30 | C14: =VLOOKUP(B14,'Cálculo Geral de Propriedades'!A:X,24,FALSE) -> 398900.99 | D14: ='Cálculo Geral de Propriedades'!A39 -> 88 | E14: =VLOOKUP(D14,'Cálculo Geral de Propriedades'!A:X,24,FALSE) -> 1871518.2 | F14: ='Cálculo Geral de Propriedades'!A65 -> 133 | G14: =VLOOKUP(F14,'Cálculo Geral de Propriedades'!A:X,24,FALSE) -> 18636.5
B15: ='Cálculo Geral de Propriedades'!A14 -> 31 | C15: =VLOOKUP(B15,'Cálculo Geral de Propriedades'!A:X,24,FALSE) -> 590895.88 | D15: ='Cálculo Geral de Propriedades'!A40 -> 89 | E15: =VLOOKUP(D15,'Cálculo Geral de Propriedades'!A:X,24,FALSE) -> 1684566.7 | F15: ='Cálculo Geral de Propriedades'!A66 -> 134 | G15: =VLOOKUP(F15,'Cálculo Geral de Propriedades'!A:X,24,FALSE) -> 34664.301
... B28: ='Cálculo Geral de Propriedades'!A27 -> 54 | C28: =VLOOKUP(B28,'Cálculo Geral de Propriedades'!A:X,24,FALSE) -> 746388.59 | D28: ='Cálculo Geral de Propriedades'!A53 -> 121 | E28: =VLOOKUP(D28,'Cálculo Geral de Propriedades'!A:X,24,FALSE) -> 12490037 | F28: ='Cálculo Geral de Propriedades'!A79 -> 147 | G28: =VLOOKUP(F28,'Cálculo Geral de Propriedades'!A:X,24,FALSE) -> 151470.93
B29: ='Cálculo Geral de Propriedades'!A28 -> 55 | C29: =VLOOKUP(B29,'Cálculo Geral de Propriedades'!A:X,24,FALSE) -> 548201.59 | D29: ='Cálculo Geral de Propriedades'!A54 -> 122 | E29: =VLOOKUP(D29,'Cálculo Geral de Propriedades'!A:X,24,FALSE) -> 99760.49
B30: SUBTOTAL = | C30: =SUM(C4:C29) -> 89068265 | D30: SUBTOTAL = | E30: =SUM(E4:E29) -> 35574914 | F30: SUBTOTAL = | G30: =SUM(G4:G28) -> 6854125.9
G32: Parte 02/03
B33: Nº PROPRIEDADE | C33: VALOR ESTIMADO (R$) | D33: Nº PROPRIEDADE | E33: VALOR ESTIMADO (R$) | F33: Nº PROPRIEDADE | G33: VALOR ESTIMADO (R$)
B34: ='Cálculo Geral de Propriedades'!A80 -> 148 | C34: =VLOOKUP(B34,'Cálculo Geral de Propriedades'!A:X,24,FALSE) -> 238497.63 | D34: ='Cálculo Geral de Propriedades'!A129 -> 197 | E34: =VLOOKUP(D34,'Cálculo Geral de Propriedades'!A:X,24,FALSE) -> 214461.17 | F34: ='Cálculo Geral de Propriedades'!A178 -> 246 | G34: =VLOOKUP(F34,'Cálculo Geral de Propriedades'!A:X,24,FALSE) -> 325008.64
B35: ='Cálculo Geral de Propriedades'!A81 -> 149 | C35: =VLOOKUP(B35,'Cálculo Geral de Propriedades'!A:X,24,FALSE) -> 463402.26 | D35: ='Cálculo Geral de Propriedades'!A130 -> 198 | E35: =VLOOKUP(D35,'Cálculo Geral de Propriedades'!A:X,24,FALSE) -> 240394.45 | F35: ='Cálculo Geral de Propriedades'!A179 -> 247 | G35: =VLOOKUP(F35,'Cálculo Geral de Propriedades'!A:X,24,FALSE) -> 461519.38
B36: ='Cálculo Geral de Propriedades'!A82 -> 150 | C36: =VLOOKUP(B36,'Cálculo Geral de Propriedades'!A:X,24,FALSE) -> 102506.27 | D36: ='Cálculo Geral de Propriedades'!A131 -> 199 | E36: =VLOOKUP(D36,'Cálculo Geral de Propriedades'!A:X,24,FALSE) -> 212667.71 | F36: ='Cálculo Geral de Propriedades'!A180 -> 248 | G36: =VLOOKUP(F36,'Cálculo Geral de Propriedades'!A:X,24,FALSE) -> 156922.38
B37: ='Cálculo Geral de Propriedades'!A83 -> 151 | C37: =VLOOKUP(B37,'Cálculo Geral de Propriedades'!A:X,24,FALSE) -> 28176.077 | D37: ='Cálculo Geral de Propriedades'!A132 -> 200 | E37: =VLOOKUP(D37,'Cálculo Geral de Propriedades'!A:X,24,FALSE) -> 284805.15 | F37: ='Cálculo Geral de Propriedades'!A181 -> 249 | G37: =VLOOKUP(F37,'Cálculo Geral de Propriedades'!A:X,24,FALSE) -> 152471.08
B38: ='Cálculo Geral de Propriedades'!A84 -> 152 | C38: =VLOOKUP(B38,'Cálculo Geral de Propriedades'!A:X,24,FALSE) -> 345784.81 | D38: ='Cálculo Geral de Propriedades'!A133 -> 201 | E38: =VLOOKUP(D38,'Cálculo Geral de Propriedades'!A:X,24,FALSE) -> 579139.36 | F38: ='Cálculo Geral de Propriedades'!A182 -> 250 | G38: =VLOOKUP(F38,'Cálculo Geral de Propriedades'!A:X,24,FALSE) -> 158966.22
B39: ='Cálculo Geral de Propriedades'!A85 -> 153 | C39: =VLOOKUP(B39,'Cálculo Geral de Propriedades'!A:X,24,FALSE) -> 846967.58 | D39: ='Cálculo Geral de Propriedades'!A134 -> 202 | E39: =VLOOKUP(D39,'Cálculo Geral de Propriedades'!A:X,24,FALSE) -> 176537.14 | F39: ='Cálculo Geral de Propriedades'!A183 -> 251 | G39: =VLOOKUP(F39,'Cálculo Geral de Propriedades'!A:X,24,FALSE) -> 5769700.9
B40: ='Cálculo Geral de Propriedades'!A86 -> 154 | C40: =VLOOKUP(B40,'Cálculo Geral de Propriedades'!A:X,24,FALSE) -> 489235.68 | D40: ='Cálculo Geral de Propriedades'!A135 -> 203 | E40: =VLOOKUP(D40,'Cálculo Geral de Propriedades'!A:X,24,FALSE) -> 326022.62 | F40: ='Cálculo Geral de Propriedades'!A184 -> 252 | G40: =VLOOKUP(F40,'Cálculo Geral de Propriedades'!A:X,24,FALSE) -> 4401082.3
B41: ='Cálculo Geral de Propriedades'!A87 -> 155 | C41: =VLOOKUP(B41,'Cálculo Geral de Propriedades'!A:X,24,FALSE) -> 561436.43 | D41: ='Cálculo Geral de Propriedades'!A136 -> 204 | E41: =VLOOKUP(D41,'Cálculo Geral de Propriedades'!A:X,24,FALSE) -> 16475.441 | F41: ='Cálculo Geral de Propriedades'!A185 -> 253 | G41: =VLOOKUP(F41,'Cálculo Geral de Propriedades'!A:X,24,FALSE) -> 3658061.5
B42: ='Cálculo Geral de Propriedades'!A88 -> 156 | C42: =VLOOKUP(B42,'Cálculo Geral de Propriedades'!A:X,24,FALSE) -> 129723.98 | D42: ='Cálculo Geral de Propriedades'!A137 -> 205 | E42: =VLOOKUP(D42,'Cálculo Geral de Propriedades'!A:X,24,FALSE) -> 16418.961 | F42: ='Cálculo Geral de Propriedades'!A186 -> 254 | G42: =VLOOKUP(F42,'Cálculo Geral de Propriedades'!A:X,24,FALSE) -> 1293850.2
B43: ='Cálculo Geral de Propriedades'!A89 -> 157 | C43: =VLOOKUP(B43,'Cálculo Geral de Propriedades'!A:X,24,FALSE) -> 183424.29 | D43: ='Cálculo Geral de Propriedades'!A138 -> 206 | E43: =VLOOKUP(D43,'Cálculo Geral de Propriedades'!A:X,24,FALSE) -> 44024.909 | F43: ='Cálculo Geral de Propriedades'!A187 -> 255 | G43: =VLOOKUP(F43,'Cálculo Geral de Propriedades'!A:X,24,FALSE) -> 794646.73
B44: ='Cálculo Geral de Propriedades'!A90 -> 158 | C44: =VLOOKUP(B44,'Cálculo Geral de Propriedades'!A:X,24,FALSE) -> 62223.656 | D44: ='Cálculo Geral de Propriedades'!A139 -> 207 | E44: =VLOOKUP(D44,'Cálculo Geral de Propriedades'!A:X,24,FALSE) -> 16456.175 | F44: ='Cálculo Geral de Propriedades'!A188 -> 256 | G44: =VLOOKUP(F44,'Cálculo Geral de Propriedades'!A:X,24,FALSE) -> 1170495.3
B45: ='Cálculo Geral de Propriedades'!A91 -> 159 | C45: =VLOOKUP(B45,'Cálculo Geral de Propriedades'!A:X,24,FALSE) -> 280013.26 | D45: ='Cálculo Geral de Propriedades'!A140 -> 208 | E45: =VLOOKUP(D45,'Cálculo Geral de Propriedades'!A:X,24,FALSE) -> 47798.892 | F45: ='Cálculo Geral de Propriedades'!A189 -> 257 | G45: =VLOOKUP(F45,'Cálculo Geral de Propriedades'!A:X,24,FALSE) -> 1534018.8
... B82: ='Cálculo Geral de Propriedades'!A128 -> 196 | C82: =VLOOKUP(B82,'Cálculo Geral de Propriedades'!A:X,24,FALSE) -> 86755.563 | D82: ='Cálculo Geral de Propriedades'!A177 -> 245 | E82: =VLOOKUP(D82,'Cálculo Geral de Propriedades'!A:X,24,FALSE) -> 2005455 | F82: ='Cálculo Geral de Propriedades'!A226 -> 294 | G82: =VLOOKUP(F82,'Cálculo Geral de Propriedades'!A:X,24,FALSE) -> 502013.85
B83: SUBTOTAL = | C83: =SUM(C34:C82) -> 18788279 | D83: SUBTOTAL = | E83: =SUM(E34:E82) -> 48878638 | F83: SUBTOTAL = | G83: =SUM(G34:G82) -> 63182309
G85: Parte 03/03
B86: Nº PROPRIEDADE | C86: VALOR ESTIMADO (R$) | D86: Nº PROPRIEDADE | E86: VALOR ESTIMADO (R$) | F86: Nº PROPRIEDADE | G86: VALOR ESTIMADO (R$)
B87: ='Cálculo Geral de Propriedades'!A227 -> 295 | C87: =VLOOKUP(B87,'Cálculo Geral de Propriedades'!A:X,24,FALSE) -> 550399.7 | D87: ='Cálculo Geral de Propriedades'!A256 -> 324 | E87: =VLOOKUP(D87,'Cálculo Geral de Propriedades'!A:X,24,FALSE) -> 2551001 | F87: ='Cálculo Geral de Propriedades'!A285 -> 353 | G87: =VLOOKUP(F87,'Cálculo Geral de Propriedades'!A:X,24,FALSE) -> 14535.868
B88: ='Cálculo Geral de Propriedades'!A228 -> 296 | C88: =VLOOKUP(B88,'Cálculo Geral de Propriedades'!A:X,24,FALSE) -> 278487.43 | D88: ='Cálculo Geral de Propriedades'!A257 -> 325 | E88: =VLOOKUP(D88,'Cálculo Geral de Propriedades'!A:X,24,FALSE) -> 726973.35 | F88: ='Cálculo Geral de Propriedades'!A286 -> 354 | G88: =VLOOKUP(F88,'Cálculo Geral de Propriedades'!A:X,24,FALSE) -> 732682.68
B89: ='Cálculo Geral de Propriedades'!A229 -> 297 | C89: =VLOOKUP(B89,'Cálculo Geral de Propriedades'!A:X,24,FALSE) -> 919405.69 | D89: ='Cálculo Geral de Propriedades'!A258 -> 326 | E89: =VLOOKUP(D89,'Cálculo Geral de Propriedades'!A:X,24,FALSE) -> 656150.01 | F89: ='Cálculo Geral de Propriedades'!A287 -> 355 | G89: =VLOOKUP(F89,'Cálculo Geral de Propriedades'!A:X,24,FALSE) -> 253934
B90: ='Cálculo Geral de Propriedades'!A230 -> 298 | C90: =VLOOKUP(B90,'Cálculo Geral de Propriedades'!A:X,24,FALSE) -> 584378.24 | D90: ='Cálculo Geral de Propriedades'!A259 -> 327 | E90: =VLOOKUP(D90,'Cálculo Geral de Propriedades'!A:X,24,FALSE) -> 249961.58 | F90: ='Cálculo Geral de Propriedades'!A288 -> 356 | G90: =VLOOKUP(F90,'Cálculo Geral de Propriedades'!A:X,24,FALSE) -> 89930.71
B91: ='Cálculo Geral de Propriedades'!A231 -> 299 | C91: =VLOOKUP(B91,'Cálculo Geral de Propriedades'!A:X,24,FALSE) -> 1026058.2 | D91: ='Cálculo Geral de Propriedades'!A260 -> 328 | E91: =VLOOKUP(D91,'Cálculo Geral de Propriedades'!A:X,24,FALSE) -> 735647.19 | F91: ='Cálculo Geral de Propriedades'!A289 -> 357 | G91: =VLOOKUP(F91,'Cálculo Geral de Propriedades'!A:X,24,FALSE) -> 149188.29
...

Sheet Valores Est. por Prop. ET.3e4
B1: ETAPA 3
G4: Parte 01/02
B5: Nº PROPRIEDADE | C5: VALOR ESTIMADO (R$) | D5: Nº PROPRIEDADE | E5: VALOR ESTIMADO (R$) | F5: Nº PROPRIEDADE | G5: VALOR ESTIMADO (R$)
B6: ='Cálculo Geral de Propriedades'!A3 -> 1 | C6: =VLOOKUP(B6,'Cálculo Geral de Propriedades'!A:X,24,FALSE) -> 7031146.8 | D6: ='Cálculo Geral de Propriedades'!A29 -> 56 | E6: =VLOOKUP(D6,'Cálculo Geral de Propriedades'!A:X,24,FALSE) -> 843732.94 | F6: ='Cálculo Geral de Propriedades'!A55 -> 123 | G6: =VLOOKUP(F6,'Cálculo Geral de Propriedades'!A:X,24,FALSE) -> 188413.37
B7: ='Cálculo Geral de Propriedades'!A4 -> 2 | C7: =VLOOKUP(B7,'Cálculo Geral de Propriedades'!A:X,24,FALSE) -> 33540757 | D7: ='Cálculo Geral de Propriedades'!A30 -> 57 | E7: =VLOOKUP(D7,'Cálculo Geral de Propriedades'!A:X,24,FALSE) -> 644282.77 | F7: ='Cálculo Geral de Propriedades'!A56 -> 124 | G7: =VLOOKUP(F7,'Cálculo Geral de Propriedades'!A:X,24,FALSE) -> 1481682.2
B8: ='Cálculo Geral de Propriedades'!A5 -> 22 | C8: =VLOOKUP(B8,'Cálculo Geral de Propriedades'!A:X,24,FALSE) -> 479324.37 | D8: ='Cálculo Geral de Propriedades'!A31 -> 58 | E8: =VLOOKUP(D8,'Cálculo Geral de Propriedades'!A:X,24,FALSE) -> 2981115.1 | F8: ='Cálculo Geral de Propriedades'!A57 -> 125 | G8: =VLOOKUP(F8,'Cálculo Geral de Propriedades'!A:X,24,FALSE) -> 153588.78
B9: ='Cálculo Geral de Propriedades'!A6 -> 23 | C9: =VLOOKUP(B9,'Cálculo Geral de Propriedades'!A:X,24,FALSE) -> 2086648.6 | D9: ='Cálculo Geral de Propriedades'!A32 -> 81 | E9: =VLOOKUP(D9,'Cálculo Geral de Propriedades'!A:X,24,FALSE) -> 453877.5 | F9: ='Cálculo Geral de Propriedades'!A58 -> 126 | G9: =VLOOKUP(F9,'Cálculo Geral de Propriedades'!A:X,24,FALSE) -> 649723.73
B10: ='Cálculo Geral de Propriedades'!A7 -> 24 | C10: =VLOOKUP(B10,'Cálculo Geral de Propriedades'!A:X,24,FALSE) -> 2260928.6 | D10: ='Cálculo Geral de Propriedades'!A33 -> 82 | E10: =VLOOKUP(D10,'Cálculo Geral de Propriedades'!A:X,24,FALSE) -> 1206389.1 | F10: ='Cálculo Geral de Propriedades'!A59 -> 127 | G10: =VLOOKUP(F10,'Cálculo Geral de Propriedades'!A:X,24,FALSE) -> 49776.62
B11: ='Cálculo Geral de Propriedades'!A8 -> 25 | C11: =VLOOKUP(B11,'Cálculo Geral de Propriedades'!A:X,24,FALSE) -> 386768.85 | D11: ='Cálculo Geral de Propriedades'!A34 -> 83 | E11: =VLOOKUP(D11,'Cálculo Geral de Propriedades'!A:X,24,FALSE) -> 1405131.4 | F11: ='Cálculo Geral de Propriedades'!A60 -> 128 | G11: =VLOOKUP(F11,'Cálculo Geral de Propriedades'!A:X,24,FALSE) -> 28430.156
B12: ='Cálculo Geral de Propriedades'!A9 -> 26 | C12: =VLOOKUP(B12,'Cálculo Geral de Propriedades'!A:X,24,FALSE) -> 9256381 | D12: ='Cálculo Geral de Propriedades'!A35 -> 84 | E12: =VLOOKUP(D12,'Cálculo Geral de Propriedades'!A:X,24,FALSE) -> 443212.6 | F12: ='Cálculo Geral de Propriedades'!A61 -> 129 | G12: =VLOOKUP(F12,'Cálculo Geral de Propriedades'!A:X,24,FALSE) -> 28382.059
B13: ='Cálculo Geral de Propriedades'!A10 -> 27 | C13: =VLOOKUP(B13,'Cálculo Geral de Propriedades'!A:X,24,FALSE) -> 1159597.4 | D13: ='Cálculo Geral de Propriedades'!A36 -> 85 | E13: =VLOOKUP(D13,'Cálculo Geral de Propriedades'!A:X,24,FALSE) -> 1233341.2 | F13: ='Cálculo Geral de Propriedades'!A62 -> 130 | G13: =VLOOKUP(F13,'Cálculo Geral de Propriedades'!A:X,24,FALSE) -> 25918.217
B14: ='Cálculo Geral de Propriedades'!A11 -> 28 | C14: =VLOOKUP(B14,'Cálculo Geral de Propriedades'!A:X,24,FALSE) -> 1729436.9 | D14: ='Cálculo Geral de Propriedades'!A37 -> 86 | E14: =VLOOKUP(D14,'Cálculo Geral de Propriedades'!A:X,24,FALSE) -> 1413710.1 | F14: ='Cálculo Geral de Propriedades'!A63 -> 131 | G14: =VLOOKUP(F14,'Cálculo Geral de Propriedades'!A:X,24,FALSE) -> 28404.618
B15: ='Cálculo Geral de Propriedades'!A12 -> 29 | C15: =VLOOKUP(B15,'Cálculo Geral de Propriedades'!A:X,24,FALSE) -> 429727.65 | D15: ='Cálculo Geral de Propriedades'!A38 -> 87 | E15: =VLOOKUP(D15,'Cálculo Geral de Propriedades'!A:X,24,FALSE) -> 3071077 | F15: ='Cálculo Geral de Propriedades'!A64 -> 132 | G15: =VLOOKUP(F15,'Cálculo Geral de Propriedades'!A:X,24,FALSE) -> 28437.397
B16: ='Cálculo Geral de Propriedades'!A13 -> 30 | C16: =VLOOKUP(B16,'Cálculo Geral de Propriedades'!A:X,24,FALSE) -> 398900.99 | D16: ='Cálculo Geral de Propriedades'!A39 -> 88 | E16: =VLOOKUP(D16,'Cálculo Geral de Propriedades'!A:X,24,FALSE) -> 1871518.2 | F16: ='Cálculo Geral de Propriedades'!A65 -> 133 | G16: =VLOOKUP(F16,'Cálculo Geral de Propriedades'!A:X,24,FALSE) -> 18636.5
B17: ='Cálculo Geral de Propriedades'!A14 -> 31 | C17: =VLOOKUP(B17,'Cálculo Geral de Propriedades'!A:X,24,FALSE) -> 590895.88 | D17: ='Cálculo Geral de Propriedades'!A40 -> 89 | E17: =VLOOKUP(D17,'Cálculo Geral de Propriedades'!A:X,24,FALSE) -> 1684566.7 | F17: ='Cálculo Geral de Propriedades'!A66 -> 134 | G17: =VLOOKUP(F17,'Cálculo Geral de Propriedades'!A:X,24,FALSE) -> 34664.301
... B30: ='Cálculo Geral de Propriedades'!A27 -> 54 | C30: =VLOOKUP(B30,'Cálculo Geral de Propriedades'!A:X,24,FALSE) -> 746388.59 | D30: ='Cálculo Geral de Propriedades'!A53 -> 121 | E30: =VLOOKUP(D30,'Cálculo Geral de Propriedades'!A:X,24,FALSE) -> 12490037 | F30: ='Cálculo Geral de Propriedades'!A79 -> 147 | G30: =VLOOKUP(F30,'Cálculo Geral de Propriedades'!A:X,24,FALSE) -> 151470.93
B31: ='Cálculo Geral de Propriedades'!A28 -> 55 | C31: =VLOOKUP(B31,'Cálculo Geral de Propriedades'!A:X,24,FALSE) -> 548201.59 | D31: ='Cálculo Geral de Propriedades'!A54 -> 122 | E31: =VLOOKUP(D31,'Cálculo Geral de Propriedades'!A:X,24,FALSE) -> 99760.49
B32: SUBTOTAL = | C32: =SUM(C6:C31) -> 89068265 | D32: SUBTOTAL = | E32: =SUM(E6:E31) -> 35574914 | F32: SUBTOTAL = | G32: =SUM(G6:G30) -> 6854125.9
G34: Parte 02/02
B35: Nº PROPRIEDADE | C35: VALOR ESTIMADO (R$) | D35: Nº PROPRIEDADE | E35: VALOR ESTIMADO (R$) | F35: Nº PROPRIEDADE | G35: VALOR ESTIMADO (R$)
B36: ='Cálculo Geral de Propriedades'!A80 -> 148 | C36: =VLOOKUP(B36,'Cálculo Geral de Propriedades'!A:X,24,FALSE) -> 238497.63 | D36: ='Cálculo Geral de Propriedades'!A109 -> 177 | E36: =VLOOKUP(D36,'Cálculo Geral de Propriedades'!A:X,24,FALSE) -> 74538.371 | F36: ='Cálculo Geral de Propriedades'!A138 -> 206 | G36: =VLOOKUP(F36,'Cálculo Geral de Propriedades'!A:X,24,FALSE) -> 44024.909
B37: ='Cálculo Geral de Propriedades'!A81 -> 149 | C37: =VLOOKUP(B37,'Cálculo Geral de Propriedades'!A:X,24,FALSE) -> 463402.26 | D37: ='Cálculo Geral de Propriedades'!A110 -> 178 | E37: =VLOOKUP(D37,'Cálculo Geral de Propriedades'!A:X,24,FALSE) -> 72254.277 | F37: ='Cálculo Geral de Propriedades'!A139 -> 207 | G37: =VLOOKUP(F37,'Cálculo Geral de Propriedades'!A:X,24,FALSE) -> 16456.175
B38: ='Cálculo Geral de Propriedades'!A82 -> 150 | C38: =VLOOKUP(B38,'Cálculo Geral de Propriedades'!A:X,24,FALSE) -> 102506.27 | D38: ='Cálculo Geral de Propriedades'!A111 -> 179 | E38: =VLOOKUP(D38,'Cálculo Geral de Propriedades'!A:X,24,FALSE) -> 77509.872 | F38: ='Cálculo Geral de Propriedades'!A140 -> 208 | G38: =VLOOKUP(F38,'Cálculo Geral de Propriedades'!A:X,24,FALSE) -> 47798.892
B39: ='Cálculo Geral de Propriedades'!A83 -> 151 | C39: =VLOOKUP(B39,'Cálculo Geral de Propriedades'!A:X,24,FALSE) -> 28176.077 | D39: ='Cálculo Geral de Propriedades'!A112 -> 180 | E39: =VLOOKUP(D39,'Cálculo Geral de Propriedades'!A:X,24,FALSE) -> 206867.81 | F39: ='Cálculo Geral de Propriedades'!A141 -> 209 | G39: =VLOOKUP(F39,'Cálculo Geral de Propriedades'!A:X,24,FALSE) -> 52897.934
B40: ='Cálculo Geral de Propriedades'!A84 -> 152 | C40: =VLOOKUP(B40,'Cálculo Geral de Propriedades'!A:X,24,FALSE) -> 345784.81 | D40: ='Cálculo Geral de Propriedades'!A113 -> 181 | E40: =VLOOKUP(D40,'Cálculo Geral de Propriedades'!A:X,24,FALSE) -> 215348.25 | F40: ='Cálculo Geral de Propriedades'!A142 -> 210 | G40: =VLOOKUP(F40,'Cálculo Geral de Propriedades'!A:X,24,FALSE) -> 494695.92
B41: ='Cálculo Geral de Propriedades'!A85 -> 153 | C41: =VLOOKUP(B41,'Cálculo Geral de Propriedades'!A:X,24,FALSE) -> 846967.58 | D41: ='Cálculo Geral de Propriedades'!A114 -> 182 | E41: =VLOOKUP(D41,'Cálculo Geral de Propriedades'!A:X,24,FALSE) -> 313513.51 | F41: ='Cálculo Geral de Propriedades'!A143 -> 211 | G41: =VLOOKUP(F41,'Cálculo Geral de Propriedades'!A:X,24,FALSE) -> 330492.13
B42: ='Cálculo Geral de Propriedades'!A86 -> 154 | C42: =VLOOKUP(B42,'Cálculo Geral de Propriedades'!A:X,24,FALSE) -> 489235.68 | D42: ='Cálculo Geral de Propriedades'!A115 -> 183 | E42: =VLOOKUP(D42,'Cálculo Geral de Propriedades'!A:X,24,FALSE) -> 284685.24 | F42: ='Cálculo Geral de Propriedades'!A144 -> 212 | G42: =VLOOKUP(F42,'Cálculo Geral de Propriedades'!A:X,24,FALSE) -> 37378.72
B43: ='Cálculo Geral de Propriedades'!A87 -> 155 | C43: =VLOOKUP(B43,'Cálculo Geral de Propriedades'!A:X,24,FALSE) -> 561436.43 | D43: ='Cálculo Geral de Propriedades'!A116 -> 184 | E43: =VLOOKUP(D43,'Cálculo Geral de Propriedades'!A:X,24,FALSE) -> 205627.25 | F43: ='Cálculo Geral de Propriedades'!A145 -> 213 | G43: =VLOOKUP(F43,'Cálculo Geral de Propriedades'!A:X,24,FALSE) -> 214450.16
B44: ='Cálculo Geral de Propriedades'!A88 -> 156 | C44: =VLOOKUP(B44,'Cálculo Geral de Propriedades'!A:X,24,FALSE) -> 129723.98 | D44: ='Cálculo Geral de Propriedades'!A117 -> 185 | E44: =VLOOKUP(D44,'Cálculo Geral de Propriedades'!A:X,24,FALSE) -> 216210.08 | F44: ='Cálculo Geral de Propriedades'!A146 -> 214 | G44: =VLOOKUP(F44,'Cálculo Geral de Propriedades'!A:X,24,FALSE) -> 152978.25
B45: ='Cálculo Geral de Propriedades'!A89 -> 157 | C45: =VLOOKUP(B45,'Cálculo Geral de Propriedades'!A:X,24,FALSE) -> 183424.29 | D45: ='Cálculo Geral de Propriedades'!A118 -> 186 | E45: =VLOOKUP(D45,'Cálculo Geral de Propriedades'!A:X,24,FALSE) -> 648465.84 | F45: ='Cálculo Geral de Propriedades'!A147 -> 215 | G45: =VLOOKUP(F45,'Cálculo Geral de Propriedades'!A:X,24,FALSE) -> 104613.83
B46: ='Cálculo Geral de Propriedades'!A90 -> 158 | C46: =VLOOKUP(B46,'Cálculo Geral de Propriedades'!A:X,24,FALSE) -> 62223.656 | D46: ='Cálculo Geral de Propriedades'!A119 -> 187 | E46: =VLOOKUP(D46,'Cálculo Geral de Propriedades'!A:X,24,FALSE) -> 1701175.9 | F46: ='Cálculo Geral de Propriedades'!A148 -> 216 | G46: =VLOOKUP(F46,'Cálculo Geral de Propriedades'!A:X,24,FALSE) -> 404944.34
B47: ='Cálculo Geral de Propriedades'!A91 -> 159 | C47: =VLOOKUP(B47,'Cálculo Geral de Propriedades'!A:X,24,FALSE) -> 280013.26 | D47: ='Cálculo Geral de Propriedades'!A120 -> 188 | E47: =VLOOKUP(D47,'Cálculo Geral de Propriedades'!A:X,24,FALSE) -> 413699.57 | F47: ='Cálculo Geral de Propriedades'!A149 -> 217 | G47: =VLOOKUP(F47,'Cálculo Geral de Propriedades'!A:X,24,FALSE) -> 257865.05
... B63: ='Cálculo Geral de Propriedades'!A107 -> 175 | C63: =VLOOKUP(B63,'Cálculo Geral de Propriedades'!A:X,24,FALSE) -> 818679.02 | D63: ='Cálculo Geral de Propriedades'!A136 -> 204 | E63: =VLOOKUP(D63,'Cálculo Geral de Propriedades'!A:X,24,FALSE) -> 16475.441 | F63: ='Cálculo Geral de Propriedades'!A165 -> 233 | G63: =VLOOKUP(F63,'Cálculo Geral de Propriedades'!A:X,24,FALSE) -> 405598.93
B64: ='Cálculo Geral de Propriedades'!A108 -> 176 | C64: =VLOOKUP(B64,'Cálculo Geral de Propriedades'!A:X,24,FALSE) -> 132146.36 | D64: ='Cálculo Geral de Propriedades'!A137 -> 205 | E64: =VLOOKUP(D64,'Cálculo Geral de Propriedades'!A:X,24,FALSE) -> 16418.961
B65: SUBTOTAL = | C65: =SUM(C36:C64) -> 12592766 | D65: SUBTOTAL = | E65: =SUM(E36:E64) -> 8262435.6 | F65: SUBTOTAL = | G65: =SUM(G36:G64) -> 19824601
F67: ETAPA 3 - TOTAL = | G67: =SUM(C32,E32,G32,C65,E65,G65) -> 1.7217711e+08
B71: ETAPA 4
G73: Parte 01/01
B74: Nº PROPRIEDADE | C74: VALOR ESTIMADO (R$) | D74: Nº PROPRIEDADE | E74: VALOR ESTIMADO (R$) | F74: Nº PROPRIEDADE | G74: VALOR ESTIMADO (R$)
B75: ='Cálculo Geral de Propriedades'!A166 -> 234 | C75: =VLOOKUP(B75,'Cálculo Geral de Propriedades'!A:X,24,FALSE) -> 4436819.2 | D75: ='Cálculo Geral de Propriedades'!A216 -> 284 | E75: =VLOOKUP(D75,'Cálculo Geral de Propriedades'!A:X,24,FALSE) -> 2508780.7 | F75: ='Cálculo Geral de Propriedades'!A265 -> 333 | G75: =VLOOKUP(F75,'Cálculo Geral de Propriedades'!A:X,24,FALSE) -> 459335.75
...
